File: ExpDat_CA_Blank-2.csv
#FILE:                       ,CA_Blank.ngb-ds3
#FORMAT:                     ,NETZSCH5
#IDENTITY:                   ,CA blank
#DECIMAL:                    ,POINT
#SEPARATOR:                  ,COMMA
#MTYPE:                      ,DSC
#INSTRUMENT:                 ,Microlab TU Delft
#PROJECT:                    ,
#DATE/TIME:                  ,2/05/2023 8:33:34 AM
#CORR. FILE:                 ,2023_04_25.ngb-bs3
#LABORATORY:                 ,TU Delft Micro Lab
#OPERATOR:                   ,Ameya
#REMARK:                     ,under argon atmosphere, 10K/min
#SAMPLE:                     ,CA_Blank
#SAMPLE MASS /mg:            ,35.1
#MATERIAL:                   ,Capsules
#REFERENCE:                  ,blank
#REFERENCE MASS /mg:         ,0
#TYPE OF CRUCIBLE:           ,DSC/TG pan Al2O3
#SAMPLE CRUCIBLE MASS /mg:   ,0
#REFERENCE CRUCIBLE MASS /mg:,0
#CORR. CODE:                 ,020
#EXO:                        ,+1
#RANGE:                      ,40/10.0(K/min)/1000
#SEGMENT:                    ,S2/2

##Temp./øC,Time/min,DSC/(mW/mg),Mass/%,Gas Flow(purge1)/(ml/min),Gas Flow(purge2)/(ml/min),Gas Flow(protective)/(ml/min),DTG/(%/min),Sensit./(uV/mW)
 40.39500, 15.00333,-3.5332e-002,  99.01994,50.00000,0.0000e+000,20.00000,    -0.30926,0.95848
 40.45100, 15.18833,-3.5172e-002,  99.00855,50.00000,0.0000e+000,20.00000,-6.5063e-002,0.95850
 40.50600, 15.37333,-3.5081e-002,  99.00000,50.00000,0.0000e+000,20.00000,-6.5462e-002,0.95851
 40.58000, 15.55833,-3.5217e-002,  98.99145,50.00000,0.0000e+000,20.00000,-6.6600e-002,0.95853
 40.71900, 15.74333,-3.6122e-002,  98.97436,50.00000,0.0000e+000,20.00000,-6.8537e-002,0.95857
 40.91500, 15.92833,-3.8093e-002,  98.96011,50.00000,0.0000e+000,20.00000,-6.9501e-002,0.95862
 41.15800, 16.11333,-4.0312e-002,  98.94872,50.00000,0.0000e+000,20.00000,-6.8244e-002,0.95869
 41.50300, 16.29833,-4.4707e-002,  98.93447,50.00000,0.0000e+000,20.00000,-7.2561e-002,0.95878
 41.93400, 16.48333,-4.9575e-002,  98.92308,50.00000,0.0000e+000,20.00000,-7.5871e-002,0.95889
 42.45400, 16.66833,-5.4849e-002,  98.90883,50.00000,0.0000e+000,20.00000,-7.3681e-002,0.95902
 43.04400, 16.85333,-6.1254e-002,  98.89459,50.00000,0.0000e+000,20.00000,-7.7617e-002,0.95917
 43.72200, 17.03833,-6.8312e-002,  98.88319,50.00000,0.0000e+000,20.00000,-8.0067e-002,0.95934
 44.51100, 17.22333,-7.5706e-002,  98.86325,50.00000,0.0000e+000,20.00000,-8.3722e-002,0.95953
 45.39100, 17.40833,-8.3978e-002,  98.85185,50.00000,0.0000e+000,20.00000,-8.4855e-002,0.95974
 46.34100, 17.59333,-9.2631e-002,  98.83476,50.00000,0.0000e+000,20.00000,-8.7041e-002,0.95997
 47.36900, 17.77833,    -0.10157,  98.81766,50.00000,0.0000e+000,20.00000,-9.3025e-002,0.96020
 48.50300, 17.96333,    -0.11089,  98.80057,50.00000,0.0000e+000,20.00000,-9.9139e-002,0.96046
 49.71300, 18.14833,    -0.12052,  98.78063,50.00000,0.0000e+000,20.00000,    -0.10886,0.96072
 51.01700, 18.33333,    -0.13053,  98.76353,50.00000,0.0000e+000,20.00000,    -0.11437,0.96099
 52.39800, 18.51833,    -0.14135,  98.74359,50.00000,0.0000e+000,20.00000,    -0.12352,0.96127
 53.86900, 18.70333,    -0.15179,  98.72080,50.00000,0.0000e+000,20.00000,    -0.13414,0.96155
 55.39500, 18.88833,    -0.16294,  98.69231,50.00000,0.0000e+000,20.00000,    -0.14902,0.96184
 57.00900, 19.07333,    -0.17421,  98.66667,50.00000,0.0000e+000,20.00000,    -0.16529,0.96212
 58.70900, 19.25833,    -0.18626,  98.63818,50.00000,0.0000e+000,20.00000,    -0.18697,0.96240
 60.47000, 19.44333,    -0.19867,  98.60399,50.00000,0.0000e+000,20.00000,    -0.21119,0.96268
 62.31600, 19.62833,    -0.21198,  98.56980,50.00000,0.0000e+000,20.00000,    -0.24037,0.96295
 64.22000, 19.81333,    -0.22548,  98.51852,50.00000,0.0000e+000,20.00000,    -0.27481,0.96321
 66.19300, 19.99833,    -0.24005,  98.47293,50.00000,0.0000e+000,20.00000,    -0.31881,0.96345
 68.21900, 20.18333,    -0.25614,  98.41311,50.00000,0.0000e+000,20.00000,    -0.36661,0.96368
 70.31900, 20.36833,    -0.27214,  98.35328,50.00000,0.0000e+000,20.00000,    -0.41219,0.96390
 72.45300, 20.55333,    -0.28983,  98.26781,50.00000,0.0000e+000,20.00000,    -0.45990,0.96409
 74.63900, 20.73833,    -0.30873,  98.17664,50.00000,0.0000e+000,20.00000,    -0.51426,0.96426
 76.85600, 20.92333,    -0.32841,  98.07123,50.00000,0.0000e+000,20.00000,    -0.59967,0.96441
 79.13200, 21.10833,    -0.35016,  97.95727,50.00000,0.0000e+000,20.00000,    -0.66259,0.96453
 81.47700, 21.29333,    -0.37194,  97.84046,50.00000,0.0000e+000,20.00000,    -0.73742,0.96462
 83.82500, 21.47833,    -0.39857,  97.70940,50.00000,0.0000e+000,20.00000,    -0.81988,0.96469
 86.21500, 21.66333,    -0.42500,  97.56125,50.00000,0.0000e+000,20.00000,    -0.89706,0.96472
 88.62600, 21.84833,    -0.45339,  97.36752,50.00000,0.0000e+000,20.00000,    -0.98031,0.96472
 91.06300, 22.03333,    -0.48346,  97.18234,50.00000,0.0000e+000,20.00000,    -1.07346,0.96469
 93.54300, 22.21833,    -0.51565,  96.98575,50.00000,0.0000e+000,20.00000,    -1.17416,0.96463
 96.02000, 22.40333,    -0.54980,  96.75499,50.00000,0.0000e+000,20.00000,    -1.27782,0.96453
 98.50300, 22.58833,    -0.58595,  96.51567,50.00000,0.0000e+000,20.00000,    -1.37971,0.96440
101.02800, 22.77333,    -0.62318,  96.25641,50.00000,0.0000e+000,20.00000,    -1.47818,0.96424
103.52400, 22.95833,    -0.66250,  95.96866,50.00000,0.0000e+000,20.00000,    -1.57901,0.96404
106.02200, 23.14333,    -0.70289,  95.67236,50.00000,0.0000e+000,20.00000,    -1.68890,0.96381
108.52300, 23.32833,    -0.74522,  95.35043,50.00000,0.0000e+000,20.00000,    -1.79508,0.96354
111.01200, 23.51333,    -0.78661,  95.00570,50.00000,0.0000e+000,20.00000,    -1.89694,0.96325
113.52200, 23.69833,    -0.82901,  94.63818,50.00000,0.0000e+000,20.00000,    -1.99391,0.96291
115.99300, 23.88333,    -0.87023,  94.25641,50.00000,0.0000e+000,20.00000,    -2.08892,0.96255
118.48700, 24.06833,    -0.91096,  93.85470,50.00000,0.0000e+000,20.00000,    -2.17961,0.96216
120.95000, 24.25333,    -0.94924,  93.43590,50.00000,0.0000e+000,20.00000,    -2.26042,0.96174
123.42500, 24.43833,    -0.98614,  93.00855,50.00000,0.0000e+000,20.00000,    -2.32503,0.96128
125.88700, 24.62333,    -1.01951,  92.56125,50.00000,0.0000e+000,20.00000,    -2.38120,0.96080
128.35300, 24.80833,    -1.05045,  92.11111,50.00000,0.0000e+000,20.00000,    -2.42718,0.96028
130.79401, 24.99333,    -1.07723,  91.64672,50.00000,0.0000e+000,20.00000,    -2.46068,0.95974
133.23000, 25.17833,    -1.10028,  91.17379,50.00000,0.0000e+000,20.00000,    -2.47839,0.95917
135.67200, 25.36333,    -1.11798,  90.70370,50.00000,0.0000e+000,20.00000,    -2.48533,0.95857
138.10201, 25.54833,    -1.13076,  90.23647,50.00000,0.0000e+000,20.00000,    -2.47589,0.95794
140.50900, 25.73333,    -1.13754,  89.76923,50.00000,0.0000e+000,20.00000,    -2.45356,0.95729
142.90800, 25.91833,    -1.13948,  89.31054,50.00000,0.0000e+000,20.00000,    -2.42155,0.95661
145.29300, 26.10333,    -1.13566,  88.86040,50.00000,0.0000e+000,20.00000,    -2.37204,0.95591
147.68700, 26.28833,    -1.12647,  88.42165,50.00000,0.0000e+000,20.00000,    -2.31498,0.95518
150.04201, 26.47333,    -1.11130,  87.99145,50.00000,0.0000e+000,20.00000,    -2.24919,0.95443
152.40100, 26.65833,    -1.09171,  87.57550,50.00000,0.0000e+000,20.00000,    -2.17172,0.95366
154.73599, 26.84333,    -1.06687,  87.17664,50.00000,0.0000e+000,20.00000,    -2.09246,0.95287
157.05299, 27.02833,    -1.03769,  86.79487,50.00000,0.0000e+000,20.00000,    -2.00553,0.95205
159.36400, 27.21333,    -1.00437,  86.43875,50.00000,0.0000e+000,20.00000,    -1.92042,0.95122
161.64200, 27.39833,    -0.96796,  86.08832,50.00000,0.0000e+000,20.00000,    -1.83067,0.95037
163.93100, 27.58333,    -0.92879,  85.75783,50.00000,0.0000e+000,20.00000,    -1.73861,0.94949
166.16701, 27.76833,    -0.88768,  85.45014,50.00000,0.0000e+000,20.00000,    -1.64840,0.94861
168.39301, 27.95333,    -0.84540,  85.15385,50.00000,0.0000e+000,20.00000,    -1.56083,0.94771
170.64101, 28.13833,    -0.80206,  84.87179,50.00000,0.0000e+000,20.00000,    -1.47656,0.94678
172.84100, 28.32333,    -0.75850,  84.60969,50.00000,0.0000e+000,20.00000,    -1.39429,0.94585
175.02400, 28.50833,    -0.71486,  84.36182,50.00000,0.0000e+000,20.00000,    -1.31481,0.94490
177.20399, 28.69333,    -0.67203,  84.13105,50.00000,0.0000e+000,20.00000,    -1.24126,0.94393
179.35400, 28.87833,    -0.63017,  83.90883,50.00000,0.0000e+000,20.00000,    -1.16530,0.94296
181.48100, 29.06333,    -0.58934,  83.69801,50.00000,0.0000e+000,20.00000,    -1.09831,0.94197
183.59100, 29.24833,    -0.54979,  83.50427,50.00000,0.0000e+000,20.00000,    -1.03083,0.94097
185.69701, 29.43333,    -0.51214,  83.31909,50.00000,0.0000e+000,20.00000,    -0.98454,0.93996
187.78101, 29.61833,    -0.47617,  83.14530,50.00000,0.0000e+000,20.00000,    -0.92853,0.93894
189.82100, 29.80333,    -0.44130,  82.98575,50.00000,0.0000e+000,20.00000,    -0.88054,0.93792
191.86600, 29.98833,    -0.40907,  82.84046,50.00000,0.0000e+000,20.00000,    -0.83554,0.93688
193.88600, 30.17333,    -0.37817,  82.68946,50.00000,0.0000e+000,20.00000,    -0.79665,0.93584
195.88901, 30.35833,    -0.34849,  82.53561,50.00000,0.0000e+000,20.00000,    -0.76187,0.93479
197.86099, 30.54333,    -0.31992,  82.40741,50.00000,0.0000e+000,20.00000,    -0.72921,0.93373
199.82401, 30.72833,    -0.29227,  82.27635,50.00000,0.0000e+000,20.00000,    -0.69996,0.93267
201.77499, 30.91333,    -0.26659,  82.15385,50.00000,0.0000e+000,20.00000,    -0.68456,0.93160
203.70000, 31.09833,    -0.24142,  82.02849,50.00000,0.0000e+000,20.00000,    -0.65282,0.93053
205.60699, 31.28333,    -0.21698,  81.90883,50.00000,0.0000e+000,20.00000,    -0.63212,0.92945
207.51401, 31.46833,    -0.19220,  81.79487,50.00000,0.0000e+000,20.00000,    -0.61901,0.92836
209.38600, 31.65333,    -0.16763,  81.68091,50.00000,0.0000e+000,20.00000,    -0.61230,0.92727
211.25500, 31.83833,    -0.14236,  81.57550,50.00000,0.0000e+000,20.00000,    -0.60883,0.92617
213.12399, 32.02333,    -0.11584,  81.47293,50.00000,0.0000e+000,20.00000,    -0.62518,0.92506
214.99300, 32.20833,-8.5963e-002,  81.36752,50.00000,0.0000e+000,20.00000,    -0.66430,0.92393
216.83600, 32.39333,-5.4128e-002,  81.26211,50.00000,0.0000e+000,20.00000,    -0.72681,0.92281
218.66901, 32.57833,-1.8867e-002,  81.14245,50.00000,0.0000e+000,20.00000,    -0.81717,0.92168
220.50400, 32.76333, 2.0212e-002,  81.01994,50.00000,0.0000e+000,20.00000,    -0.93435,0.92054
222.33000, 32.94833, 6.2060e-002,  80.84330,50.00000,0.0000e+000,20.00000,    -1.07746,0.91939
224.17300, 33.13334,     0.10584,  80.65527,50.00000,0.0000e+000,20.00000,    -1.24249,0.91821
225.99001, 33.31833,     0.14935,  80.42450,50.00000,0.0000e+000,20.00000,    -1.41569,0.91704
227.82401, 33.50333,     0.19108,  80.14530,50.00000,0.0000e+000,20.00000,    -1.59302,0.91585
229.64301, 33.68833,     0.22933,  79.82336,50.00000,0.0000e+000,20.00000,    -1.76971,0.91465
231.44701, 33.87333,     0.26287,  79.46154,50.00000,0.0000e+000,20.00000,    -1.90451,0.91345
233.25600, 34.05833,     0.29069,  79.05128,50.00000,0.0000e+000,20.00000,    -2.02572,0.91224
235.04300, 34.24333,     0.31110,  78.64103,50.00000,0.0000e+000,20.00000,    -2.12114,0.91103
236.83299, 34.42833,     0.32377,  78.20513,50.00000,0.0000e+000,20.00000,    -2.16423,0.90981
238.61099, 34.61333,     0.32815,  77.77208,50.00000,0.0000e+000,20.00000,    -2.18208,0.90859
240.39500, 34.79833,     0.32577,  77.34473,50.00000,0.0000e+000,20.00000,    -2.16241,0.90735
242.14500, 34.98333,     0.31928,  76.93447,50.00000,0.0000e+000,20.00000,    -2.11213,0.90612
243.89301, 35.16833,     0.30992,  76.53846,50.00000,0.0000e+000,20.00000,    -2.05174,0.90488
245.64400, 35.35333,     0.30032,  76.17379,50.00000,0.0000e+000,20.00000,    -1.97135,0.90363
247.39200, 35.53833,     0.29271,  75.81482,50.00000,0.0000e+000,20.00000,    -1.88926,0.90238
249.12300, 35.72333,     0.28625,  75.47578,50.00000,0.0000e+000,20.00000,    -1.81068,0.90112
250.87300, 35.90833,     0.28293,  75.15954,50.00000,0.0000e+000,20.00000,    -1.73340,0.89984
252.60400, 36.09333,     0.28268,  74.85185,50.00000,0.0000e+000,20.00000,    -1.67303,0.89857
254.34399, 36.27833,     0.28570,  74.55555,50.00000,0.0000e+000,20.00000,    -1.62873,0.89728
256.09601, 36.46333,     0.29085,  74.27635,50.00000,0.0000e+000,20.00000,    -1.59796,0.89597
257.85001, 36.64833,     0.29840,  73.99430,50.00000,0.0000e+000,20.00000,    -1.58732,0.89465
259.57999, 36.83333,     0.30765,  73.71510,50.00000,0.0000e+000,20.00000,    -1.59456,0.89334
261.35699, 37.01833,     0.31776,  73.43020,50.00000,0.0000e+000,20.00000,    -1.63113,0.89198
263.12701, 37.20333,     0.32818,  73.14530,50.00000,0.0000e+000,20.00000,    -1.68968,0.89062
264.89700, 37.38833,     0.33925,  72.84900,50.00000,0.0000e+000,20.00000,    -1.77963,0.88925
266.65399, 37.57333,     0.34917,  72.52992,50.00000,0.0000e+000,20.00000,    -1.88376,0.88788
268.43201, 37.75834,     0.35816,  72.19658,50.00000,0.0000e+000,20.00000,    -2.00565,0.88649
270.21799, 37.94333,     0.36550,  71.81481,50.00000,0.0000e+000,20.00000,    -2.12557,0.88508
272.00900, 38.12833,     0.37214,  71.40741,50.00000,0.0000e+000,20.00000,    -2.25610,0.88365
273.78299, 38.31333,     0.37873,  70.96581,50.00000,0.0000e+000,20.00000,    -2.38049,0.88223
275.56900, 38.49833,     0.38604,  70.49573,50.00000,0.0000e+000,20.00000,    -2.49309,0.88079
277.35300, 38.68333,     0.39517,  69.99715,50.00000,0.0000e+000,20.00000,    -2.59787,0.87935
279.15399, 38.86833,     0.40732,  69.49858,50.00000,0.0000e+000,20.00000,    -2.68090,0.87788
280.93900, 39.05333,     0.42244,  68.98575,50.00000,0.0000e+000,20.00000,    -2.76262,0.87642
282.73499, 39.23833,     0.44079,  68.45869,50.00000,0.0000e+000,20.00000,    -2.83502,0.87494
284.52301, 39.42333,     0.46254,  67.93447,50.00000,0.0000e+000,20.00000,    -2.90837,0.87345
286.33099, 39.60833,     0.48605,  67.41026,50.00000,0.0000e+000,20.00000,    -2.99256,0.87195
288.13101, 39.79333,     0.51154,  66.86325,50.00000,0.0000e+000,20.00000,    -3.08529,0.87044
289.94601, 39.97833,     0.53706,  66.30484,50.00000,0.0000e+000,20.00000,    -3.17871,0.86891
291.73700, 40.16333,     0.55958,  65.72080,50.00000,0.0000e+000,20.00000,    -3.26469,0.86739
293.55499, 40.34833,     0.57757,  65.09687,50.00000,0.0000e+000,20.00000,    -3.33939,0.86584
295.36499, 40.53333,     0.58982,  64.44444,50.00000,0.0000e+000,20.00000,    -3.40577,0.86429
297.16800, 40.71833,     0.59409,  63.77208,50.00000,0.0000e+000,20.00000,    -3.43921,0.86274
298.96701, 40.90333,     0.59269,  63.09117,50.00000,0.0000e+000,20.00000,    -3.42836,0.86118
300.78201, 41.08833,     0.58606,  62.41595,50.00000,0.0000e+000,20.00000,    -3.38769,0.85960
302.57901, 41.27333,     0.57566,  61.76638,50.00000,0.0000e+000,20.00000,    -3.28991,0.85803
304.36700, 41.45833,     0.56166,  61.13390,50.00000,0.0000e+000,20.00000,    -3.15338,0.85646
306.15500, 41.64333,     0.54386,  60.53561,50.00000,0.0000e+000,20.00000,    -2.96530,0.85488
307.94000, 41.82833,     0.52347,  59.99430,50.00000,0.0000e+000,20.00000,    -2.75061,0.85330
309.71899, 42.01333,     0.50099,  59.49288,50.00000,0.0000e+000,20.00000,    -2.52052,0.85172
311.49799, 42.19833,     0.47669,  59.05128,50.00000,0.0000e+000,20.00000,    -2.28337,0.85013
313.29501, 42.38334,     0.45231,  58.64957,50.00000,0.0000e+000,20.00000,    -2.04552,0.84852
315.07501, 42.56833,     0.42902,  58.31909,50.00000,0.0000e+000,20.00000,    -1.81348,0.84691
316.85199, 42.75333,     0.40790,  58.02279,50.00000,0.0000e+000,20.00000,    -1.60055,0.84531
318.63901, 42.93833,     0.39016,  57.76638,50.00000,0.0000e+000,20.00000,    -1.40081,0.84369
320.42599, 43.12333,     0.37535,  57.54131,50.00000,0.0000e+000,20.00000,    -1.23566,0.84206
322.20700, 43.30833,     0.36405,  57.34188,50.00000,0.0000e+000,20.00000,    -1.10218,0.84043
324.00400, 43.49333,     0.35580,  57.16809,50.00000,0.0000e+000,20.00000,    -0.98772,0.83878
325.79599, 43.67833,     0.35134,  57.02849,50.00000,0.0000e+000,20.00000,    -0.89413,0.83713
327.59698, 43.86333,     0.34837,  56.88604,50.00000,0.0000e+000,20.00000,    -0.82436,0.83546
329.40500, 44.04833,     0.34727,  56.74074,50.00000,0.0000e+000,20.00000,    -0.77291,0.83378
331.19800, 44.23333,     0.34718,  56.60399,50.00000,0.0000e+000,20.00000,    -0.73143,0.83211
333.03000, 44.41833,     0.34824,  56.47578,50.00000,0.0000e+000,20.00000,    -0.70251,0.83040
334.83499, 44.60333,     0.35071,  56.34758,50.00000,0.0000e+000,20.00000,    -0.69039,0.82871
336.66101, 44.78833,     0.35336,  56.22222,50.00000,0.0000e+000,20.00000,    -0.67388,0.82699
338.48599, 44.97333,     0.35691,  56.09971,50.00000,0.0000e+000,20.00000,    -0.65996,0.82527
340.30801, 45.15833,     0.36082,  55.98006,50.00000,0.0000e+000,20.00000,    -0.65087,0.82354
342.13599, 45.34333,     0.36524,  55.86325,50.00000,0.0000e+000,20.00000,    -0.64404,0.82181
343.96100, 45.52833,     0.36946,  55.74644,50.00000,0.0000e+000,20.00000,    -0.63751,0.82007
345.79501, 45.71333,     0.37290,  55.62963,50.00000,0.0000e+000,20.00000,    -0.62896,0.81832
347.62900, 45.89833,     0.37661,  55.50997,50.00000,0.0000e+000,20.00000,    -0.61720,0.81657
349.46201, 46.08333,     0.37987,  55.39886,50.00000,0.0000e+000,20.00000,    -0.61470,0.81481
351.29001, 46.26833,     0.38310,  55.28490,50.00000,0.0000e+000,20.00000,    -0.60894,0.81305
353.11899, 46.45333,     0.38589,  55.17094,50.00000,0.0000e+000,20.00000,    -0.60453,0.81128
354.95801, 46.63833,     0.38832,  55.06268,50.00000,0.0000e+000,20.00000,    -0.59533,0.80951
356.78601, 46.82333,     0.39025,  54.95726,50.00000,0.0000e+000,20.00000,    -0.58846,0.80773
358.62299, 47.00834,     0.39206,  54.83761,50.00000,0.0000e+000,20.00000,    -0.57947,0.80595
360.46301, 47.19333,     0.39404,  54.74074,50.00000,0.0000e+000,20.00000,    -0.57368,0.80416
362.31100, 47.37833,     0.39677,  54.62963,50.00000,0.0000e+000,20.00000,    -0.56612,0.80236
364.15799, 47.56333,     0.40000,  54.52991,50.00000,0.0000e+000,20.00000,    -0.56390,0.80055
366.00500, 47.74833,     0.40207,  54.42450,50.00000,0.0000e+000,20.00000,    -0.56050,0.79874
367.85199, 47.93333,     0.40424,  54.32479,50.00000,0.0000e+000,20.00000,    -0.54780,0.79693
369.66501, 48.11833,     0.40597,  54.22222,50.00000,0.0000e+000,20.00000,    -0.55135,0.79514
371.49899, 48.30333,     0.40815,  54.11966,50.00000,0.0000e+000,20.00000,    -0.55002,0.79334
373.33801, 48.48833,     0.41000,  54.01994,50.00000,0.0000e+000,20.00000,    -0.55045,0.79152
375.16901, 48.67333,     0.41245,  53.92023,50.00000,0.0000e+000,20.00000,    -0.55256,0.78971
377.01199, 48.85833,     0.41647,  53.82051,50.00000,0.0000e+000,20.00000,    -0.55861,0.78789
378.84698, 49.04333,     0.42031,  53.72080,50.00000,0.0000e+000,20.00000,    -0.56113,0.78607
380.68399, 49.22833,     0.42486,  53.61253,50.00000,0.0000e+000,20.00000,    -0.56594,0.78424
382.51999, 49.41333,     0.42894,  53.50712,50.00000,0.0000e+000,20.00000,    -0.58025,0.78242
384.34201, 49.59833,     0.43408,  53.40171,50.00000,0.0000e+000,20.00000,    -0.59317,0.78060
386.19501, 49.78333,     0.43880,  53.29060,50.00000,0.0000e+000,20.00000,    -0.61202,0.77875
388.03000, 49.96833,     0.44467,  53.18233,50.00000,0.0000e+000,20.00000,    -0.63232,0.77692
389.88800, 50.15333,     0.45073,  53.06838,50.00000,0.0000e+000,20.00000,    -0.67026,0.77506
391.73199, 50.33833,     0.45661,  52.94302,50.00000,0.0000e+000,20.00000,    -0.68461,0.77322
393.58301, 50.52333,     0.46442,  52.82051,50.00000,0.0000e+000,20.00000,    -0.71745,0.77136
395.43701, 50.70833,     0.47288,  52.68661,50.00000,0.0000e+000,20.00000,    -0.73201,0.76951
397.29501, 50.89333,     0.47944,  52.53846,50.00000,0.0000e+000,20.00000,    -0.76426,0.76764
399.14401, 51.07833,     0.48279,  52.37607,50.00000,0.0000e+000,20.00000,    -0.77318,0.76578
400.98801, 51.26333,     0.48663,  52.23647,50.00000,0.0000e+000,20.00000,    -0.78973,0.76393
402.84100, 51.44833,     0.48477,  52.07692,50.00000,0.0000e+000,20.00000,    -0.78828,0.76207
404.68701, 51.63334,     0.48681,  51.93732,50.00000,0.0000e+000,20.00000,    -0.78576,0.76021
406.54700, 51.81833,     0.49813,  51.77493,50.00000,0.0000e+000,20.00000,    -0.76295,0.75834
408.38901, 52.00333,     0.51749,  51.64387,50.00000,0.0000e+000,20.00000,    -0.74124,0.75648
410.23099, 52.18833,     0.54834,  51.49573,50.00000,0.0000e+000,20.00000,    -0.70324,0.75462
412.07901, 52.37333,     0.57883,  51.37037,50.00000,0.0000e+000,20.00000,    -0.67636,0.75276
413.90701, 52.55833,     0.59357,  51.24216,50.00000,0.0000e+000,20.00000,    -0.63508,0.75092
415.73700, 52.74333,     0.59480,  51.12536,50.00000,0.0000e+000,20.00000,    -0.58875,0.74907
417.53799, 52.92833,     0.59078,  51.01994,50.00000,0.0000e+000,20.00000,    -0.55091,0.74726
419.36301, 53.11333,     0.58495,  50.92592,50.00000,0.0000e+000,20.00000,    -0.51462,0.74541
421.17801, 53.29833,     0.57879,  50.83476,50.00000,0.0000e+000,20.00000,    -0.47930,0.74358
423.00699, 53.48333,     0.57296,  50.76638,50.00000,0.0000e+000,20.00000,    -0.44951,0.74174
424.81900, 53.66833,     0.56797,  50.68946,50.00000,0.0000e+000,20.00000,    -0.41698,0.73991
426.64600, 53.85333,     0.56285,  50.61824,50.00000,0.0000e+000,20.00000,    -0.39937,0.73806
428.46399, 54.03833,     0.55805,  50.54701,50.00000,0.0000e+000,20.00000,    -0.38444,0.73623
430.29300, 54.22333,     0.55345,  50.47863,50.00000,0.0000e+000,20.00000,    -0.36941,0.73439
432.11499, 54.40833,     0.55036,  50.41026,50.00000,0.0000e+000,20.00000,    -0.36596,0.73255
433.93900, 54.59333,     0.54734,  50.34758,50.00000,0.0000e+000,20.00000,    -0.35858,0.73071
435.76599, 54.77833,     0.54538,  50.27635,50.00000,0.0000e+000,20.00000,    -0.35270,0.72887
437.59601, 54.96333,     0.54267,  50.21652,50.00000,0.0000e+000,20.00000,    -0.34768,0.72703
439.42499, 55.14833,     0.54063,  50.15100,50.00000,0.0000e+000,20.00000,    -0.34087,0.72519
441.26801, 55.33333,     0.53868,  50.09117,50.00000,0.0000e+000,20.00000,    -0.33841,0.72333
443.08899, 55.51833,     0.53724,  50.02849,50.00000,0.0000e+000,20.00000,    -0.33777,0.72150
444.93301, 55.70333,     0.53524,  49.96581,50.00000,0.0000e+000,20.00000,    -0.32943,0.71965
446.76901, 55.88833,     0.53410,  49.90598,50.00000,0.0000e+000,20.00000,    -0.32931,0.71781
448.60501, 56.07333,     0.53384,  49.84330,50.00000,0.0000e+000,20.00000,    -0.32992,0.71597
450.43701, 56.25834,     0.53283,  49.78062,50.00000,0.0000e+000,20.00000,    -0.32899,0.71413
452.28500, 56.44333,     0.53193,  49.72365,50.00000,0.0000e+000,20.00000,    -0.32587,0.71228
454.12500, 56.62833,     0.53034,  49.66667,50.00000,0.0000e+000,20.00000,    -0.32399,0.71044
455.97101, 56.81333,     0.52822,  49.60399,50.00000,0.0000e+000,20.00000,    -0.32735,0.70860
457.82001, 56.99833,     0.52369,  49.54416,50.00000,0.0000e+000,20.00000,    -0.31965,0.70675
459.65100, 57.18333,     0.51981,  49.48433,50.00000,0.0000e+000,20.00000,    -0.31795,0.70493
461.50800, 57.36833,     0.51706,  49.42735,50.00000,0.0000e+000,20.00000,    -0.31623,0.70308
463.35001, 57.55333,     0.51578,  49.36182,50.00000,0.0000e+000,20.00000,    -0.31422,0.70125
465.17899, 57.73833,     0.51563,  49.30769,50.00000,0.0000e+000,20.00000,    -0.31332,0.69944
467.01801, 57.92333,     0.51629,  49.25071,50.00000,0.0000e+000,20.00000,    -0.31204,0.69761
468.85599, 58.10833,     0.51651,  49.19088,50.00000,0.0000e+000,20.00000,    -0.31100,0.69579
470.67999, 58.29333,     0.51685,  49.13675,50.00000,0.0000e+000,20.00000,    -0.30773,0.69399
472.50699, 58.47833,     0.51719,  49.08547,50.00000,0.0000e+000,20.00000,    -0.29895,0.69219
474.34698, 58.66333,     0.51616,  49.02279,50.00000,0.0000e+000,20.00000,    -0.29891,0.69038
476.18399, 58.84833,     0.51615,  48.96581,50.00000,0.0000e+000,20.00000,    -0.29536,0.68857
478.02600, 59.03333,     0.51628,  48.91168,50.00000,0.0000e+000,20.00000,    -0.28751,0.68676
479.86700, 59.21833,     0.51665,  48.86040,50.00000,0.0000e+000,20.00000,    -0.28334,0.68496
481.70599, 59.40333,     0.51715,  48.80912,50.00000,0.0000e+000,20.00000,    -0.28059,0.68316
483.55399, 59.58833,     0.51744,  48.76068,50.00000,0.0000e+000,20.00000,    -0.27101,0.68136
485.39600, 59.77333,     0.51842,  48.70940,50.00000,0.0000e+000,20.00000,    -0.26323,0.67956
487.23199, 59.95833,     0.51995,  48.66382,50.00000,0.0000e+000,20.00000,    -0.26092,0.67778
489.07199, 60.14333,     0.52135,  48.60969,50.00000,0.0000e+000,20.00000,    -0.26063,0.67599
490.90302, 60.32833,     0.52150,  48.56695,50.00000,0.0000e+000,20.00000,    -0.25777,0.67422
492.73999, 60.51333,     0.52129,  48.51852,50.00000,0.0000e+000,20.00000,    -0.25112,0.67245
494.56500, 60.69833,     0.52207,  48.47578,50.00000,0.0000e+000,20.00000,    -0.24054,0.67069
496.40500, 60.88334,     0.52361,  48.42735,50.00000,0.0000e+000,20.00000,    -0.23848,0.66892
498.23099, 61.06833,     0.52756,  48.37607,50.00000,0.0000e+000,20.00000,    -0.22645,0.66717
500.08200, 61.25333,     0.53181,  48.33618,50.00000,0.0000e+000,20.00000,    -0.22742,0.66540
501.93399, 61.43833,     0.53755,  48.29345,50.00000,0.0000e+000,20.00000,    -0.22304,0.66363
503.79599, 61.62333,     0.54138,  48.26496,50.00000,0.0000e+000,20.00000,    -0.21814,0.66186
505.67999, 61.80833,     0.54463,  48.21938,50.00000,0.0000e+000,20.00000,    -0.21198,0.66007
507.52200, 61.99333,     0.54729,  48.18234,50.00000,0.0000e+000,20.00000,    -0.20368,0.65833
509.38599, 62.17833,     0.54982,  48.14530,50.00000,0.0000e+000,20.00000,    -0.20355,0.65657
511.23901, 62.36333,     0.55311,  48.10541,50.00000,0.0000e+000,20.00000,    -0.20013,0.65483
513.09698, 62.54833,     0.55618,  48.06837,50.00000,0.0000e+000,20.00000,    -0.19776,0.65308
514.94501, 62.73333,     0.55852,  48.03134,50.00000,0.0000e+000,20.00000,    -0.19186,0.65136
516.78198, 62.91833,     0.56344,  47.99430,50.00000,0.0000e+000,20.00000,    -0.18719,0.64964
518.63000, 63.10333,     0.56631,  47.96297,50.00000,0.0000e+000,20.00000,    -0.18331,0.64793
520.48901, 63.28833,     0.57028,  47.92877,50.00000,0.0000e+000,20.00000,    -0.17593,0.64620
522.31000, 63.47333,     0.58876,  47.89744,50.00000,0.0000e+000,20.00000,    -0.17072,0.64452
524.15601, 63.65833,     0.60134,  47.86895,50.00000,0.0000e+000,20.00000,    -0.16694,0.64282
525.98602, 63.84333,     0.61167,  47.83761,50.00000,0.0000e+000,20.00000,    -0.15954,0.64114
527.81500, 64.02834,     0.62387,  47.80627,50.00000,0.0000e+000,20.00000,    -0.15824,0.63947
529.64899, 64.21333,     0.64132,  47.78348,50.00000,0.0000e+000,20.00000,    -0.15309,0.63780
531.48999, 64.39833,     0.65527,  47.75499,50.00000,0.0000e+000,20.00000,    -0.14839,0.63612
533.30798, 64.58334,     0.66787,  47.72650,50.00000,0.0000e+000,20.00000,    -0.14611,0.63448
535.14203, 64.76833,     0.68071,  47.70086,50.00000,0.0000e+000,20.00000,    -0.14252,0.63282
536.99200, 64.95333,     0.69193,  47.67237,50.00000,0.0000e+000,20.00000,    -0.13657,0.63116
538.83600, 65.13834,     0.70335,  47.64957,50.00000,0.0000e+000,20.00000,    -0.13655,0.62951
540.71002, 65.32333,     0.70993,  47.62393,50.00000,0.0000e+000,20.00000,    -0.13283,0.62784
542.53900, 65.50833,     0.71528,  47.59829,50.00000,0.0000e+000,20.00000,    -0.12978,0.62622
544.39203, 65.69334,     0.72115,  47.57550,50.00000,0.0000e+000,20.00000,    -0.12632,0.62458
546.23901, 65.87833,     0.72970,  47.55271,50.00000,0.0000e+000,20.00000,    -0.12538,0.62295
548.10498, 66.06333,     0.73635,  47.52992,50.00000,0.0000e+000,20.00000,    -0.12265,0.62131
549.94800, 66.24834,     0.74349,  47.50427,50.00000,0.0000e+000,20.00000,    -0.11745,0.61970
551.81598, 66.43333,     0.74977,  47.48433,50.00000,0.0000e+000,20.00000,    -0.11281,0.61808
553.65802, 66.61833,     0.75651,  47.46154,50.00000,0.0000e+000,20.00000,    -0.11138,0.61648
555.50500, 66.80334,     0.76193,  47.44445,50.00000,0.0000e+000,20.00000,    -0.10600,0.61489
557.35303, 66.98833,     0.76787,  47.42450,50.00000,0.0000e+000,20.00000,    -0.10287,0.61330
559.20599, 67.17333,     0.77455,  47.40741,50.00000,0.0000e+000,20.00000,    -0.10048,0.61172
561.04901, 67.35833,     0.78196,  47.38746,50.00000,0.0000e+000,20.00000,    -0.10045,0.61015
562.91199, 67.54333,     0.79038,  47.37037,50.00000,0.0000e+000,20.00000,    -0.10095,0.60857
564.77698, 67.72833,     0.79773,  47.35612,50.00000,0.0000e+000,20.00000,    -0.10012,0.60700
566.65198, 67.91333,     0.80759,  47.33618,50.00000,0.0000e+000,20.00000,    -0.10009,0.60542
568.54102, 68.09834,     0.81596,  47.31909,50.00000,0.0000e+000,20.00000,    -0.10050,0.60385
570.41101, 68.28333,     0.82103,  47.29630,50.00000,0.0000e+000,20.00000,    -0.10100,0.60229
572.26501, 68.46833,     0.82366,  47.27636,50.00000,0.0000e+000,20.00000,    -0.10010,0.60076
574.11298, 68.65334,     0.82608,  47.25926,50.00000,0.0000e+000,20.00000,    -0.10202,0.59924
575.95502, 68.83833,     0.82809,  47.23647,50.00000,0.0000e+000,20.00000,    -0.10420,0.59773
577.79303, 69.02333,     0.83057,  47.21937,50.00000,0.0000e+000,20.00000,    -0.10282,0.59624
579.62201, 69.20834,     0.83293,  47.19658,50.00000,0.0000e+000,20.00000,-9.9107e-002,0.59475
581.45203, 69.39333,     0.83489,  47.18804,50.00000,0.0000e+000,20.00000,    -0.10070,0.59328
583.28101, 69.57833,     0.83483,  47.16524,50.00000,0.0000e+000,20.00000,    -0.10093,0.59181
585.12299, 69.76334,     0.83643,  47.14530,50.00000,0.0000e+000,20.00000,    -0.10368,0.59035
586.97601, 69.94833,     0.83726,  47.12821,50.00000,0.0000e+000,20.00000,    -0.10337,0.58888
588.81097, 70.13333,     0.83869,  47.10826,50.00000,0.0000e+000,20.00000,    -0.10499,0.58743
590.66101, 70.31834,     0.83772,  47.08832,50.00000,0.0000e+000,20.00000,    -0.11078,0.58598
592.50897, 70.50333,     0.83440,  47.06837,50.00000,0.0000e+000,20.00000,    -0.10848,0.58454
594.36700, 70.68833,     0.83336,  47.04558,50.00000,0.0000e+000,20.00000,    -0.10874,0.58310
596.23602, 70.87334,     0.83494,  47.02564,50.00000,0.0000e+000,20.00000,    -0.11262,0.58166
598.07501, 71.05833,     0.83659,  47.00570,50.00000,0.0000e+000,20.00000,    -0.11271,0.58025
599.91498, 71.24333,     0.83689,  46.98576,50.00000,0.0000e+000,20.00000,    -0.11198,0.57885
601.76501, 71.42834,     0.83699,  46.96581,50.00000,0.0000e+000,20.00000,    -0.11362,0.57745
603.61102, 71.61333,     0.83727,  46.94587,50.00000,0.0000e+000,20.00000,    -0.11223,0.57607
605.45502, 71.79833,     0.83856,  46.92593,50.00000,0.0000e+000,20.00000,    -0.11487,0.57469
607.31799, 71.98333,     0.84100,  46.90313,50.00000,0.0000e+000,20.00000,    -0.12127,0.57331
609.16699, 72.16833,     0.84373,  46.88034,50.00000,0.0000e+000,20.00000,    -0.12566,0.57194
611.00500, 72.35333,     0.84199,  46.85755,50.00000,0.0000e+000,20.00000,    -0.12715,0.57060
612.85303, 72.53833,     0.84127,  46.83761,50.00000,0.0000e+000,20.00000,    -0.13110,0.56925
614.70697, 72.72334,     0.84390,  46.81197,50.00000,0.0000e+000,20.00000,    -0.13641,0.56791
616.56299, 72.90833,     0.84896,  46.78062,50.00000,0.0000e+000,20.00000,    -0.13821,0.56658
618.41498, 73.09333,     0.85148,  46.75499,50.00000,0.0000e+000,20.00000,    -0.14447,0.56526
620.27698, 73.27834,     0.85251,  46.72934,50.00000,0.0000e+000,20.00000,    -0.14844,0.56394
622.12903, 73.46333,     0.85321,  46.70371,50.00000,0.0000e+000,20.00000,    -0.15227,0.56263
623.97498, 73.64833,     0.85335,  46.67521,50.00000,0.0000e+000,20.00000,    -0.15976,0.56134
625.82397, 73.83334,     0.85371,  46.64672,50.00000,0.0000e+000,20.00000,    -0.16117,0.56006
627.67297, 74.01833,     0.85231,  46.61539,50.00000,0.0000e+000,20.00000,    -0.16467,0.55879
629.52100, 74.20333,     0.85186,  46.58405,50.00000,0.0000e+000,20.00000,    -0.17000,0.55753
631.37701, 74.38834,     0.85051,  46.55556,50.00000,0.0000e+000,20.00000,    -0.17569,0.55627
633.21399, 74.57333,     0.84970,  46.51567,50.00000,0.0000e+000,20.00000,    -0.18282,0.55503
635.06897, 74.75833,     0.84862,  46.48433,50.00000,0.0000e+000,20.00000,    -0.18982,0.55379
636.91199, 74.94334,     0.84750,  46.45014,50.00000,0.0000e+000,20.00000,    -0.19709,0.55257
638.76801, 75.12833,     0.84209,  46.41595,50.00000,0.0000e+000,20.00000,    -0.20324,0.55135
640.62000, 75.31333,     0.83801,  46.37892,50.00000,0.0000e+000,20.00000,    -0.20984,0.55014
642.46399, 75.49834,     0.83500,  46.33333,50.00000,0.0000e+000,20.00000,    -0.21600,0.54895
644.30298, 75.68333,     0.83256,  46.29060,50.00000,0.0000e+000,20.00000,    -0.22419,0.54777
646.14001, 75.86833,     0.82710,  46.24786,50.00000,0.0000e+000,20.00000,    -0.23296,0.54659
647.97699, 76.05334,     0.82081,  46.20798,50.00000,0.0000e+000,20.00000,    -0.23732,0.54543
649.81799, 76.23833,     0.81588,  46.15669,50.00000,0.0000e+000,20.00000,    -0.24833,0.54428
651.65698, 76.42333,     0.81112,  46.11396,50.00000,0.0000e+000,20.00000,    -0.25489,0.54314
653.51501, 76.60833,     0.80541,  46.06838,50.00000,0.0000e+000,20.00000,    -0.26684,0.54199
655.33398, 76.79333,     0.80112,  46.01994,50.00000,0.0000e+000,20.00000,    -0.27601,0.54088
657.17798, 76.97833,     0.79500,  45.97151,50.00000,0.0000e+000,20.00000,    -0.28702,0.53977
659.02600, 77.16333,     0.78922,  45.91453,50.00000,0.0000e+000,20.00000,    -0.29324,0.53866
660.87903, 77.34834,     0.78566,  45.86040,50.00000,0.0000e+000,20.00000,    -0.30700,0.53755
662.73798, 77.53333,     0.78370,  45.79772,50.00000,0.0000e+000,20.00000,    -0.32167,0.53646
664.59302, 77.71833,     0.78471,  45.74074,50.00000,0.0000e+000,20.00000,    -0.33929,0.53538
666.44702, 77.90334,     0.78609,  45.67806,50.00000,0.0000e+000,20.00000,    -0.35110,0.53430
668.31500, 78.08833,     0.78799,  45.61824,50.00000,0.0000e+000,20.00000,    -0.36318,0.53323
670.17297, 78.27333,     0.78261,  45.54416,50.00000,0.0000e+000,20.00000,    -0.38130,0.53218
672.03302, 78.45834,     0.77617,  45.47293,50.00000,0.0000e+000,20.00000,    -0.39177,0.53113
673.89099, 78.64333,     0.77260,  45.39601,50.00000,0.0000e+000,20.00000,    -0.40600,0.53010
675.73700, 78.82833,     0.77314,  45.32479,50.00000,0.0000e+000,20.00000,    -0.42352,0.52908
677.59497, 79.01334,     0.77397,  45.24786,50.00000,0.0000e+000,20.00000,    -0.43732,0.52807
679.44202, 79.19833,     0.77172,  45.15670,50.00000,0.0000e+000,20.00000,    -0.44928,0.52707
681.27698, 79.38333,     0.76741,  45.07692,50.00000,0.0000e+000,20.00000,    -0.46117,0.52609
683.12500, 79.56834,     0.76603,  44.98860,50.00000,0.0000e+000,20.00000,    -0.47498,0.52511
684.97498, 79.75333,     0.76380,  44.89459,50.00000,0.0000e+000,20.00000,    -0.49532,0.52414
686.83099, 79.93833,     0.75996,  44.80627,50.00000,0.0000e+000,20.00000,    -0.50842,0.52318
688.67798, 80.12334,     0.75955,  44.71795,50.00000,0.0000e+000,20.00000,    -0.51819,0.52223
690.53198, 80.30833,     0.75784,  44.61539,50.00000,0.0000e+000,20.00000,    -0.53694,0.52129
692.50800, 80.50333,     0.75744,  44.50997,50.00000,0.0000e+000,20.00000,    -0.54916,0.52030
694.38098, 80.68833,     0.75704,  44.40171,50.00000,0.0000e+000,20.00000,    -0.57015,0.51937
696.24103, 80.87334,     0.75241,  44.29345,50.00000,0.0000e+000,20.00000,    -0.58799,0.51846
698.10199, 81.05833,     0.75036,  44.18803,50.00000,0.0000e+000,20.00000,    -0.60770,0.51756
699.95801, 81.24333,     0.75069,  44.07407,50.00000,0.0000e+000,20.00000,    61.46442,0.51667
701.80402, 81.42834,     0.75255,  43.96581,50.00000,0.0000e+000,20.00000,    -0.64039,0.51580
703.64899, 81.61333,     0.75368,  43.83476,50.00000,0.0000e+000,20.00000,    -0.66768,0.51494
705.51898, 81.79833,     0.75676,  43.71510,50.00000,0.0000e+000,20.00000,    -0.67550,0.51408
707.39502, 81.98333,     0.76336,  43.58689,50.00000,0.0000e+000,20.00000,    -0.69352,0.51322
709.25000, 82.16833,     0.76423,  43.46154,50.00000,0.0000e+000,20.00000,    -0.71252,0.51238
711.09399, 82.35333,     0.76154,  43.32194,50.00000,0.0000e+000,20.00000,    -0.71809,0.51156
712.94202, 82.53833,     0.75884,  43.16809,50.00000,0.0000e+000,20.00000,    -0.72271,0.51075
714.78497, 82.72334,     0.75977,  43.04843,50.00000,0.0000e+000,20.00000,    -0.73111,0.50995
716.62299, 82.90833,     0.76269,  42.90313,50.00000,0.0000e+000,20.00000,    -0.75148,0.50917
718.46399, 83.09333,     0.76335,  42.76638,50.00000,0.0000e+000,20.00000,    -0.75261,0.50839
720.31299, 83.27834,     0.76600,  42.63818,50.00000,0.0000e+000,20.00000,    -0.74209,0.50762
722.15802, 83.46333,     0.76908,  42.50143,50.00000,0.0000e+000,20.00000,    -0.73768,0.50686
724.01001, 83.64833,     0.77426,  42.36182,50.00000,0.0000e+000,20.00000,    -0.73805,0.50611
725.86200, 83.83334,     0.78387,  42.19373,50.00000,0.0000e+000,20.00000,    -0.73687,0.50537
727.72803, 84.01833,     0.79595,  42.07408,50.00000,0.0000e+000,20.00000,    -0.72091,0.50463
729.58600, 84.20333,     0.80770,  41.94587,50.00000,0.0000e+000,20.00000,    -0.71093,0.50391
731.45801, 84.38834,     0.82211,  41.80912,50.00000,0.0000e+000,20.00000,    -0.69064,0.50319
733.31097, 84.57333,     0.83329,  41.68376,50.00000,0.0000e+000,20.00000,    -0.67184,0.50250
735.17200, 84.75833,     0.84362,  41.54701,50.00000,0.0000e+000,20.00000,    -0.63223,0.50180
737.01501, 84.94334,     0.85526,  41.43875,50.00000,0.0000e+000,20.00000,    -0.61950,0.50113
738.85901, 85.12833,     0.86695,  41.32764,50.00000,0.0000e+000,20.00000,    -0.58659,0.50046
740.73901, 85.31333,     0.88319,  41.22792,50.00000,0.0000e+000,20.00000,    -0.55474,0.49980
742.67902, 85.49834,     0.91692,  41.12251,50.00000,0.0000e+000,20.00000,    -0.51193,0.49912
744.60303, 85.68333,     0.94474,  41.03134,50.00000,0.0000e+000,20.00000,    -0.46824,0.49846
746.47400, 85.86833,     0.96226,  40.93163,50.00000,0.0000e+000,20.00000,    -0.43815,0.49783
748.30298, 86.05334,     0.97397,  40.86325,50.00000,0.0000e+000,20.00000,    -0.39426,0.49722
750.16803, 86.23833,     0.99513,  40.79202,50.00000,0.0000e+000,20.00000,    -0.36087,0.49661
752.00598, 86.42333,     1.01651,  40.73789,50.00000,0.0000e+000,20.00000,    -0.31465,0.49603
753.85901, 86.60833,     1.03894,  40.67806,50.00000,0.0000e+000,20.00000,    -0.27427,0.49544
755.69897, 86.79333,     1.06192,  40.63248,50.00000,0.0000e+000,20.00000,    -0.23955,0.49487
757.53998, 86.97833,     1.08471,  40.59829,50.00000,0.0000e+000,20.00000,    -0.20269,0.49431
759.37701, 87.16333,     1.10767,  40.56126,50.00000,0.0000e+000,20.00000,    -0.17079,0.49376
761.22198, 87.34834,     1.12404,  40.54131,50.00000,0.0000e+000,20.00000,    -0.14788,0.49322
763.03601, 87.53333,     1.15148,  40.51567,50.00000,0.0000e+000,20.00000,    -0.12525,0.49270
764.86603, 87.71833,     1.18965,  40.49573,50.00000,0.0000e+000,20.00000,    -0.10400,0.49219
766.69702, 87.90334,     1.22023,  40.47863,50.00000,0.0000e+000,20.00000,-9.0928e-002,0.49168
768.55701, 88.08833,     1.23515,  40.47009,50.00000,0.0000e+000,20.00000,-8.0974e-002,0.49118
770.40399, 88.27333,     1.24680,  40.45584,50.00000,0.0000e+000,20.00000,-7.4310e-002,0.49069
772.25098, 88.45834,     1.25467,  40.44729,50.00000,0.0000e+000,20.00000,-6.5162e-002,0.49021
774.08698, 88.64333,     1.26297,  40.43590,50.00000,0.0000e+000,20.00000,-5.8871e-002,0.48974
775.92700, 88.82833,     1.26908,  40.42450,50.00000,0.0000e+000,20.00000,-5.5203e-002,0.48928
777.77197, 89.01334,     1.27826,  40.41025,50.00000,0.0000e+000,20.00000,-5.6820e-002,0.48883
779.63800, 89.19833,     1.28672,  40.40171,50.00000,0.0000e+000,20.00000,-4.7810e-002,0.48839
781.50702, 89.38333,     1.29312,  40.39601,50.00000,0.0000e+000,20.00000,-4.8093e-002,0.48795
783.36499, 89.56834,     1.29634,  40.38462,50.00000,0.0000e+000,20.00000,-4.6860e-002,0.48753
785.22400, 89.75333,     1.29922,  40.37607,50.00000,0.0000e+000,20.00000,-4.1397e-002,0.48712
787.09998, 89.93833,     1.30334,  40.36752,50.00000,0.0000e+000,20.00000,-3.8924e-002,0.48671
788.99597, 90.12334,     1.31130,  40.36467,50.00000,0.0000e+000,20.00000,-3.9990e-002,0.48631
790.88898, 90.30833,     1.31329,  40.35897,50.00000,0.0000e+000,20.00000,-3.7039e-002,0.48592
792.73297, 90.49333,     1.30636,  40.35328,50.00000,0.0000e+000,20.00000,-3.6310e-002,0.48555
794.57898, 90.67834,     1.30029,  40.34758,50.00000,0.0000e+000,20.00000,-3.5822e-002,0.48519
796.44202, 90.86333,     1.29810,  40.34188,50.00000,0.0000e+000,20.00000,-3.7861e-002,0.48484
798.29303, 91.04833,     1.29776,  40.33049,50.00000,0.0000e+000,20.00000,-3.9678e-002,0.48450
800.15198, 91.23333,     1.29887,  40.32764,50.00000,0.0000e+000,20.00000,-3.8958e-002,0.48417
802.00702, 91.41833,     1.30023,  40.31624,50.00000,0.0000e+000,20.00000,-3.8948e-002,0.48384
803.88000, 91.60333,     1.29609,  40.31054,50.00000,0.0000e+000,20.00000,-3.7416e-002,0.48353
805.73798, 91.78833,     1.29222,  40.29914,50.00000,0.0000e+000,20.00000,-4.0077e-002,0.48323
807.59003, 91.97334,     1.28864,  40.29345,50.00000,0.0000e+000,20.00000,-3.5977e-002,0.48293
809.44800, 92.15833,     1.28228,  40.29060,50.00000,0.0000e+000,20.00000,-3.7347e-002,0.48265
811.31000, 92.34333,     1.28080,  40.28490,50.00000,0.0000e+000,20.00000,-3.4091e-002,0.48238
813.16498, 92.52834,     1.27943,  40.27350,50.00000,0.0000e+000,20.00000,-3.0915e-002,0.48211
815.01599, 92.71333,     1.27821,  40.26496,50.00000,0.0000e+000,20.00000,-3.2206e-002,0.48186
816.85101, 92.89833,     1.27722,  40.25926,50.00000,0.0000e+000,20.00000,-3.0845e-002,0.48162
818.69000, 93.08334,     1.27667,  40.25926,50.00000,0.0000e+000,20.00000,-3.4084e-002,0.48138
820.53003, 93.26833,     1.27189,  40.25641,50.00000,0.0000e+000,20.00000,-3.0040e-002,0.48116
822.38397, 93.45333,     1.27101,  40.25071,50.00000,0.0000e+000,20.00000,-2.9220e-002,0.48094
824.22601, 93.63834,     1.26912,  40.24216,50.00000,0.0000e+000,20.00000,-2.3739e-002,0.48074
826.07098, 93.82333,     1.26941,  40.23932,50.00000,0.0000e+000,20.00000,-2.3824e-002,0.48054
827.93201, 94.00833,     1.26959,  40.23077,50.00000,0.0000e+000,20.00000,-2.5981e-002,0.48035
829.80499, 94.19334,     1.27256,  40.23077,50.00000,0.0000e+000,20.00000,-2.5330e-002,0.48017
831.70697, 94.37833,     1.28258,  40.22222,50.00000,0.0000e+000,20.00000,-3.0815e-002,0.48000
833.60901, 94.56333,     1.28755,  40.21937,50.00000,0.0000e+000,20.00000,-2.9186e-002,0.47983
835.48700, 94.74834,     1.28275,  40.21653,50.00000,0.0000e+000,20.00000,-3.4641e-002,0.47968
837.33002, 94.93333,     1.27764,  40.20798,50.00000,0.0000e+000,20.00000,-3.2575e-002,0.47954
839.17798, 95.11833,     1.27151,  40.20798,50.00000,0.0000e+000,20.00000,-3.4090e-002,0.47941
841.03003, 95.30334,     1.26476,  40.19373,50.00000,0.0000e+000,20.00000,-3.5451e-002,0.47928
842.86700, 95.48833,     1.26017,  40.18804,50.00000,0.0000e+000,20.00000,-3.4902e-002,0.47917
844.72101, 95.67333,     1.26167,  40.17094,50.00000,0.0000e+000,20.00000,-3.1025e-002,0.47906
846.57501, 95.85833,     1.26411,  40.17094,50.00000,0.0000e+000,20.00000,-3.4186e-002,0.47896
848.42700, 96.04333,     1.26556,  40.16809,50.00000,0.0000e+000,20.00000,-3.4139e-002,0.47888
850.29199, 96.22833,     1.26396,  40.16239,50.00000,0.0000e+000,20.00000,-2.9220e-002,0.47880
852.12598, 96.41333,     1.26728,  40.15669,50.00000,0.0000e+000,20.00000,-2.7023e-002,0.47872
853.95801, 96.59834,     1.26690,  40.15670,50.00000,0.0000e+000,20.00000,-2.2728e-002,0.47866
855.79797, 96.78333,     1.26659,  40.15100,50.00000,0.0000e+000,20.00000,-2.6481e-002,0.47861
857.61902, 96.96833,     1.26316,  40.13960,50.00000,0.0000e+000,20.00000,-3.0335e-002,0.47856
859.44897, 97.15334,     1.26417,  40.13960,50.00000,0.0000e+000,20.00000,-2.8578e-002,0.47853
861.32098, 97.33833,     1.27701,  40.13391,50.00000,0.0000e+000,20.00000,-3.1928e-002,0.47850
863.19397, 97.52333,     1.27961,  40.12536,50.00000,0.0000e+000,20.00000,-2.7883e-002,0.47848
865.02600, 97.70834,     1.27896,  40.11966,50.00000,0.0000e+000,20.00000,-2.7597e-002,0.47847
866.84998, 97.89333,     1.27420,  40.10826,50.00000,0.0000e+000,20.00000,-2.7598e-002,0.47846
868.69501, 98.07833,     1.27577,  40.10826,50.00000,0.0000e+000,20.00000,-2.9220e-002,0.47847
870.55701, 98.26334,     1.27933,  40.10256,50.00000,0.0000e+000,20.00000,-3.1656e-002,0.47848
872.42999, 98.44833,     1.28250,  40.09686,50.00000,0.0000e+000,20.00000,-3.1192e-002,0.47850
874.30603, 98.63333,     1.28641,  40.09117,50.00000,0.0000e+000,20.00000,-3.2360e-002,0.47853
876.16699, 98.81834,     1.28432,  40.08547,50.00000,0.0000e+000,20.00000,-3.0866e-002,0.47857
878.03497, 99.00333,     1.28823,  40.08262,50.00000,0.0000e+000,20.00000,-3.4096e-002,0.47861
879.91199, 99.18833,     1.29100,  40.07977,50.00000,0.0000e+000,20.00000,-3.5714e-002,0.47867
881.78101, 99.37334,     1.29037,  40.06838,50.00000,0.0000e+000,20.00000,-3.2684e-002,0.47873
883.64203, 99.55833,     1.29178,  40.05698,50.00000,0.0000e+000,20.00000,-3.4092e-002,0.47880
885.50500, 99.74333,     1.29261,  40.05128,50.00000,0.0000e+000,20.00000,-3.4090e-002,0.47888
887.40601, 99.92834,     1.29755,  40.04559,50.00000,0.0000e+000,20.00000,-3.8852e-002,0.47896
889.32397,100.11333,     1.30582,  40.03704,50.00000,0.0000e+000,20.00000,-3.8711e-002,0.47906
891.20099,100.29833,     1.30908,  40.03419,50.00000,0.0000e+000,20.00000,-3.9224e-002,0.47916
893.05798,100.48333,     1.30361,  40.02849,50.00000,0.0000e+000,20.00000,-3.7330e-002,0.47927
894.88202,100.66833,     1.28902,  40.02279,50.00000,0.0000e+000,20.00000,-3.7842e-002,0.47938
896.69202,100.85333,     1.28258,  40.01140,50.00000,0.0000e+000,20.00000,-3.4164e-002,0.47950
898.52899,101.03833,     1.27526,  40.00285,50.00000,0.0000e+000,20.00000,-3.2361e-002,0.47963
900.36499,101.22334,     1.27879,  39.99715,50.00000,0.0000e+000,20.00000,-3.3584e-002,0.47977
902.20801,101.40833,     1.28131,  39.98860,50.00000,0.0000e+000,20.00000,-3.0320e-002,0.47991
904.05701,101.59333,     1.28453,  39.98861,50.00000,0.0000e+000,20.00000,-2.9439e-002,0.48006
905.89801,101.77834,     1.28374,  39.98575,50.00000,0.0000e+000,20.00000,-3.3072e-002,0.48022
907.72900,101.96333,     1.28167,  39.98005,50.00000,0.0000e+000,20.00000,-3.2471e-002,0.48039
909.58698,102.14833,     1.28216,  39.97721,50.00000,0.0000e+000,20.00000,-3.3850e-002,0.48056
911.44598,102.33334,     1.28697,  39.97151,50.00000,0.0000e+000,20.00000,-3.1364e-002,0.48074
913.31799,102.51833,     1.28864,  39.96296,50.00000,0.0000e+000,20.00000,-3.4117e-002,0.48093
915.18799,102.70333,     1.28735,  39.95157,50.00000,0.0000e+000,20.00000,-3.4334e-002,0.48112
917.04999,102.88834,     1.28536,  39.94017,50.00000,0.0000e+000,20.00000,-3.5183e-002,0.48132
918.90802,103.07333,     1.28400,  39.93732,50.00000,0.0000e+000,20.00000,-3.7775e-002,0.48153
920.77301,103.25833,     1.28094,  39.92877,50.00000,0.0000e+000,20.00000,-3.8062e-002,0.48175
922.63000,103.44334,     1.27905,  39.92593,50.00000,0.0000e+000,20.00000,-3.9103e-002,0.48197
924.48602,103.62833,     1.27966,  39.91738,50.00000,0.0000e+000,20.00000,-3.7599e-002,0.48220
926.37000,103.81333,     1.27876,  39.91453,50.00000,0.0000e+000,20.00000,-3.5716e-002,0.48243
928.23102,103.99834,     1.27749,  39.90883,50.00000,0.0000e+000,20.00000,-3.5223e-002,0.48267
930.10699,104.18333,     1.27679,  39.89459,50.00000,0.0000e+000,20.00000,-3.4615e-002,0.48292
931.94098,104.36833,     1.27163,  39.88889,50.00000,0.0000e+000,20.00000,-3.8744e-002,0.48317
933.75800,104.55334,     1.26116,  39.88319,50.00000,0.0000e+000,20.00000,-3.7339e-002,0.48343
935.59399,104.73833,     1.25253,  39.87749,50.00000,0.0000e+000,20.00000,-3.9866e-002,0.48369
937.44501,104.92333,     1.25641,  39.87180,50.00000,0.0000e+000,20.00000,-4.0062e-002,0.48396
939.28601,105.10833,     1.26436,  39.86040,50.00000,0.0000e+000,20.00000,-3.2475e-002,0.48423
941.14502,105.29333,     1.27210,  39.85185,50.00000,0.0000e+000,20.00000,-3.3587e-002,0.48452
943.00299,105.47833,     1.27838,  39.84900,50.00000,0.0000e+000,20.00000,-2.9591e-002,0.48480
944.87903,105.66333,     1.28181,  39.84330,50.00000,0.0000e+000,20.00000,-3.3557e-002,0.48510
946.75598,105.84834,     1.28414,  39.83760,50.00000,0.0000e+000,20.00000,-3.6208e-002,0.48541
948.60602,106.03333,     1.28074,  39.83476,50.00000,0.0000e+000,20.00000,-3.0842e-002,0.48571
950.44800,106.21833,     1.28144,  39.82336,50.00000,0.0000e+000,20.00000,-3.0846e-002,0.48602
952.29901,106.40334,     1.28396,  39.82906,50.00000,0.0000e+000,20.00000,-3.4165e-002,0.48634
954.16803,106.58833,     1.28838,  39.81481,50.00000,0.0000e+000,20.00000,-3.7599e-002,0.48666
956.00800,106.77333,     1.28627,  39.80627,50.00000,0.0000e+000,20.00000,-4.1879e-002,0.48698
957.86902,106.95834,     1.28744,  39.80342,50.00000,0.0000e+000,20.00000,-4.0583e-002,0.48732
959.71899,107.14333,     1.28958,  39.79202,50.00000,0.0000e+000,20.00000,-4.0579e-002,0.48766
961.55701,107.32833,     1.28886,  39.78633,50.00000,0.0000e+000,20.00000,-4.5655e-002,0.48800
963.41101,107.51334,     1.29101,  39.77208,50.00000,0.0000e+000,20.00000,-4.2247e-002,0.48834
965.26801,107.69833,     1.29039,  39.76354,50.00000,0.0000e+000,20.00000,-4.2104e-002,0.48870
967.10999,107.88333,     1.29572,  39.75783,50.00000,0.0000e+000,20.00000,-3.9973e-002,0.48905
968.96899,108.06834,     1.30497,  39.75213,50.00000,0.0000e+000,20.00000,-4.3898e-002,0.48942
970.83801,108.25333,     1.31494,  39.74359,50.00000,0.0000e+000,20.00000,-4.3844e-002,0.48979
972.69202,108.43833,     1.31780,  39.74359,50.00000,0.0000e+000,20.00000,-3.6325e-002,0.49016
974.55402,108.62334,     1.32143,  39.72935,50.00000,0.0000e+000,20.00000,-3.7835e-002,0.49054
976.40302,108.80833,     1.32559,  39.72649,50.00000,0.0000e+000,20.00000,-3.8699e-002,0.49092
978.25201,108.99333,     1.32946,  39.70940,50.00000,0.0000e+000,20.00000,-3.6417e-002,0.49131
980.10498,109.17834,     1.33265,  39.70370,50.00000,0.0000e+000,20.00000,-3.5717e-002,0.49170
981.96600,109.36333,     1.33369,  39.70085,50.00000,0.0000e+000,20.00000,-3.9485e-002,0.49209
983.86200,109.54833,     1.33907,  39.69231,50.00000,0.0000e+000,20.00000,-4.0552e-002,0.49250
985.72699,109.73333,     1.33290,  39.68946,50.00000,0.0000e+000,20.00000,-4.1953e-002,0.49291
987.56702,109.91833,     1.32824,  39.68661,50.00000,0.0000e+000,20.00000,-3.2756e-002,0.49331
989.41498,110.10333,     1.32123,  39.67521,50.00000,0.0000e+000,20.00000,-3.6788e-002,0.49372
991.24298,110.28833,     1.31776,  39.66382,50.00000,0.0000e+000,20.00000,-3.4089e-002,0.49413
993.09198,110.47334,     1.32104,  39.65527,50.00000,0.0000e+000,20.00000,-4.0613e-002,0.49455
994.94202,110.65833,     1.32298,  39.64957,50.00000,0.0000e+000,20.00000,-2.9364e-002,0.49498
996.79498,110.84333,     1.32360,  39.64672,50.00000,0.0000e+000,20.00000,-1.2669e-002,0.49540
998.34802,110.99834,     1.32482,  39.64388,50.00000,0.0000e+000,20.00000,-3.7308e-002,0.49577