File: ExpDat_CA_FeCN_5050-2.csv
#FILE:                       ,CA_FeCN_5050.ngb-ds3
#FORMAT:                     ,NETZSCH5
#IDENTITY:                   ,CA_FeCN_5050
#DECIMAL:                    ,POINT
#SEPARATOR:                  ,COMMA
#MTYPE:                      ,DSC
#INSTRUMENT:                 ,Microlab TU Delft
#PROJECT:                    ,
#DATE/TIME:                  ,2/05/2023 3:52:04 PM
#CORR. FILE:                 ,2023_04_25.ngb-bs3
#LABORATORY:                 ,TU Delft Micro Lab
#OPERATOR:                   ,Ameya
#REMARK:                     ,under argon atmosphere, 10K/min
#SAMPLE:                     ,CA_FeCN_5050
#SAMPLE MASS /mg:            ,37.6
#MATERIAL:                   ,Capsules
#REFERENCE:                  ,blank
#REFERENCE MASS /mg:         ,0
#TYPE OF CRUCIBLE:           ,DSC/TG pan Al2O3
#SAMPLE CRUCIBLE MASS /mg:   ,0
#REFERENCE CRUCIBLE MASS /mg:,0
#CORR. CODE:                 ,020
#EXO:                        ,+1
#RANGE:                      ,40/10.0(K/min)/1000
#SEGMENT:                    ,S2/2

##Temp./øC,Time/min,DSC/(mW/mg),Mass/%,Gas Flow(purge1)/(ml/min),Gas Flow(purge2)/(ml/min),Gas Flow(protective)/(ml/min),DTG/(%/min),Sensit./(uV/mW)
 40.58400, 15.02667,-5.5356e-002,  98.52128,50.00000,0.0000e+000,20.00000,    -0.12112,0.95853
 40.63700, 15.21167,-5.5101e-002,  98.49468,50.00000,0.0000e+000,20.00000,    -0.13344,0.95855
 40.70400, 15.39667,-5.6243e-002,  98.47074,50.00000,0.0000e+000,20.00000,    -0.13256,0.95857
 40.81100, 15.58167,-5.8316e-002,  98.44947,50.00000,0.0000e+000,20.00000,    -0.13614,0.95860
 40.97500, 15.76667,-6.1785e-002,  98.42287,50.00000,0.0000e+000,20.00000,    -0.14112,0.95864
 41.19600, 15.95167,-6.6353e-002,  98.39894,50.00000,0.0000e+000,20.00000,    -0.14543,0.95870
 41.49200, 16.13667,-7.3014e-002,  98.36968,50.00000,0.0000e+000,20.00000,    -0.14679,0.95877
 41.89700, 16.32167,-7.9862e-002,  98.34043,50.00000,0.0000e+000,20.00000,    -0.15170,0.95888
 42.34100, 16.50667,-8.8316e-002,  98.31117,50.00000,0.0000e+000,20.00000,    -0.15545,0.95899
 42.87100, 16.69167,-9.7845e-002,  98.27926,50.00000,0.0000e+000,20.00000,    -0.15897,0.95913
 43.50400, 16.87667,    -0.10783,  98.25000,50.00000,0.0000e+000,20.00000,    -0.16114,0.95929
 44.23100, 17.06167,    -0.11851,  98.22340,50.00000,0.0000e+000,20.00000,    -0.16665,0.95947
 45.02900, 17.24667,    -0.13001,  98.19415,50.00000,0.0000e+000,20.00000,    -0.17223,0.95966
 45.92300, 17.43167,    -0.14157,  98.16489,50.00000,0.0000e+000,20.00000,    -0.17685,0.95987
 46.90300, 17.61667,    -0.15460,  98.13298,50.00000,0.0000e+000,20.00000,    -0.18668,0.96010
 47.95900, 17.80167,    -0.16749,  98.09840,50.00000,0.0000e+000,20.00000,    -0.20007,0.96034
 49.09600, 17.98667,    -0.18143,  98.06383,50.00000,0.0000e+000,20.00000,    -0.21041,0.96059
 50.32400, 18.17167,    -0.19585,  98.02660,50.00000,0.0000e+000,20.00000,    -0.22687,0.96085
 51.64300, 18.35667,    -0.21105,  97.97872,50.00000,0.0000e+000,20.00000,    -0.24518,0.96112
 53.02300, 18.54167,    -0.22741,  97.93085,50.00000,0.0000e+000,20.00000,    -0.27220,0.96139
 54.51500, 18.72667,    -0.24473,  97.88564,50.00000,0.0000e+000,20.00000,    -0.30170,0.96168
 56.06600, 18.91167,    -0.26299,  97.83245,50.00000,0.0000e+000,20.00000,    -0.34048,0.96196
 57.68700, 19.09667,    -0.28255,  97.76862,50.00000,0.0000e+000,20.00000,    -0.38308,0.96224
 59.38000, 19.28167,    -0.30384,  97.70479,50.00000,0.0000e+000,20.00000,    -0.43020,0.96251
 61.16200, 19.46667,    -0.32700,  97.62234,50.00000,0.0000e+000,20.00000,    -0.47970,0.96278
 62.99600, 19.65167,    -0.35304,  97.53457,50.00000,0.0000e+000,20.00000,    -0.55568,0.96304
 64.89800, 19.83667,    -0.38088,  97.42553,50.00000,0.0000e+000,20.00000,    -0.62406,0.96330
 66.85700, 20.02167,    -0.41265,  97.30851,50.00000,0.0000e+000,20.00000,    -0.70004,0.96353
 68.86800, 20.20667,    -0.44807,  97.18351,50.00000,0.0000e+000,20.00000,    -0.78845,0.96375
 70.92800, 20.39167,    -0.48940,  97.04521,50.00000,0.0000e+000,20.00000,    -0.88026,0.96396
 73.03400, 20.57667,    -0.53410,  96.85106,50.00000,0.0000e+000,20.00000,    -0.98276,0.96414
 75.15900, 20.76167,    -0.58453,  96.67021,50.00000,0.0000e+000,20.00000,    -1.08902,0.96430
 77.36700, 20.94667,    -0.63919,  96.46809,50.00000,0.0000e+000,20.00000,    -1.21446,0.96444
 79.57600, 21.13167,    -0.69901,  96.24202,50.00000,0.0000e+000,20.00000,    -1.34701,0.96455
 81.84100, 21.31667,    -0.76100,  95.98936,50.00000,0.0000e+000,20.00000,    -1.48954,0.96463
 84.10400, 21.50167,    -0.82597,  95.70745,50.00000,0.0000e+000,20.00000,    -1.63361,0.96469
 86.41000, 21.68667,    -0.89062,  95.40160,50.00000,0.0000e+000,20.00000,    -1.80180,0.96472
 88.75000, 21.87167,    -0.95138,  95.05585,50.00000,0.0000e+000,20.00000,    -1.98243,0.96472
 91.12000, 22.05667,    -1.00881,  94.68085,50.00000,0.0000e+000,20.00000,    -2.17517,0.96469
 93.51000, 22.24167,    -1.06334,  94.27128,50.00000,0.0000e+000,20.00000,    -2.37602,0.96463
 95.89800, 22.42667,    -1.11622,  93.81649,50.00000,0.0000e+000,20.00000,    -2.58627,0.96454
 98.33000, 22.61167,    -1.16747,  93.32447,50.00000,0.0000e+000,20.00000,    -2.80226,0.96441
100.77100, 22.79667,    -1.21829,  92.78457,50.00000,0.0000e+000,20.00000,    -3.02464,0.96426
103.22200, 22.98167,    -1.26751,  92.20213,50.00000,0.0000e+000,20.00000,    -3.24956,0.96407
105.68300, 23.16667,    -1.31597,  91.57979,50.00000,0.0000e+000,20.00000,    -3.47269,0.96384
108.15800, 23.35167,    -1.36526,  90.91755,50.00000,0.0000e+000,20.00000,    -3.68733,0.96358
110.61600, 23.53667,    -1.41351,  90.20745,50.00000,0.0000e+000,20.00000,    -3.88539,0.96330
113.09200, 23.72167,    -1.46348,  89.45479,50.00000,0.0000e+000,20.00000,    -4.06710,0.96297
115.57500, 23.90667,    -1.51439,  88.66755,50.00000,0.0000e+000,20.00000,    -4.22383,0.96262
118.04700, 24.09167,    -1.56605,  87.86170,50.00000,0.0000e+000,20.00000,    -4.35549,0.96223
120.51600, 24.27667,    -1.61517,  87.01862,50.00000,0.0000e+000,20.00000,    -4.45687,0.96181
122.99400, 24.46167,    -1.66044,  86.15957,50.00000,0.0000e+000,20.00000,    -4.51328,0.96136
125.45600, 24.64667,    -1.69873,  85.29521,50.00000,0.0000e+000,20.00000,    -4.52390,0.96089
127.92500, 24.83167,    -1.72961,  84.41755,50.00000,0.0000e+000,20.00000,    -4.48172,0.96037
130.39600, 25.01667,    -1.75180,  83.55585,50.00000,0.0000e+000,20.00000,    -4.39666,0.95983
132.85201, 25.20167,    -1.76396,  82.72074,50.00000,0.0000e+000,20.00000,    -4.26253,0.95926
135.31100, 25.38667,    -1.76473,  81.90957,50.00000,0.0000e+000,20.00000,    -4.08452,0.95866
137.76900, 25.57167,    -1.75285,  81.13830,50.00000,0.0000e+000,20.00000,    -3.87003,0.95803
140.23000, 25.75667,    -1.72581,  80.42553,50.00000,0.0000e+000,20.00000,    -3.62207,0.95737
142.69400, 25.94167,    -1.68277,  79.76330,50.00000,0.0000e+000,20.00000,    -3.35420,0.95668
145.16901, 26.12667,    -1.62313,  79.16755,50.00000,0.0000e+000,20.00000,    -3.07536,0.95595
147.62500, 26.31167,    -1.54750,  78.62766,50.00000,0.0000e+000,20.00000,    -2.79634,0.95520
150.08701, 26.49667,    -1.45829,  78.14894,50.00000,0.0000e+000,20.00000,    -2.51778,0.95442
152.55400, 26.68167,    -1.36150,  77.73138,50.00000,0.0000e+000,20.00000,    -2.25674,0.95361
155.00900, 26.86667,    -1.25928,  77.35106,50.00000,0.0000e+000,20.00000,    -2.01428,0.95277
157.46500, 27.05167,    -1.15621,  77.01596,50.00000,0.0000e+000,20.00000,    -1.79004,0.95191
159.90500, 27.23667,    -1.05686,  76.72074,50.00000,0.0000e+000,20.00000,    -1.59335,0.95102
162.33200, 27.42167,    -0.96277,  76.46276,50.00000,0.0000e+000,20.00000,    -1.42319,0.95011
164.73300, 27.60667,    -0.87592,  76.22341,50.00000,0.0000e+000,20.00000,    -1.28364,0.94918
167.11301, 27.79167,    -0.79511,  76.01330,50.00000,0.0000e+000,20.00000,    -1.15972,0.94823
169.45500, 27.97667,    -0.72086,  75.83245,50.00000,0.0000e+000,20.00000,    -1.05192,0.94727
171.76199, 28.16167,    -0.65375,  75.67021,50.00000,0.0000e+000,20.00000,    -0.95552,0.94631
174.04500, 28.34667,    -0.59588,  75.50000,50.00000,0.0000e+000,20.00000,    -0.87650,0.94533
176.29800, 28.53167,    -0.54886,  75.33777,50.00000,0.0000e+000,20.00000,    -0.80362,0.94434
178.51300, 28.71667,    -0.50879,  75.18085,50.00000,0.0000e+000,20.00000,    -0.74089,0.94334
180.69299, 28.90167,    -0.47165,  75.06117,50.00000,0.0000e+000,20.00000,    -0.68792,0.94234
182.84399, 29.08667,    -0.43428,  74.94681,50.00000,0.0000e+000,20.00000,    -0.64400,0.94133
184.97600, 29.27167,    -0.39822,  74.83777,50.00000,0.0000e+000,20.00000,    -0.59017,0.94031
187.07600, 29.45667,    -0.36476,  74.73404,50.00000,0.0000e+000,20.00000,    -0.54204,0.93929
189.14799, 29.64167,    -0.33484,  74.64096,50.00000,0.0000e+000,20.00000,    -0.49037,0.93826
191.19299, 29.82667,    -0.30750,  74.56117,50.00000,0.0000e+000,20.00000,    -0.45947,0.93722
193.20100, 30.01167,    -0.28308,  74.47606,50.00000,0.0000e+000,20.00000,    -0.43155,0.93619
195.19800, 30.19667,    -0.26124,  74.40160,50.00000,0.0000e+000,20.00000,    -0.40015,0.93515
197.17000, 30.38167,    -0.24168,  74.33511,50.00000,0.0000e+000,20.00000,    -0.38047,0.93410
199.11000, 30.56667,    -0.22419,  74.27128,50.00000,0.0000e+000,20.00000,    -0.35892,0.93306
201.02600, 30.75167,    -0.20815,  74.20745,50.00000,0.0000e+000,20.00000,    -0.34611,0.93201
202.93800, 30.93667,    -0.19357,  74.14628,50.00000,0.0000e+000,20.00000,    -0.32740,0.93095
204.82401, 31.12167,    -0.17993,  74.09309,50.00000,0.0000e+000,20.00000,    -0.31397,0.92989
206.68201, 31.30667,    -0.16699,  74.02926,50.00000,0.0000e+000,20.00000,    -0.30382,0.92883
208.52800, 31.49167,    -0.15452,  73.97074,50.00000,0.0000e+000,20.00000,    -0.29916,0.92777
210.37399, 31.67667,    -0.14237,  73.91755,50.00000,0.0000e+000,20.00000,    -0.28860,0.92669
212.19299, 31.86167,    -0.12947,  73.86968,50.00000,0.0000e+000,20.00000,    -0.28818,0.92561
214.01900, 32.04667,    -0.11628,  73.82181,50.00000,0.0000e+000,20.00000,    -0.29076,0.92452
215.81200, 32.23167,    -0.10182,  73.77128,50.00000,0.0000e+000,20.00000,    -0.30231,0.92344
217.61200, 32.41667,-8.5974e-002,  73.72075,50.00000,0.0000e+000,20.00000,    -0.33217,0.92233
219.40800, 32.60167,-6.8105e-002,  73.67021,50.00000,0.0000e+000,20.00000,    -0.36964,0.92122
221.20700, 32.78667,-4.7877e-002,  73.61170,50.00000,0.0000e+000,20.00000,    -0.44615,0.92009
222.98100, 32.97167,-2.6540e-002,  73.54787,50.00000,0.0000e+000,20.00000,    -0.51226,0.91897
224.76601, 33.15667,-4.8858e-003,  73.45745,50.00000,0.0000e+000,20.00000,    -0.59176,0.91783
226.54500, 33.34167, 1.6070e-002,  73.34840,50.00000,0.0000e+000,20.00000,    -0.67393,0.91668
228.31599, 33.52667, 3.5217e-002,  73.21809,50.00000,0.0000e+000,20.00000,    -0.76380,0.91553
230.09399, 33.71167, 5.2017e-002,  73.02926,50.00000,0.0000e+000,20.00000,    -0.84891,0.91435
231.86400, 33.89667, 6.7194e-002,  72.86170,50.00000,0.0000e+000,20.00000,    -0.92814,0.91318
233.63600, 34.08167, 7.9051e-002,  72.67287,50.00000,0.0000e+000,20.00000,    -0.99015,0.91199
235.39400, 34.26667, 8.8734e-002,  72.47606,50.00000,0.0000e+000,20.00000,    -1.04396,0.91079
237.14799, 34.45167, 9.5209e-002,  72.26064,50.00000,0.0000e+000,20.00000,    -1.07191,0.90959
238.89101, 34.63667, 9.8909e-002,  72.05851,50.00000,0.0000e+000,20.00000,    -1.07961,0.90839
240.64101, 34.82167,     0.10112,  71.84840,50.00000,0.0000e+000,20.00000,    -1.08131,0.90717
242.38200, 35.00667,     0.10151,  71.63298,50.00000,0.0000e+000,20.00000,    -1.07239,0.90595
244.10899, 35.19167,     0.10045,  71.43351,50.00000,0.0000e+000,20.00000,    -1.05308,0.90473
245.84000, 35.37667, 9.8929e-002,  71.24202,50.00000,0.0000e+000,20.00000,    -1.02454,0.90349
247.58299, 35.56167, 9.6840e-002,  71.05319,50.00000,0.0000e+000,20.00000,    -0.99676,0.90224
249.31500, 35.74667, 9.4205e-002,  70.87500,50.00000,0.0000e+000,20.00000,    -0.96949,0.90098
251.06900, 35.93167, 9.1904e-002,  70.70213,50.00000,0.0000e+000,20.00000,    -0.93005,0.89970
252.80701, 36.11666, 8.9550e-002,  70.54255,50.00000,0.0000e+000,20.00000,    -0.90801,0.89842
254.54800, 36.30167, 8.8119e-002,  70.36702,50.00000,0.0000e+000,20.00000,    -0.88511,0.89713
256.29800, 36.48667, 8.7500e-002,  70.22074,50.00000,0.0000e+000,20.00000,    -0.87770,0.89582
258.04199, 36.67167, 8.7583e-002,  70.05851,50.00000,0.0000e+000,20.00000,    -0.86827,0.89451
259.81000, 36.85667, 8.8214e-002,  69.91755,50.00000,0.0000e+000,20.00000,    -0.87242,0.89316
261.56601, 37.04167, 8.9917e-002,  69.74468,50.00000,0.0000e+000,20.00000,    -0.89151,0.89182
263.32599, 37.22667, 9.2036e-002,  69.59308,50.00000,0.0000e+000,20.00000,    -0.91059,0.89047
265.10300, 37.41167, 9.5009e-002,  69.42287,50.00000,0.0000e+000,20.00000,    -0.96209,0.88909
266.88501, 37.59667, 9.7397e-002,  69.25532,50.00000,0.0000e+000,20.00000,    -1.00890,0.88770
268.64801, 37.78167, 9.9518e-002,  69.07447,50.00000,0.0000e+000,20.00000,    -1.07457,0.88632
270.43301, 37.96667,     0.10183,  68.87766,50.00000,0.0000e+000,20.00000,    -1.13042,0.88491
272.23199, 38.15167,     0.10370,  68.66489,50.00000,0.0000e+000,20.00000,    -1.20173,0.88347
274.01700, 38.33667,     0.10607,  68.43351,50.00000,0.0000e+000,20.00000,    -1.27669,0.88204
275.79401, 38.52167,     0.10827,  68.18351,50.00000,0.0000e+000,20.00000,    -1.34398,0.88061
277.58701, 38.70667,     0.11157,  67.92553,50.00000,0.0000e+000,20.00000,    -1.41433,0.87916
279.38901, 38.89167,     0.11575,  67.64894,50.00000,0.0000e+000,20.00000,    -1.47892,0.87769
281.18399, 39.07667,     0.12174,  67.36436,50.00000,0.0000e+000,20.00000,    -1.54353,0.87622
282.98499, 39.26167,     0.12863,  67.07181,50.00000,0.0000e+000,20.00000,    -1.59845,0.87473
284.78299, 39.44667,     0.13649,  66.77128,50.00000,0.0000e+000,20.00000,    -1.65494,0.87324
286.57999, 39.63167,     0.14494,  66.46277,50.00000,0.0000e+000,20.00000,    -1.70474,0.87174
288.38501, 39.81667,     0.15312,  66.14894,50.00000,0.0000e+000,20.00000,    -1.74765,0.87022
290.18600, 40.00167,     0.16124,  65.82181,50.00000,0.0000e+000,20.00000,    -1.78220,0.86870
292.00000, 40.18667,     0.16700,  65.48404,50.00000,0.0000e+000,20.00000,    -1.80279,0.86716
293.79401, 40.37167,     0.17076,  65.12766,50.00000,0.0000e+000,20.00000,    -1.81130,0.86563
295.59799, 40.55667,     0.17130,  64.77394,50.00000,0.0000e+000,20.00000,    -1.79700,0.86409
297.41400, 40.74166,     0.16893,  64.42021,50.00000,0.0000e+000,20.00000,    -1.76484,0.86252
299.21201, 40.92667,     0.16365,  64.07979,50.00000,0.0000e+000,20.00000,    -1.70899,0.86097
301.00699, 41.11167,     0.15503,  63.75532,50.00000,0.0000e+000,20.00000,    -1.63076,0.85940
302.80301, 41.29667,     0.14358,  63.44149,50.00000,0.0000e+000,20.00000,    -1.52668,0.85783
304.60300, 41.48167,     0.13074,  63.15957,50.00000,0.0000e+000,20.00000,    -1.40149,0.85625
306.38800, 41.66667,     0.11503,  62.90691,50.00000,0.0000e+000,20.00000,    -1.27244,0.85468
308.18399, 41.85167, 9.8471e-002,  62.68085,50.00000,0.0000e+000,20.00000,    -1.14618,0.85309
309.98199, 42.03667, 8.1713e-002,  62.47872,50.00000,0.0000e+000,20.00000,    -1.01958,0.85149
311.78101, 42.22167, 6.4869e-002,  62.31383,50.00000,0.0000e+000,20.00000,    -0.90002,0.84988
313.56100, 42.40667, 4.9323e-002,  62.18617,50.00000,0.0000e+000,20.00000,    -0.78841,0.84828
315.36099, 42.59167, 3.4511e-002,  62.06383,50.00000,0.0000e+000,20.00000,    -0.69187,0.84666
317.15701, 42.77667, 1.9066e-002,  61.94947,50.00000,0.0000e+000,20.00000,    -0.60862,0.84503
318.96201, 42.96167, 6.5921e-003,  61.85106,50.00000,0.0000e+000,20.00000,    -0.53539,0.84339
320.78101, 43.14667,-4.8212e-003,  61.76330,50.00000,0.0000e+000,20.00000,    -0.48473,0.84173
322.60101, 43.33167,-1.3792e-002,  61.68883,50.00000,0.0000e+000,20.00000,    -0.45061,0.84007
324.40601, 43.51667,-2.0741e-002,  61.60904,50.00000,0.0000e+000,20.00000,    -0.41342,0.83841
326.21701, 43.70167,-2.5802e-002,  61.53989,50.00000,0.0000e+000,20.00000,    -0.38367,0.83674
328.04199, 43.88667,-2.9912e-002,  61.47606,50.00000,0.0000e+000,20.00000,    -0.36235,0.83505
329.86301, 44.07167,-3.4331e-002,  61.41224,50.00000,0.0000e+000,20.00000,    -0.34766,0.83336
331.67899, 44.25667,-3.7402e-002,  61.34840,50.00000,0.0000e+000,20.00000,    -0.33668,0.83166
333.50101, 44.44167,-4.0951e-002,  61.29255,50.00000,0.0000e+000,20.00000,    -0.32225,0.82996
335.32700, 44.62667,-4.3583e-002,  61.23404,50.00000,0.0000e+000,20.00000,    -0.31575,0.82825
337.14999, 44.81167,-4.5883e-002,  61.18085,50.00000,0.0000e+000,20.00000,    -0.31057,0.82653
338.96899, 44.99667,-4.7627e-002,  61.11436,50.00000,0.0000e+000,20.00000,    -0.30565,0.82481
340.79901, 45.18167,-4.9453e-002,  61.06383,50.00000,0.0000e+000,20.00000,    -0.30057,0.82308
342.62799, 45.36666,-5.1064e-002,  61.01064,50.00000,0.0000e+000,20.00000,    -0.29856,0.82134
344.45300, 45.55167,-5.2782e-002,  60.95745,50.00000,0.0000e+000,20.00000,    -0.29498,0.81960
346.26999, 45.73667,-5.4904e-002,  60.89894,50.00000,0.0000e+000,20.00000,    -0.29220,0.81787
348.09399, 45.92167,-5.6936e-002,  60.84574,50.00000,0.0000e+000,20.00000,    -0.28659,0.81612
349.93100, 46.10667,-5.8878e-002,  60.79787,50.00000,0.0000e+000,20.00000,    -0.28715,0.81436
351.75699, 46.29167,-6.0828e-002,  60.74202,50.00000,0.0000e+000,20.00000,    -0.28374,0.81260
353.59399, 46.47667,-6.3163e-002,  60.68617,50.00000,0.0000e+000,20.00000,    -0.27591,0.81083
355.42599, 46.66167,-6.5509e-002,  60.63830,50.00000,0.0000e+000,20.00000,    -0.27084,0.80905
357.25400, 46.84667,-6.8543e-002,  60.58511,50.00000,0.0000e+000,20.00000,    -0.26976,0.80728
359.08401, 47.03167,-7.1087e-002,  60.53723,50.00000,0.0000e+000,20.00000,    -0.26711,0.80550
360.90900, 47.21667,-7.3997e-002,  60.48936,50.00000,0.0000e+000,20.00000,    -0.26378,0.80372
362.74799, 47.40167,-7.6389e-002,  60.44149,50.00000,0.0000e+000,20.00000,    -0.26041,0.80193
364.57800, 47.58667,-7.9020e-002,  60.39628,50.00000,0.0000e+000,20.00000,    -0.25809,0.80014
366.41101, 47.77167,-8.1561e-002,  60.34840,50.00000,0.0000e+000,20.00000,    -0.25533,0.79834
368.24899, 47.95667,-8.4039e-002,  60.30319,50.00000,0.0000e+000,20.00000,    -0.25667,0.79654
370.06900, 48.14167,-8.6602e-002,  60.25532,50.00000,0.0000e+000,20.00000,    -0.25674,0.79475
371.90601, 48.32667,-9.0306e-002,  60.20745,50.00000,0.0000e+000,20.00000,    -0.25895,0.79293
373.74301, 48.51167,-9.3642e-002,  60.15957,50.00000,0.0000e+000,20.00000,    -0.25997,0.79112
375.56500, 48.69667,-9.7172e-002,  60.11170,50.00000,0.0000e+000,20.00000,    -0.26237,0.78932
377.41599, 48.88167,    -0.10003,  60.06117,50.00000,0.0000e+000,20.00000,    -0.26200,0.78749
379.23901, 49.06667,    -0.10222,  60.01330,50.00000,0.0000e+000,20.00000,    -0.26235,0.78568
381.06799, 49.25167,    -0.10463,  59.96542,50.00000,0.0000e+000,20.00000,    -0.26469,0.78386
382.89200, 49.43667,    -0.10664,  59.91489,50.00000,0.0000e+000,20.00000,    -0.27040,0.78204
384.71301, 49.62167,    -0.10733,  59.86170,50.00000,0.0000e+000,20.00000,    -0.27582,0.78023
386.53500, 49.80667,    -0.10588,  59.81915,50.00000,0.0000e+000,20.00000,    -0.27603,0.77841
388.34900, 49.99166,    -0.10386,  59.76596,50.00000,0.0000e+000,20.00000,    -0.28166,0.77660
390.18100, 50.17667,    -0.10151,  59.71543,50.00000,0.0000e+000,20.00000,    -0.29396,0.77477
392.00900, 50.36167,-9.9494e-002,  59.65426,50.00000,0.0000e+000,20.00000,    -0.30156,0.77294
393.84698, 50.54667,-9.6837e-002,  59.60106,50.00000,0.0000e+000,20.00000,    -0.31228,0.77110
395.67099, 50.73167,-9.4086e-002,  59.55319,50.00000,0.0000e+000,20.00000,    -0.32494,0.76927
397.50299, 50.91667,-9.1086e-002,  59.48936,50.00000,0.0000e+000,20.00000,    -0.33802,0.76743
399.35001, 51.10167,-8.8895e-002,  59.41755,50.00000,0.0000e+000,20.00000,    -0.34888,0.76558
401.18500, 51.28667,-8.7356e-002,  59.35638,50.00000,0.0000e+000,20.00000,    -0.35783,0.76373
403.02899, 51.47167,-8.5491e-002,  59.28989,50.00000,0.0000e+000,20.00000,    -0.36847,0.76188
404.86600, 51.65667,-8.2709e-002,  59.21808,50.00000,0.0000e+000,20.00000,    -0.38536,0.76003
406.69601, 51.84167,-7.6621e-002,  59.14362,50.00000,0.0000e+000,20.00000,    -0.38680,0.75819
408.53201, 52.02667,-6.9538e-002,  59.06915,50.00000,0.0000e+000,20.00000,    -0.38796,0.75634
410.38400, 52.21167,-6.0324e-002,  58.99202,50.00000,0.0000e+000,20.00000,    -0.39040,0.75447
412.21201, 52.39667,-5.1817e-002,  58.92021,50.00000,0.0000e+000,20.00000,    -0.39077,0.75263
414.05701, 52.58167,-4.3513e-002,  58.84309,50.00000,0.0000e+000,20.00000,    -0.38611,0.75077
415.89099, 52.76667,-3.6577e-002,  58.77659,50.00000,0.0000e+000,20.00000,    -0.37641,0.74892
417.72900, 52.95167,-2.8981e-002,  58.70479,50.00000,0.0000e+000,20.00000,    -0.36689,0.74706
419.56100, 53.13667,-2.3226e-002,  58.63564,50.00000,0.0000e+000,20.00000,    -0.35753,0.74521
421.40500, 53.32167,-1.9353e-002,  58.56649,50.00000,0.0000e+000,20.00000,    -0.34393,0.74335
423.24200, 53.50667,-1.6282e-002,  58.51064,50.00000,0.0000e+000,20.00000,    -0.33019,0.74150
425.07700, 53.69167,-1.4293e-002,  58.44681,50.00000,0.0000e+000,20.00000,    -0.31741,0.73965
426.92499, 53.87667,-1.4961e-002,  58.38830,50.00000,0.0000e+000,20.00000,    -0.30357,0.73778
428.75500, 54.06167,-1.7232e-002,  58.33511,50.00000,0.0000e+000,20.00000,    -0.28961,0.73594
430.59900, 54.24667,-2.0178e-002,  58.28458,50.00000,0.0000e+000,20.00000,    -0.27634,0.73408
432.42599, 54.43167,-2.3277e-002,  58.23404,50.00000,0.0000e+000,20.00000,    -0.26551,0.73224
434.26999, 54.61666,-2.6448e-002,  58.18351,50.00000,0.0000e+000,20.00000,    -0.25437,0.73038
436.10101, 54.80167,-2.9467e-002,  58.13830,50.00000,0.0000e+000,20.00000,    -0.24549,0.72853
437.94601, 54.98667,-3.3145e-002,  58.09840,50.00000,0.0000e+000,20.00000,    -0.23988,0.72668
439.78799, 55.17167,-3.6169e-002,  58.05585,50.00000,0.0000e+000,20.00000,    -0.23214,0.72482
441.63501, 55.35667,-3.9040e-002,  58.01596,50.00000,0.0000e+000,20.00000,    -0.22393,0.72297
443.48300, 55.54167,-4.1814e-002,  57.97872,50.00000,0.0000e+000,20.00000,    -0.22068,0.72111
445.32001, 55.72667,-4.3924e-002,  57.93085,50.00000,0.0000e+000,20.00000,    -0.21685,0.71926
447.16199, 55.91167,-4.4320e-002,  57.89362,50.00000,0.0000e+000,20.00000,    -0.21517,0.71741
448.99799, 56.09667,-4.5030e-002,  57.85106,50.00000,0.0000e+000,20.00000,    -0.21221,0.71557
450.82300, 56.28167,-4.6026e-002,  57.81915,50.00000,0.0000e+000,20.00000,    -0.21023,0.71375
452.66199, 56.46667,-4.7171e-002,  57.77926,50.00000,0.0000e+000,20.00000,    -0.20702,0.71191
454.50900, 56.65167,-4.7923e-002,  57.73670,50.00000,0.0000e+000,20.00000,    -0.20366,0.71006
456.33801, 56.83667,-4.9250e-002,  57.70213,50.00000,0.0000e+000,20.00000,    -0.20043,0.70823
458.17200, 57.02167,-5.0296e-002,  57.66489,50.00000,0.0000e+000,20.00000,    -0.19773,0.70640
460.01401, 57.20667,-5.0946e-002,  57.62766,50.00000,0.0000e+000,20.00000,    -0.19776,0.70457
461.85001, 57.39167,-5.1194e-002,  57.59042,50.00000,0.0000e+000,20.00000,    -0.19181,0.70274
463.69800, 57.57667,-5.1299e-002,  57.55585,50.00000,0.0000e+000,20.00000,    -0.18664,0.70091
465.52600, 57.76167,-5.1548e-002,  57.52394,50.00000,0.0000e+000,20.00000,    -0.18353,0.69909
467.37799, 57.94667,-5.1771e-002,  57.48670,50.00000,0.0000e+000,20.00000,    -0.18089,0.69726
469.21500, 58.13167,-5.2140e-002,  57.45213,50.00000,0.0000e+000,20.00000,    -0.17734,0.69544
471.05899, 58.31667,-5.2979e-002,  57.42553,50.00000,0.0000e+000,20.00000,    -0.17317,0.69362
472.89600, 58.50167,-5.4408e-002,  57.39362,50.00000,0.0000e+000,20.00000,    -0.17103,0.69181
474.74200, 58.68667,-5.5904e-002,  57.36170,50.00000,0.0000e+000,20.00000,    -0.16712,0.68999
476.58899, 58.87167,-5.7408e-002,  57.33245,50.00000,0.0000e+000,20.00000,    -0.16202,0.68817
478.42401, 59.05667,-5.8120e-002,  57.30053,50.00000,0.0000e+000,20.00000,    -0.16205,0.68637
480.26501, 59.24166,-5.7977e-002,  57.26862,50.00000,0.0000e+000,20.00000,    -0.15874,0.68457
482.10999, 59.42667,-5.8160e-002,  57.23936,50.00000,0.0000e+000,20.00000,    -0.15503,0.68277
483.94299, 59.61167,-5.8729e-002,  57.21011,50.00000,0.0000e+000,20.00000,    -0.15190,0.68098
485.78299, 59.79667,-5.8108e-002,  57.18351,50.00000,0.0000e+000,20.00000,    -0.14977,0.67919
487.62601, 59.98167,-5.7482e-002,  57.15691,50.00000,0.0000e+000,20.00000,    -0.14512,0.67740
489.45999, 60.16667,-5.6372e-002,  57.13032,50.00000,0.0000e+000,20.00000,    -0.14207,0.67562
491.30499, 60.35167,-5.5046e-002,  57.10372,50.00000,0.0000e+000,20.00000,    -0.14104,0.67383
493.13800, 60.53667,-5.2655e-002,  57.08245,50.00000,0.0000e+000,20.00000,    -0.13865,0.67206
494.96600, 60.72167,-5.0886e-002,  57.05585,50.00000,0.0000e+000,20.00000,    -0.13674,0.67030
496.80399, 60.90667,-4.8501e-002,  57.02925,50.00000,0.0000e+000,20.00000,    -0.13449,0.66854
498.65201, 61.09167,-4.4370e-002,  57.00532,50.00000,0.0000e+000,20.00000,    -0.13112,0.66677
500.49701, 61.27667,-4.0673e-002,  56.97606,50.00000,0.0000e+000,20.00000,    -0.12784,0.66500
502.34000, 61.46167,-3.8701e-002,  56.95479,50.00000,0.0000e+000,20.00000,    -0.12787,0.66325
504.17001, 61.64667,-3.7177e-002,  56.93351,50.00000,0.0000e+000,20.00000,    -0.12402,0.66151
506.01999, 61.83167,-3.5922e-002,  56.90957,50.00000,0.0000e+000,20.00000,    -0.11999,0.65975
507.86099, 62.01667,-3.5401e-002,  56.89096,50.00000,0.0000e+000,20.00000,    -0.11845,0.65801
509.69699, 62.20167,-3.4845e-002,  56.86702,50.00000,0.0000e+000,20.00000,    -0.11485,0.65628
511.54199, 62.38667,-3.4131e-002,  56.84840,50.00000,0.0000e+000,20.00000,    -0.11264,0.65454
513.37598, 62.57167,-3.3351e-002,  56.82447,50.00000,0.0000e+000,20.00000,    -0.11163,0.65282
515.23102, 62.75667,-3.3066e-002,  56.80585,50.00000,0.0000e+000,20.00000,    -0.10927,0.65109
517.05499, 62.94167,-3.2809e-002,  56.78723,50.00000,0.0000e+000,20.00000,    -0.10968,0.64939
518.89899, 63.12667,-3.4368e-002,  56.76596,50.00000,0.0000e+000,20.00000,    -0.10903,0.64768
520.73700, 63.31167,-3.6186e-002,  56.74734,50.00000,0.0000e+000,20.00000,    -0.10607,0.64597
522.57397, 63.49667,-3.7510e-002,  56.72340,50.00000,0.0000e+000,20.00000,    -0.10430,0.64428
524.40900, 63.68167,-3.9029e-002,  56.70745,50.00000,0.0000e+000,20.00000,    -0.10573,0.64259
526.26501, 63.86666,-4.0653e-002,  56.68617,50.00000,0.0000e+000,20.00000,    -0.10616,0.64089
528.10999, 64.05167,-4.1776e-002,  56.66755,50.00000,0.0000e+000,20.00000,    -0.10839,0.63920
529.94800, 64.23666,-4.2745e-002,  56.64894,50.00000,0.0000e+000,20.00000,    -0.11100,0.63752
531.77600, 64.42167,-4.4196e-002,  56.63032,50.00000,0.0000e+000,20.00000,    -0.11026,0.63586
533.62299, 64.60667,-4.6744e-002,  56.60904,50.00000,0.0000e+000,20.00000,    -0.11468,0.63419
535.47302, 64.79166,-4.9113e-002,  56.58511,50.00000,0.0000e+000,20.00000,    -0.11846,0.63253
537.30902, 64.97667,-5.2426e-002,  56.56649,50.00000,0.0000e+000,20.00000,    -0.12605,0.63088
539.15997, 65.16167,-5.5401e-002,  56.53989,50.00000,0.0000e+000,20.00000,    -0.13236,0.62922
541.00098, 65.34666,-5.9620e-002,  56.52128,50.00000,0.0000e+000,20.00000,    -0.13636,0.62758
542.86102, 65.53167,-6.5742e-002,  56.49202,50.00000,0.0000e+000,20.00000,    -0.14603,0.62593
544.69897, 65.71667,-7.0138e-002,  56.46543,50.00000,0.0000e+000,20.00000,    -0.15147,0.62431
546.55701, 65.90166,-7.6449e-002,  56.43085,50.00000,0.0000e+000,20.00000,    -0.15834,0.62267
548.40100, 66.08667,-7.9915e-002,  56.40160,50.00000,0.0000e+000,20.00000,    -0.16537,0.62105
550.24701, 66.27167,-8.3726e-002,  56.37766,50.00000,0.0000e+000,20.00000,    -0.17386,0.61944
552.08801, 66.45667,-8.8016e-002,  56.34043,50.00000,0.0000e+000,20.00000,    -0.18160,0.61784
553.94202, 66.64167,-9.2822e-002,  56.30585,50.00000,0.0000e+000,20.00000,    -0.19166,0.61624
555.77399, 66.82667,-9.7418e-002,  56.27394,50.00000,0.0000e+000,20.00000,    -0.19674,0.61466
557.61700, 67.01167,    -0.10098,  56.23670,50.00000,0.0000e+000,20.00000,    -0.20939,0.61307
559.44501, 67.19666,    -0.10568,  56.19415,50.00000,0.0000e+000,20.00000,    -0.22198,0.61151
561.27698, 67.38167,    -0.11197,  56.15692,50.00000,0.0000e+000,20.00000,    -0.23256,0.60995
563.11603, 67.56667,    -0.11906,  56.10904,50.00000,0.0000e+000,20.00000,    -0.24724,0.60840
564.99500, 67.75166,    -0.12710,  56.06915,50.00000,0.0000e+000,20.00000,    -0.26135,0.60681
566.87097, 67.93667,    -0.13528,  56.01862,50.00000,0.0000e+000,20.00000,    -0.27572,0.60524
568.75098, 68.12167,    -0.13892,  55.96543,50.00000,0.0000e+000,20.00000,    -0.29315,0.60367
570.58899, 68.30666,    -0.13799,  55.90692,50.00000,0.0000e+000,20.00000,    -0.31230,0.60215
572.42200, 68.49167,    -0.13952,  55.85107,50.00000,0.0000e+000,20.00000,    -0.32557,0.60063
574.26898, 68.67667,    -0.14333,  55.78989,50.00000,0.0000e+000,20.00000,    -0.34306,0.59911
576.10498, 68.86166,    -0.14919,  55.72606,50.00000,0.0000e+000,20.00000,    -0.36254,0.59761
577.94397, 69.04667,    -0.15763,  55.65425,50.00000,0.0000e+000,20.00000,    -0.37955,0.59611
579.76599, 69.23167,    -0.16584,  55.57713,50.00000,0.0000e+000,20.00000,    -0.39618,0.59464
581.62500, 69.41666,    -0.17430,  55.50798,50.00000,0.0000e+000,20.00000,    -0.41069,0.59314
583.45502, 69.60167,    -0.18255,  55.43085,50.00000,0.0000e+000,20.00000,    -0.42779,0.59168
585.28900, 69.78667,    -0.19142,  55.34574,50.00000,0.0000e+000,20.00000,    -0.44372,0.59021
587.12598, 69.97166,    -0.20186,  55.26330,50.00000,0.0000e+000,20.00000,    -0.45635,0.58876
588.98700, 70.15667,    -0.21217,  55.17553,50.00000,0.0000e+000,20.00000,    -0.47199,0.58729
590.84399, 70.34167,    -0.22073,  55.09043,50.00000,0.0000e+000,20.00000,    -0.49122,0.58584
592.69702, 70.52666,    -0.23253,  54.99734,50.00000,0.0000e+000,20.00000,    -0.50465,0.58439
594.54303, 70.71167,    -0.24243,  54.90160,50.00000,0.0000e+000,20.00000,    -0.51931,0.58297
596.39697, 70.89667,    -0.25161,  54.80851,50.00000,0.0000e+000,20.00000,    -0.53264,0.58154
598.24597, 71.08167,    -0.26009,  54.71011,50.00000,0.0000e+000,20.00000,    -0.54995,0.58012
600.07599, 71.26667,    -0.27092,  54.60107,50.00000,0.0000e+000,20.00000,    -0.56785,0.57873
601.93298, 71.45167,    -0.28367,  54.49734,50.00000,0.0000e+000,20.00000,    -0.58486,0.57733
603.77899, 71.63667,    -0.29485,  54.38564,50.00000,0.0000e+000,20.00000,    -0.60102,0.57594
605.61700, 71.82166,    -0.30615,  54.27926,50.00000,0.0000e+000,20.00000,    -0.62271,0.57457
607.47498, 72.00667,    -0.31733,  54.15957,50.00000,0.0000e+000,20.00000,    -0.63573,0.57319
609.32001, 72.19167,    -0.32986,  54.04255,50.00000,0.0000e+000,20.00000,    -0.64991,0.57183
611.16302, 72.37666,    -0.35156,  53.91755,50.00000,0.0000e+000,20.00000,    -0.67802,0.57048
612.99701, 72.56167,    -0.37755,  53.76330,50.00000,0.0000e+000,20.00000,    -0.68949,0.56915
614.84497, 72.74667,    -0.40710,  53.65957,50.00000,0.0000e+000,20.00000,    -0.71510,0.56781
616.67297, 72.93166,    -0.44056,  53.52925,50.00000,0.0000e+000,20.00000,    -0.73215,0.56650
618.50702, 73.11667,    -0.47741,  53.39361,50.00000,0.0000e+000,20.00000,    -0.75507,0.56519
620.34003, 73.30167,    -0.51273,  53.23936,50.00000,0.0000e+000,20.00000,    -0.77753,0.56389
622.21698, 73.48666,    -0.54304,  53.10372,50.00000,0.0000e+000,20.00000,    -0.78793,0.56257
624.08600, 73.67167,    -0.56209,  52.96277,50.00000,0.0000e+000,20.00000,    -0.81212,0.56127
625.93500, 73.85667,    -0.57026,  52.79521,50.00000,0.0000e+000,20.00000,    -0.82855,0.55999
627.79700, 74.04166,    -0.56979,  52.64362,50.00000,0.0000e+000,20.00000,    -0.82038,0.55870
629.67102, 74.22667,    -0.55643,  52.48404,50.00000,0.0000e+000,20.00000,    -0.83393,0.55742
631.51501, 74.41167,    -0.53247,  52.31383,50.00000,0.0000e+000,20.00000,    -0.82469,0.55617
633.37799, 74.59666,    -0.50073,  52.15958,50.00000,0.0000e+000,20.00000,    -0.84084,0.55492
635.24597, 74.78167,    -0.46535,  52.00532,50.00000,0.0000e+000,20.00000,    -0.81194,0.55367
637.13098, 74.96667,    -0.42549,  51.86702,50.00000,0.0000e+000,20.00000,    -0.79986,0.55243
638.98999, 75.15166,    -0.39256,  51.69947,50.00000,0.0000e+000,20.00000,    -0.77910,0.55120
640.85199, 75.33667,    -0.37369,  51.57713,50.00000,0.0000e+000,20.00000,    -0.75733,0.54999
642.70697, 75.52167,    -0.35854,  51.42553,50.00000,0.0000e+000,20.00000,    -0.73634,0.54879
644.56799, 75.70667,    -0.34502,  51.28989,50.00000,0.0000e+000,20.00000,    -0.71988,0.54760
646.42499, 75.89167,    -0.34045,  51.16755,50.00000,0.0000e+000,20.00000,    -0.70458,0.54641
648.28601, 76.07667,    -0.34360,  51.04521,50.00000,0.0000e+000,20.00000,    -0.67119,0.54524
650.15997, 76.26167,    -0.34490,  50.91224,50.00000,0.0000e+000,20.00000,    -0.65494,0.54407
652.04999, 76.44666,    -0.34057,  50.79787,50.00000,0.0000e+000,20.00000,    -0.62416,0.54290
653.88800, 76.63167,    -0.33423,  50.67819,50.00000,0.0000e+000,20.00000,    -0.59414,0.54176
655.73602, 76.81667,    -0.32746,  50.56649,50.00000,0.0000e+000,20.00000,    -0.56589,0.54064
657.57202, 77.00166,    -0.32148,  50.46011,50.00000,0.0000e+000,20.00000,    -0.53509,0.53953
659.42297, 77.18667,    -0.31197,  50.37234,50.00000,0.0000e+000,20.00000,    -0.49664,0.53842
661.27802, 77.37167,    -0.30192,  50.27926,50.00000,0.0000e+000,20.00000,    -0.46598,0.53732
663.13501, 77.55666,    -0.29175,  50.19681,50.00000,0.0000e+000,20.00000,    -0.42945,0.53623
664.98499, 77.74167,    -0.27766,  50.12500,50.00000,0.0000e+000,20.00000,    -0.39497,0.53515
666.84601, 77.92667,    -0.26181,  50.05851,50.00000,0.0000e+000,20.00000,    -0.36307,0.53407
668.69598, 78.11166,    -0.24451,  49.99468,50.00000,0.0000e+000,20.00000,    -0.33528,0.53302
670.54303, 78.29667,    -0.23008,  49.93351,50.00000,0.0000e+000,20.00000,    -0.30364,0.53197
672.37500, 78.48167,    -0.21883,  49.88032,50.00000,0.0000e+000,20.00000,    -0.27757,0.53094
674.21503, 78.66666,    -0.21634,  49.83244,50.00000,0.0000e+000,20.00000,    -0.25388,0.52992
676.06500, 78.85167,    -0.21868,  49.78457,50.00000,0.0000e+000,20.00000,    -0.23353,0.52890
677.88098, 79.03667,    -0.22220,  49.74734,50.00000,0.0000e+000,20.00000,    -0.21149,0.52791
679.72803, 79.22166,    -0.23182,  49.71543,50.00000,0.0000e+000,20.00000,    -0.19166,0.52692
681.55798, 79.40667,    -0.24491,  49.68351,50.00000,0.0000e+000,20.00000,    -0.17665,0.52594
683.43500, 79.59167,    -0.25581,  49.65691,50.00000,0.0000e+000,20.00000,    -0.16290,0.52495
685.32397, 79.77666,    -0.26008,  49.62500,50.00000,0.0000e+000,20.00000,    -0.15191,0.52396
687.20898, 79.96167,    -0.25983,  49.60372,50.00000,0.0000e+000,20.00000,    -0.14611,0.52299
689.09802, 80.14667,    -0.25837,  49.57979,50.00000,0.0000e+000,20.00000,    -0.13773,0.52202
691.00598, 80.33167,    -0.25394,  49.55053,50.00000,0.0000e+000,20.00000,    -0.13484,0.52105
693.06500, 80.53667,    -0.24773,  49.52393,50.00000,0.0000e+000,20.00000,    -0.13585,0.52003
694.88702, 80.72166,    -0.24453,  49.50266,50.00000,0.0000e+000,20.00000,    -0.13648,0.51913
696.71002, 80.90667,    -0.24475,  49.47873,50.00000,0.0000e+000,20.00000,    -0.13740,0.51824
698.56299, 81.09167,    -0.24180,  49.45745,50.00000,0.0000e+000,20.00000,    -0.13943,0.51734
700.39301, 81.27666,    -0.23251,  49.42819,50.00000,0.0000e+000,20.00000,     0.60077,0.51647
702.22601, 81.46167,    -0.22093,  49.40160,50.00000,0.0000e+000,20.00000,    -0.14645,0.51560
704.06403, 81.64667,    -0.21326,  49.37234,50.00000,0.0000e+000,20.00000,    -0.15365,0.51475
705.90802, 81.83167,    -0.20702,  49.34575,50.00000,0.0000e+000,20.00000,    -0.16207,0.51390
707.78400, 82.01667,    -0.20499,  49.31383,50.00000,0.0000e+000,20.00000,    -0.16927,0.51304
709.64600, 82.20167,    -0.18892,  49.28724,50.00000,0.0000e+000,20.00000,    -0.17433,0.51221
711.49799, 82.38667,    -0.17895,  49.25266,50.00000,0.0000e+000,20.00000,    -0.17700,0.51139
713.34198, 82.57166,    -0.17208,  49.21543,50.00000,0.0000e+000,20.00000,    -0.18032,0.51058
715.19397, 82.75667,    -0.16737,  49.17553,50.00000,0.0000e+000,20.00000,    -0.18198,0.50978
717.02502, 82.94167,    -0.16500,  49.14096,50.00000,0.0000e+000,20.00000,    -0.18151,0.50900
718.84998, 83.12666,    -0.16888,  49.10904,50.00000,0.0000e+000,20.00000,    -0.18332,0.50823
720.69598, 83.31167,    -0.17402,  49.07181,50.00000,0.0000e+000,20.00000,    -0.17832,0.50746
722.55200, 83.49667,    -0.18044,  49.04255,50.00000,0.0000e+000,20.00000,    -0.17228,0.50670
724.42499, 83.68166,    -0.18625,  49.01330,50.00000,0.0000e+000,20.00000,    -0.16647,0.50594
726.27698, 83.86667,    -0.18716,  48.98139,50.00000,0.0000e+000,20.00000,    -0.16054,0.50520
728.12097, 84.05167,    -0.19326,  48.95213,50.00000,0.0000e+000,20.00000,    -0.15400,0.50448
729.97101, 84.23666,    -0.20196,  48.92287,50.00000,0.0000e+000,20.00000,    -0.14947,0.50376
731.82001, 84.42167,    -0.20813,  48.89627,50.00000,0.0000e+000,20.00000,    -0.14664,0.50306
733.69397, 84.60667,    -0.21670,  48.86968,50.00000,0.0000e+000,20.00000,    -0.14330,0.50235
735.54498, 84.79166,    -0.21999,  48.84840,50.00000,0.0000e+000,20.00000,    -0.13910,0.50167
737.41101, 84.97667,    -0.22730,  48.82181,50.00000,0.0000e+000,20.00000,    -0.13556,0.50099
739.28198, 85.16167,    -0.23215,  48.79521,50.00000,0.0000e+000,20.00000,    -0.12890,0.50031
741.14600, 85.34666,    -0.23972,  48.77128,50.00000,0.0000e+000,20.00000,    -0.12669,0.49965
743.00098, 85.53167,    -0.24605,  48.74468,50.00000,0.0000e+000,20.00000,    -0.11943,0.49901
744.83600, 85.71667,    -0.24917,  48.72606,50.00000,0.0000e+000,20.00000,    -0.11604,0.49838
746.71100, 85.90166,    -0.25833,  48.70213,50.00000,0.0000e+000,20.00000,    -0.11228,0.49775
748.60602, 86.08667,    -0.26245,  48.68351,50.00000,0.0000e+000,20.00000,    -0.10991,0.49712
750.46698, 86.27167,    -0.25832,  48.67021,50.00000,0.0000e+000,20.00000,    -0.10306,0.49652
752.32202, 86.45667,    -0.26112,  48.64893,50.00000,0.0000e+000,20.00000,-9.7204e-002,0.49592
754.16302, 86.64167,    -0.26499,  48.63032,50.00000,0.0000e+000,20.00000,-9.2545e-002,0.49535
756.00800, 86.82667,    -0.27161,  48.61170,50.00000,0.0000e+000,20.00000,-8.9614e-002,0.49478
757.84198, 87.01167,    -0.27339,  48.59575,50.00000,0.0000e+000,20.00000,-8.4510e-002,0.49422
759.60797, 87.19666,    -0.27825,  48.57713,50.00000,0.0000e+000,20.00000,-8.1592e-002,0.49370
761.56299, 87.38167,    -0.29836,  48.56649,50.00000,0.0000e+000,20.00000,-7.8811e-002,0.49313
763.52698, 87.56667,    -0.29347,  48.55319,50.00000,0.0000e+000,20.00000,-7.4347e-002,0.49256
765.45001, 87.75166,    -0.28257,  48.53457,50.00000,0.0000e+000,20.00000,-7.4102e-002,0.49202
767.30200, 87.93667,    -0.27989,  48.52660,50.00000,0.0000e+000,20.00000,-7.1642e-002,0.49152
769.15698, 88.12167,    -0.29336,  48.51596,50.00000,0.0000e+000,20.00000,-6.9763e-002,0.49102
770.98999, 88.30666,    -0.30602,  48.50532,50.00000,0.0000e+000,20.00000,-6.9373e-002,0.49053
772.83600, 88.49167,    -0.31265,  48.49202,50.00000,0.0000e+000,20.00000,-6.8439e-002,0.49006
774.67700, 88.67667,    -0.32227,  48.47606,50.00000,0.0000e+000,20.00000,-6.8198e-002,0.48959
776.50598, 88.86166,    -0.32714,  48.46011,50.00000,0.0000e+000,20.00000,-7.0236e-002,0.48914
778.31500, 89.04667,    -0.33112,  48.44947,50.00000,0.0000e+000,20.00000,-6.9245e-002,0.48870
780.14398, 89.23167,    -0.33769,  48.43617,50.00000,0.0000e+000,20.00000,-6.7622e-002,0.48827
781.95801, 89.41666,    -0.33973,  48.42553,50.00000,0.0000e+000,20.00000,-6.6927e-002,0.48785
783.78003, 89.60167,    -0.34422,  48.40958,50.00000,0.0000e+000,20.00000,-6.3650e-002,0.48744
785.63000, 89.78667,    -0.34872,  48.40159,50.00000,0.0000e+000,20.00000,-6.4574e-002,0.48703
787.49103, 89.97166,    -0.35021,  48.39096,50.00000,0.0000e+000,20.00000,-6.3094e-002,0.48663
789.34100, 90.15667,    -0.34899,  48.38298,50.00000,0.0000e+000,20.00000,-6.4124e-002,0.48624
791.18298, 90.34167,    -0.35010,  48.36436,50.00000,0.0000e+000,20.00000,-6.2219e-002,0.48586
793.05298, 90.52666,    -0.35459,  48.35372,50.00000,0.0000e+000,20.00000,-5.9287e-002,0.48549
794.89899, 90.71167,    -0.35326,  48.34309,50.00000,0.0000e+000,20.00000,-6.1071e-002,0.48513
796.75000, 90.89667,    -0.35385,  48.32979,50.00000,0.0000e+000,20.00000,-6.1663e-002,0.48478
798.58899, 91.08167,    -0.35338,  48.31915,50.00000,0.0000e+000,20.00000,-6.2980e-002,0.48444
800.41302, 91.26667,    -0.35500,  48.30585,50.00000,0.0000e+000,20.00000,-6.3650e-002,0.48412
802.26099, 91.45167,    -0.36023,  48.29521,50.00000,0.0000e+000,20.00000,-6.5870e-002,0.48380
804.10901, 91.63667,    -0.36587,  48.28457,50.00000,0.0000e+000,20.00000,-6.6250e-002,0.48349
805.97601, 91.82166,    -0.36577,  48.27394,50.00000,0.0000e+000,20.00000,-6.8766e-002,0.48319
807.83002, 92.00667,    -0.36889,  48.26330,50.00000,0.0000e+000,20.00000,-6.6631e-002,0.48290
809.68701, 92.19167,    -0.37272,  48.25000,50.00000,0.0000e+000,20.00000,-6.7478e-002,0.48262
811.54999, 92.37666,    -0.37507,  48.23138,50.00000,0.0000e+000,20.00000,-6.7251e-002,0.48234
813.41101, 92.56167,    -0.37591,  48.21808,50.00000,0.0000e+000,20.00000,-6.9004e-002,0.48208
815.23401, 92.74667,    -0.37429,  48.20745,50.00000,0.0000e+000,20.00000,-6.9890e-002,0.48183
817.06299, 92.93166,    -0.37423,  48.19681,50.00000,0.0000e+000,20.00000,-7.0786e-002,0.48159
818.90198, 93.11667,    -0.37883,  48.18617,50.00000,0.0000e+000,20.00000,-7.1978e-002,0.48136
820.77399, 93.30167,    -0.38395,  48.17553,50.00000,0.0000e+000,20.00000,-7.0305e-002,0.48113
822.64398, 93.48666,    -0.38623,  48.15958,50.00000,0.0000e+000,20.00000,-6.9514e-002,0.48091
824.53699, 93.67167,    -0.38285,  48.14628,50.00000,0.0000e+000,20.00000,-7.1047e-002,0.48070
826.38202, 93.85667,    -0.37976,  48.13032,50.00000,0.0000e+000,20.00000,-7.5489e-002,0.48051
828.23700, 94.04166,    -0.38383,  48.11436,50.00000,0.0000e+000,20.00000,-7.8937e-002,0.48032
830.08502, 94.22667,    -0.38600,  48.10107,50.00000,0.0000e+000,20.00000,-8.0219e-002,0.48014
831.93500, 94.41167,    -0.38842,  48.08776,50.00000,0.0000e+000,20.00000,-8.5542e-002,0.47998
833.79602, 94.59666,    -0.39198,  48.07181,50.00000,0.0000e+000,20.00000,-8.7844e-002,0.47982
835.66302, 94.78167,    -0.39578,  48.05585,50.00000,0.0000e+000,20.00000,-9.2981e-002,0.47967
837.53802, 94.96667,    -0.39145,  48.04521,50.00000,0.0000e+000,20.00000,-8.9415e-002,0.47952
839.41101, 95.15166,    -0.38991,  48.02394,50.00000,0.0000e+000,20.00000,-9.5477e-002,0.47939
841.26501, 95.33667,    -0.39433,  48.00000,50.00000,0.0000e+000,20.00000,    -0.10078,0.47927
843.12299, 95.52167,    -0.39811,  47.98404,50.00000,0.0000e+000,20.00000,    -0.10079,0.47915
844.96899, 95.70667,    -0.39921,  47.96011,50.00000,0.0000e+000,20.00000,    -0.10071,0.47905
846.82599, 95.89167,    -0.39874,  47.94415,50.00000,0.0000e+000,20.00000,    -0.10697,0.47895
848.68402, 96.07667,    -0.40161,  47.92553,50.00000,0.0000e+000,20.00000,    -0.10729,0.47886
850.53497, 96.26167,    -0.40236,  47.90425,50.00000,0.0000e+000,20.00000,    -0.10884,0.47879
852.39697, 96.44666,    -0.39898,  47.88298,50.00000,0.0000e+000,20.00000,    -0.11034,0.47872
854.25000, 96.63167,    -0.39852,  47.86702,50.00000,0.0000e+000,20.00000,    -0.11337,0.47865
856.10498, 96.81667,    -0.39742,  47.84841,50.00000,0.0000e+000,20.00000,    -0.11759,0.47860
857.96899, 97.00166,    -0.39682,  47.82181,50.00000,0.0000e+000,20.00000,    -0.12489,0.47856
859.80902, 97.18667,    -0.39274,  47.80053,50.00000,0.0000e+000,20.00000,    -0.12598,0.47852
861.65601, 97.37167,    -0.39090,  47.77925,50.00000,0.0000e+000,20.00000,    -0.13489,0.47849
863.50098, 97.55666,    -0.39316,  47.75000,50.00000,0.0000e+000,20.00000,    -0.13931,0.47848
865.34998, 97.74167,    -0.39143,  47.72340,50.00000,0.0000e+000,20.00000,    -0.14520,0.47847
867.19800, 97.92667,    -0.39113,  47.69681,50.00000,0.0000e+000,20.00000,    -0.14948,0.47846
869.04999, 98.11166,    -0.39020,  47.67287,50.00000,0.0000e+000,20.00000,    -0.15459,0.47847
870.90601, 98.29667,    -0.38895,  47.64096,50.00000,0.0000e+000,20.00000,    -0.15919,0.47848
872.76001, 98.48167,    -0.38923,  47.60904,50.00000,0.0000e+000,20.00000,    -0.16063,0.47851
874.62500, 98.66666,    -0.38806,  47.57979,50.00000,0.0000e+000,20.00000,    -0.16702,0.47854
876.47998, 98.85167,    -0.38850,  47.54787,50.00000,0.0000e+000,20.00000,    -0.17403,0.47858
878.30902, 99.03667,    -0.38596,  47.51596,50.00000,0.0000e+000,20.00000,    -0.17825,0.47862
880.19397, 99.22166,    -0.38575,  47.48936,50.00000,0.0000e+000,20.00000,    -0.18211,0.47868
882.04999, 99.40667,    -0.38404,  47.45479,50.00000,0.0000e+000,20.00000,    -0.18494,0.47874
883.88898, 99.59167,    -0.38026,  47.41489,50.00000,0.0000e+000,20.00000,    -0.18842,0.47881
885.74597, 99.77666,    -0.38011,  47.37500,50.00000,0.0000e+000,20.00000,    -0.19298,0.47889
887.59802, 99.96167,    -0.38152,  47.33777,50.00000,0.0000e+000,20.00000,    -0.19779,0.47897
889.44598,100.14667,    -0.37603,  47.30053,50.00000,0.0000e+000,20.00000,    -0.20748,0.47907
891.30402,100.33167,    -0.37083,  47.26861,50.00000,0.0000e+000,20.00000,    -0.20900,0.47917
893.16602,100.51667,    -0.36735,  47.22872,50.00000,0.0000e+000,20.00000,    -0.21354,0.47928
895.02502,100.70167,    -0.36904,  47.18617,50.00000,0.0000e+000,20.00000,    -0.21672,0.47939
896.92902,100.88667,    -0.37017,  47.15160,50.00000,0.0000e+000,20.00000,    -0.21876,0.47952
898.81201,101.07166,    -0.36533,  47.10638,50.00000,0.0000e+000,20.00000,    -0.22510,0.47965
900.65601,101.25667,    -0.35360,  47.06649,50.00000,0.0000e+000,20.00000,    -0.23075,0.47979
902.50702,101.44167,    -0.35882,  47.01596,50.00000,0.0000e+000,20.00000,    -0.23777,0.47994
904.39600,101.62666,    -0.35287,  46.97873,50.00000,0.0000e+000,20.00000,    -0.24365,0.48009
906.25000,101.81167,    -0.34443,  46.93085,50.00000,0.0000e+000,20.00000,    -0.25229,0.48025
908.08398,101.99667,    -0.34448,  46.88830,50.00000,0.0000e+000,20.00000,    -0.25950,0.48042
909.92297,102.18166,    -0.34161,  46.84043,50.00000,0.0000e+000,20.00000,    -0.26401,0.48059
911.73499,102.36667,    -0.34220,  46.78989,50.00000,0.0000e+000,20.00000,    -0.26884,0.48077
913.57397,102.55167,    -0.34304,  46.73936,50.00000,0.0000e+000,20.00000,    -0.27988,0.48095
915.42603,102.73666,    -0.33788,  46.68085,50.00000,0.0000e+000,20.00000,    -0.28386,0.48115
917.26599,102.92167,    -0.32994,  46.62766,50.00000,0.0000e+000,20.00000,    -0.29251,0.48135
919.12000,103.10667,    -0.32559,  46.57713,50.00000,0.0000e+000,20.00000,    -0.30515,0.48156
920.96399,103.29166,    -0.32106,  46.51596,50.00000,0.0000e+000,20.00000,    -0.31621,0.48177
922.87299,103.47667,    -0.31384,  46.46277,50.00000,0.0000e+000,20.00000,    -0.31417,0.48200
924.71100,103.66167,    -0.30233,  46.40692,50.00000,0.0000e+000,20.00000,    -0.32183,0.48222
926.56201,103.84666,    -0.29815,  46.34574,50.00000,0.0000e+000,20.00000,    -0.33213,0.48246
928.39301,104.03167,    -0.29653,  46.27394,50.00000,0.0000e+000,20.00000,    -0.33952,0.48269
930.30603,104.21667,    -0.29225,  46.20745,50.00000,0.0000e+000,20.00000,    -0.34582,0.48295
932.20502,104.40166,    -0.27887,  46.15160,50.00000,0.0000e+000,20.00000,    -0.35575,0.48321
934.04999,104.58667,    -0.27314,  46.08511,50.00000,0.0000e+000,20.00000,    -0.36583,0.48347
935.90802,104.77167,    -0.27421,  46.01330,50.00000,0.0000e+000,20.00000,    -0.37391,0.48373
937.74799,104.95667,    -0.26932,  45.94681,50.00000,0.0000e+000,20.00000,    -0.37377,0.48400
939.59399,105.14167,    -0.26258,  45.87500,50.00000,0.0000e+000,20.00000,    -0.38217,0.48428
941.46301,105.32667,    -0.25791,  45.80053,50.00000,0.0000e+000,20.00000,    -0.39909,0.48456
943.30402,105.51167,    -0.25189,  45.72873,50.00000,0.0000e+000,20.00000,    -0.40502,0.48485
945.16101,105.69666,    -0.24635,  45.64894,50.00000,0.0000e+000,20.00000,    -0.40971,0.48515
947.00800,105.88167,    -0.24101,  45.57713,50.00000,0.0000e+000,20.00000,    -0.42392,0.48545
948.86603,106.06667,    -0.23718,  45.50532,50.00000,0.0000e+000,20.00000,    -0.43091,0.48575
950.70398,106.25166,    -0.23202,  45.41489,50.00000,0.0000e+000,20.00000,    -0.44077,0.48606
952.55298,106.43667,    -0.22782,  45.33777,50.00000,0.0000e+000,20.00000,    -0.45296,0.48638
954.40399,106.62167,    -0.22217,  45.24734,50.00000,0.0000e+000,20.00000,    -0.46154,0.48670
956.26703,106.80666,    -0.22023,  45.15691,50.00000,0.0000e+000,20.00000,    -0.47775,0.48703
958.17999,106.99167,    -0.22265,  45.07447,50.00000,0.0000e+000,20.00000,    -0.48940,0.48738
960.12500,107.17667,    -0.20111,  44.98670,50.00000,0.0000e+000,20.00000,    -0.49269,0.48773
961.95001,107.36166,    -0.19719,  44.89362,50.00000,0.0000e+000,20.00000,    -0.50819,0.48807
963.81097,107.54667,    -0.19609,  44.80053,50.00000,0.0000e+000,20.00000,    -0.51845,0.48842
965.66302,107.73167,    -0.19752,  44.69947,50.00000,0.0000e+000,20.00000,    -0.53037,0.48877
967.48798,107.91666,    -0.19124,  44.59840,50.00000,0.0000e+000,20.00000,    -0.54193,0.48913
969.32501,108.10167,    -0.18791,  44.50266,50.00000,0.0000e+000,20.00000,    -0.56212,0.48949
971.15698,108.28667,    -0.17994,  44.39362,50.00000,0.0000e+000,20.00000,    -0.57432,0.48985
972.97601,108.47166,    -0.17683,  44.28989,50.00000,0.0000e+000,20.00000,    -0.58235,0.49022
974.81897,108.65667,    -0.17520,  44.17553,50.00000,0.0000e+000,20.00000,    -0.59469,0.49059
976.68201,108.84167,    -0.17023,  44.06915,50.00000,0.0000e+000,20.00000,    -0.60609,0.49098
978.57501,109.02666,    -0.16353,  43.94947,50.00000,0.0000e+000,20.00000,    -0.61707,0.49137
980.43597,109.21167,    -0.15452,  43.83245,50.00000,0.0000e+000,20.00000,    -0.62785,0.49177
982.30798,109.39667,    -0.15399,  43.72074,50.00000,0.0000e+000,20.00000,    -0.63909,0.49217
984.13098,109.58167,    -0.15559,  43.59575,50.00000,0.0000e+000,20.00000,    -0.65914,0.49256
985.97699,109.76667,    -0.16176,  43.48138,50.00000,0.0000e+000,20.00000,    -0.66327,0.49296
987.81897,109.95167,    -0.16422,  43.35904,50.00000,0.0000e+000,20.00000,    -0.68115,0.49337
989.67798,110.13667,    -0.16803,  43.23138,50.00000,0.0000e+000,20.00000,    -0.68581,0.49378
991.51898,110.32166,    -0.16703,  43.09309,50.00000,0.0000e+000,20.00000,    -0.69204,0.49420
993.35797,110.50667,    -0.16565,  42.96543,50.00000,0.0000e+000,20.00000,    -0.71215,0.49461
995.23297,110.69167,    -0.16494,  42.84042,50.00000,0.0000e+000,20.00000,    -0.69103,0.49504
997.04700,110.87666,    -0.16271,  42.69149,50.00000,0.0000e+000,20.00000,    -0.71446,0.49546
998.23401,110.99667,    -0.16372,  42.61702,50.00000,0.0000e+000,20.00000,    -0.79965,0.49574