File: Data/ExpDat.csv
#FILE:                       ,CP2_C1_0,5_28; 17-5-2023.ngb-ds3
#FORMAT:                     ,NETZSCH5
#IDENTITY:                   ,Cement paste
#DECIMAL:                    ,POINT
#SEPARATOR:                  ,COMMA
#MTYPE:                      ,DSC
#INSTRUMENT:                 ,Microlab TU Delft
#PROJECT:                    ,
#DATE/TIME:                  ,17/05/2023 3:53:12 PM
#CORR. FILE:                 ,Blank with cover upto 1050 C; 2-5-2023.ngb-bs3
#LABORATORY:                 ,TU Delft Micro Lab
#OPERATOR:                   ,Patrick
#REMARK:                     ,under argon atmosphere, 10K/min
#SAMPLE:                     ,CP2_C1_0,5_28;17-5-2023
#SAMPLE MASS /mg:            ,46.7
#MATERIAL:                   ,CEMENT PASTE
#REFERENCE:                  ,blank
#REFERENCE MASS /mg:         ,0
#TYPE OF CRUCIBLE:           ,DSC/TG pan Al2O3
#SAMPLE CRUCIBLE MASS /mg:   ,0
#REFERENCE CRUCIBLE MASS /mg:,0
#CORR. CODE:                 ,020
#EXO:                        ,+1
#RANGE:                      ,40/10.0(K/min)/1050
#SEGMENT:                    ,S2/2

##Temp./øC,Time/min,DSC/(mW/mg),Mass/%,Gas Flow(purge1)/(ml/min),Gas Flow(purge2)/(ml/min),Gas Flow(protective)/(ml/min),DTG/(%/min),Sensit./(uV/mW)
  40.38000, 15.04833,-1.1505e-002,99.71734,50.00000,0.0000e+000,20.00000,-2.8215e-002,0.95848
  40.40500, 15.23833,-1.1335e-002,99.71306,50.00000,0.0000e+000,20.00000,-1.4698e-002,0.95849
  40.48900, 15.42833,-1.1249e-002,99.71306,50.00000,0.0000e+000,20.00000,-1.6115e-002,0.95851
  40.58400, 15.61833,-1.1283e-002,99.70878,50.00000,0.0000e+000,20.00000,-1.7804e-002,0.95853
  40.73900, 15.80833,-1.2049e-002,99.70450,50.00000,0.0000e+000,20.00000,-1.3943e-002,0.95858
  40.97100, 15.99833,-1.3344e-002,99.70236,50.00000,0.0000e+000,20.00000,-1.7282e-002,0.95864
  41.29600, 16.18833,-1.5234e-002,99.69807,50.00000,0.0000e+000,20.00000,-1.5513e-002,0.95872
  41.68900, 16.37833,-1.7686e-002,99.69593,50.00000,0.0000e+000,20.00000,-1.1859e-002,0.95882
  42.18500, 16.56833,-2.1074e-002,99.69593,50.00000,0.0000e+000,20.00000,-1.2697e-002,0.95895
  42.76500, 16.75833,-2.4324e-002,99.68951,50.00000,0.0000e+000,20.00000,-1.4306e-002,0.95910
  43.46300, 16.94833,-2.8611e-002,99.69165,50.00000,0.0000e+000,20.00000,-1.3537e-002,0.95928
  44.23500, 17.13833,-3.2897e-002,99.68522,50.00000,0.0000e+000,20.00000,-1.4661e-002,0.95947
  45.11000, 17.32833,-3.7264e-002,99.68308,50.00000,0.0000e+000,20.00000,-1.5280e-002,0.95968
  46.07200, 17.51833,-4.2463e-002,99.68094,50.00000,0.0000e+000,20.00000,-1.7421e-002,0.95991
  47.12200, 17.70833,-4.7098e-002,99.67880,50.00000,0.0000e+000,20.00000,-1.8058e-002,0.96015
  48.27200, 17.89833,-5.2580e-002,99.67452,50.00000,0.0000e+000,20.00000,-1.6206e-002,0.96041
  49.51000, 18.08833,-5.7786e-002,99.67024,50.00000,0.0000e+000,20.00000,-1.5257e-002,0.96068
  50.82900, 18.27833,-6.2937e-002,99.66809,50.00000,0.0000e+000,20.00000,-2.3655e-002,0.96095
  52.25700, 18.46833,-6.7779e-002,99.66595,50.00000,0.0000e+000,20.00000,-2.4537e-002,0.96124
  53.73500, 18.65833,-7.3179e-002,99.66381,50.00000,0.0000e+000,20.00000,-2.6820e-002,0.96153
  55.33900, 18.84833,-7.7963e-002,99.65310,50.00000,0.0000e+000,20.00000,-2.8808e-002,0.96183
  56.99800, 19.03833,-8.2762e-002,99.64454,50.00000,0.0000e+000,20.00000,-3.7470e-002,0.96212
  58.78100, 19.22833,-8.7880e-002,99.63597,50.00000,0.0000e+000,20.00000,-4.2522e-002,0.96242
  60.58600, 19.41833,-9.2351e-002,99.63383,50.00000,0.0000e+000,20.00000,-4.6393e-002,0.96270
  62.50200, 19.60833,-9.7329e-002,99.62099,50.00000,0.0000e+000,20.00000,-4.6962e-002,0.96298
  64.46900, 19.79833,    -0.10231,99.61028,50.00000,0.0000e+000,20.00000,-5.4502e-002,0.96324
  66.51700, 19.98833,    -0.10706,99.60171,50.00000,0.0000e+000,20.00000,-6.0833e-002,0.96349
  68.62100, 20.17833,    -0.11215,99.59101,50.00000,0.0000e+000,20.00000,-7.2447e-002,0.96373
  70.77200, 20.36833,    -0.11745,99.57602,50.00000,0.0000e+000,20.00000,-8.4496e-002,0.96394
  72.99300, 20.55833,    -0.12297,99.56103,50.00000,0.0000e+000,20.00000,-9.5905e-002,0.96414
  75.24400, 20.74833,    -0.12899,99.54390,50.00000,0.0000e+000,20.00000,    -0.11354,0.96430
  77.57400, 20.93833,    -0.13531,99.51820,50.00000,0.0000e+000,20.00000,    -0.12994,0.96445
  79.91800, 21.12833,    -0.14122,99.49465,50.00000,0.0000e+000,20.00000,    -0.15239,0.96456
  82.31100, 21.31833,    -0.14820,99.46253,50.00000,0.0000e+000,20.00000,    -0.17402,0.96465
  84.75600, 21.50833,    -0.15553,99.43041,50.00000,0.0000e+000,20.00000,    -0.19946,0.96470
  87.20300, 21.69833,    -0.16284,99.38972,50.00000,0.0000e+000,20.00000,    -0.22226,0.96473
  89.73400, 21.88833,    -0.17099,99.34475,50.00000,0.0000e+000,20.00000,    -0.25582,0.96471
  92.24600, 22.07833,    -0.17936,99.29336,50.00000,0.0000e+000,20.00000,    -0.29129,0.96467
  94.81100, 22.26833,    -0.18778,99.23983,50.00000,0.0000e+000,20.00000,    -0.31898,0.96459
  97.37400, 22.45833,    -0.19622,99.17131,50.00000,0.0000e+000,20.00000,    -0.34724,0.96447
  99.93200, 22.64833,    -0.20506,99.09850,50.00000,0.0000e+000,20.00000,    -0.37522,0.96431
 102.51900, 22.83833,    -0.21354,99.01927,50.00000,0.0000e+000,20.00000,    -0.40163,0.96412
 105.10000, 23.02833,    -0.22200,98.94647,50.00000,0.0000e+000,20.00000,    -0.42262,0.96390
 107.68400, 23.21833,    -0.22977,98.86724,50.00000,0.0000e+000,20.00000,    -0.43521,0.96364
 110.26600, 23.40833,    -0.23742,98.78158,50.00000,0.0000e+000,20.00000,    -0.44666,0.96334
 112.84400, 23.59833,    -0.24365,98.69379,50.00000,0.0000e+000,20.00000,    -0.46737,0.96301
 115.42100, 23.78833,    -0.24930,98.60171,50.00000,0.0000e+000,20.00000,    -0.48018,0.96264
 117.99500, 23.97833,    -0.25479,98.50964,50.00000,0.0000e+000,20.00000,    -0.49099,0.96224
 120.56200, 24.16833,    -0.25908,98.40899,50.00000,0.0000e+000,20.00000,    -0.50340,0.96181
 123.11100, 24.35833,    -0.26261,98.31692,50.00000,0.0000e+000,20.00000,    -0.51351,0.96134
 125.65900, 24.54833,    -0.26507,98.22056,50.00000,0.0000e+000,20.00000,    -0.52089,0.96084
 128.20399, 24.73833,    -0.26733,98.11991,50.00000,0.0000e+000,20.00000,    -0.52381,0.96032
 130.74400, 24.92833,    -0.26813,98.01071,50.00000,0.0000e+000,20.00000,    -0.52948,0.95975
 133.25999, 25.11833,    -0.26881,97.91221,50.00000,0.0000e+000,20.00000,    -0.53770,0.95916
 135.77800, 25.30833,    -0.26861,97.81370,50.00000,0.0000e+000,20.00000,    -0.54160,0.95854
 138.28101, 25.49833,    -0.26753,97.70878,50.00000,0.0000e+000,20.00000,    -0.53110,0.95789
 140.76601, 25.68833,    -0.26664,97.60814,50.00000,0.0000e+000,20.00000,    -0.53147,0.95722
 143.22000, 25.87833,    -0.26473,97.50321,50.00000,0.0000e+000,20.00000,    -0.53057,0.95652
 145.66800, 26.06833,    -0.26191,97.40471,50.00000,0.0000e+000,20.00000,    -0.53448,0.95580
 148.09700, 26.25833,    -0.25903,97.30407,50.00000,0.0000e+000,20.00000,    -0.53032,0.95505
 150.48700, 26.44833,    -0.25578,97.20771,50.00000,0.0000e+000,20.00000,    -0.52213,0.95429
 152.88000, 26.63833,    -0.25135,97.10492,50.00000,0.0000e+000,20.00000,    -0.52134,0.95350
 155.22800, 26.82833,    -0.24707,97.00214,50.00000,0.0000e+000,20.00000,    -0.52472,0.95269
 157.56200, 27.01833,    -0.24238,96.90792,50.00000,0.0000e+000,20.00000,    -0.52384,0.95187
 159.89101, 27.20833,    -0.23692,96.81156,50.00000,0.0000e+000,20.00000,    -0.51632,0.95102
 162.17400, 27.39833,    -0.23148,96.71092,50.00000,0.0000e+000,20.00000,    -0.50413,0.95017
 164.45000, 27.58833,    -0.22538,96.60814,50.00000,0.0000e+000,20.00000,    -0.50284,0.94929
 166.68401, 27.77833,    -0.21915,96.51820,50.00000,0.0000e+000,20.00000,    -0.49526,0.94840
 168.91701, 27.96833,    -0.21277,96.42398,50.00000,0.0000e+000,20.00000,    -0.48058,0.94750
 171.11099, 28.15833,    -0.20593,96.33405,50.00000,0.0000e+000,20.00000,    -0.47554,0.94658
 173.29700, 28.34833,    -0.19914,96.24411,50.00000,0.0000e+000,20.00000,    -0.46669,0.94565
 175.47000, 28.53833,    -0.19209,96.15632,50.00000,0.0000e+000,20.00000,    -0.45851,0.94470
 177.59900, 28.72833,    -0.18516,96.07066,50.00000,0.0000e+000,20.00000,    -0.45142,0.94375
 179.71100, 28.91833,    -0.17838,95.98501,50.00000,0.0000e+000,20.00000,    -0.45114,0.94279
 181.83299, 29.10833,    -0.17152,95.90150,50.00000,0.0000e+000,20.00000,    -0.44527,0.94181
 183.92400, 29.29833,    -0.16474,95.81799,50.00000,0.0000e+000,20.00000,    -0.44258,0.94082
 185.98900, 29.48833,    -0.15853,95.73019,50.00000,0.0000e+000,20.00000,    -0.43458,0.93982
 188.05400, 29.67833,    -0.15192,95.65096,50.00000,0.0000e+000,20.00000,    -0.42572,0.93880
 190.08299, 29.86833,    -0.14487,95.56745,50.00000,0.0000e+000,20.00000,    -0.41851,0.93779
 192.10201, 30.05833,    -0.13741,95.49036,50.00000,0.0000e+000,20.00000,    -0.40608,0.93676
 194.12000, 30.24833,    -0.12892,95.41542,50.00000,0.0000e+000,20.00000,    -0.39497,0.93571
 196.11301, 30.43833,    -0.12036,95.33619,50.00000,0.0000e+000,20.00000,    -0.38266,0.93467
 198.10400, 30.62833,    -0.11173,95.26767,50.00000,0.0000e+000,20.00000,    -0.37218,0.93360
 200.06700, 30.81833,    -0.10285,95.19914,50.00000,0.0000e+000,20.00000,    -0.36044,0.93254
 202.02299, 31.00833,-9.4168e-002,95.13490,50.00000,0.0000e+000,20.00000,    -0.34776,0.93146
 203.97301, 31.19833,-8.5516e-002,95.06638,50.00000,0.0000e+000,20.00000,    -0.33708,0.93037
 205.90601, 31.38833,-7.7529e-002,95.00214,50.00000,0.0000e+000,20.00000,    -0.32864,0.92928
 207.83099, 31.57833,-6.9155e-002,94.94433,50.00000,0.0000e+000,20.00000,    -0.32665,0.92817
 209.75200, 31.76833,-6.1538e-002,94.88437,50.00000,0.0000e+000,20.00000,    -0.31333,0.92706
 211.65800, 31.95833,-5.3973e-002,94.82655,50.00000,0.0000e+000,20.00000,    -0.30464,0.92593
 213.56300, 32.14833,-4.6814e-002,94.76445,50.00000,0.0000e+000,20.00000,    -0.29775,0.92480
 215.45200, 32.33833,-3.9973e-002,94.70450,50.00000,0.0000e+000,20.00000,    -0.29058,0.92365
 217.33501, 32.52833,-3.2833e-002,94.65739,50.00000,0.0000e+000,20.00000,    -0.28709,0.92250
 219.19901, 32.71833,-2.6704e-002,94.60385,50.00000,0.0000e+000,20.00000,    -0.27826,0.92135
 221.07500, 32.90833,-2.0027e-002,94.55246,50.00000,0.0000e+000,20.00000,    -0.27608,0.92018
 222.94701, 33.09833,-1.3937e-002,94.49893,50.00000,0.0000e+000,20.00000,    -0.27814,0.91899
 224.79800, 33.28833,-7.2802e-003,94.44968,50.00000,0.0000e+000,20.00000,    -0.27474,0.91781
 226.66600, 33.47833,-9.0900e-004,94.39186,50.00000,0.0000e+000,20.00000,    -0.26980,0.91660
 228.50000, 33.66833, 5.1042e-003,94.33833,50.00000,0.0000e+000,20.00000,    -0.26519,0.91541
 230.36099, 33.85833, 1.1276e-002,94.28908,50.00000,0.0000e+000,20.00000,    -0.26072,0.91418
 232.22900, 34.04833, 1.7215e-002,94.23983,50.00000,0.0000e+000,20.00000,    -0.25594,0.91293
 234.06599, 34.23833, 2.2578e-002,94.19486,50.00000,0.0000e+000,20.00000,    -0.25011,0.91170
 235.90199, 34.42833, 2.8387e-002,94.14989,50.00000,0.0000e+000,20.00000,    -0.24248,0.91045
 237.73801, 34.61833, 3.3709e-002,94.10278,50.00000,0.0000e+000,20.00000,    -0.24089,0.90919
 239.57201, 34.80833, 3.8615e-002,94.05139,50.00000,0.0000e+000,20.00000,    -0.23952,0.90792
 241.41800, 34.99833, 4.3283e-002,94.01071,50.00000,0.0000e+000,20.00000,    -0.23352,0.90663
 243.24600, 35.18833, 4.7657e-002,93.96788,50.00000,0.0000e+000,20.00000,    -0.23134,0.90534
 245.09200, 35.37833, 5.2028e-002,93.92291,50.00000,0.0000e+000,20.00000,    -0.22900,0.90403
 246.94000, 35.56833, 5.6466e-002,93.88437,50.00000,0.0000e+000,20.00000,    -0.22461,0.90270
 248.77000, 35.75834, 6.0536e-002,93.83940,50.00000,0.0000e+000,20.00000,    -0.22243,0.90138
 250.58600, 35.94833, 6.4255e-002,93.79229,50.00000,0.0000e+000,20.00000,    -0.22254,0.90005
 252.42300, 36.13833, 6.7897e-002,93.75375,50.00000,0.0000e+000,20.00000,    -0.22240,0.89870
 254.25700, 36.32833, 7.1313e-002,93.71306,50.00000,0.0000e+000,20.00000,    -0.22303,0.89734
 256.09500, 36.51833, 7.4814e-002,93.67024,50.00000,0.0000e+000,20.00000,    -0.21972,0.89597
 257.93701, 36.70833, 7.8272e-002,93.62955,50.00000,0.0000e+000,20.00000,    -0.21965,0.89458
 259.76300, 36.89833, 8.1704e-002,93.58458,50.00000,0.0000e+000,20.00000,    -0.22224,0.89320
 261.59799, 37.08833, 8.5093e-002,93.54176,50.00000,0.0000e+000,20.00000,    -0.21592,0.89180
 263.44601, 37.27833, 8.8330e-002,93.50107,50.00000,0.0000e+000,20.00000,    -0.21470,0.89037
 265.26901, 37.46833, 9.1208e-002,93.46039,50.00000,0.0000e+000,20.00000,    -0.21860,0.88896
 267.12100, 37.65833, 9.4541e-002,93.41970,50.00000,0.0000e+000,20.00000,    -0.21873,0.88752
 268.97101, 37.84833, 9.7444e-002,93.38330,50.00000,0.0000e+000,20.00000,    -0.22104,0.88606
 270.80099, 38.03833,     0.10078,93.34475,50.00000,0.0000e+000,20.00000,    -0.21880,0.88461
 272.64499, 38.22833,     0.10407,93.29336,50.00000,0.0000e+000,20.00000,    -0.21889,0.88314
 274.48199, 38.41833,     0.10751,93.25054,50.00000,0.0000e+000,20.00000,    -0.22294,0.88167
 276.32001, 38.60833,     0.11090,93.20985,50.00000,0.0000e+000,20.00000,    -0.22409,0.88019
 278.16901, 38.79833,     0.11408,93.16917,50.00000,0.0000e+000,20.00000,    -0.22175,0.87869
 280.01300, 38.98833,     0.11735,93.12848,50.00000,0.0000e+000,20.00000,    -0.22182,0.87718
 281.84000, 39.17833,     0.12065,93.08565,50.00000,0.0000e+000,20.00000,    -0.21956,0.87568
 283.70999, 39.36833,     0.12387,93.04711,50.00000,0.0000e+000,20.00000,    -0.22119,0.87413
 285.55301, 39.55833,     0.12699,92.99786,50.00000,0.0000e+000,20.00000,    -0.22038,0.87260
 287.39700, 39.74833,     0.12947,92.95503,50.00000,0.0000e+000,20.00000,    -0.21846,0.87105
 289.25000, 39.93833,     0.13252,92.91435,50.00000,0.0000e+000,20.00000,    -0.22314,0.86949
 291.10501, 40.12833,     0.13558,92.87366,50.00000,0.0000e+000,20.00000,    -0.21929,0.86792
 292.96201, 40.31833,     0.13900,92.83726,50.00000,0.0000e+000,20.00000,    -0.21376,0.86634
 294.81601, 40.50834,     0.14220,92.79229,50.00000,0.0000e+000,20.00000,    -0.21291,0.86476
 296.67401, 40.69833,     0.14561,92.74946,50.00000,0.0000e+000,20.00000,    -0.20733,0.86316
 298.52301, 40.88833,     0.14862,92.71092,50.00000,0.0000e+000,20.00000,    -0.21035,0.86156
 300.37500, 41.07833,     0.15152,92.67238,50.00000,0.0000e+000,20.00000,    -0.20579,0.85995
 302.22699, 41.26833,     0.15484,92.63812,50.00000,0.0000e+000,20.00000,    -0.20368,0.85834
 304.09698, 41.45833,     0.15816,92.59743,50.00000,0.0000e+000,20.00000,    -0.20461,0.85670
 305.95499, 41.64833,     0.16219,92.55889,50.00000,0.0000e+000,20.00000,    -0.20662,0.85506
 307.82700, 41.83833,     0.16536,92.51820,50.00000,0.0000e+000,20.00000,    -0.21060,0.85340
 309.68399, 42.02833,     0.16821,92.47966,50.00000,0.0000e+000,20.00000,    -0.20874,0.85175
 311.54599, 42.21833,     0.17179,92.43897,50.00000,0.0000e+000,20.00000,    -0.20989,0.85009
 313.41599, 42.40833,     0.17448,92.40043,50.00000,0.0000e+000,20.00000,    -0.20903,0.84841
 315.28400, 42.59833,     0.17693,92.35974,50.00000,0.0000e+000,20.00000,    -0.20748,0.84673
 317.15302, 42.78833,     0.17864,92.31906,50.00000,0.0000e+000,20.00000,    -0.20549,0.84503
 319.02200, 42.97833,     0.18157,92.27837,50.00000,0.0000e+000,20.00000,    -0.20541,0.84334
 320.89301, 43.16833,     0.18415,92.24411,50.00000,0.0000e+000,20.00000,    -0.20361,0.84163
 322.76401, 43.35833,     0.18681,92.20343,50.00000,0.0000e+000,20.00000,    -0.20614,0.83992
 324.62299, 43.54833,     0.18910,92.16488,50.00000,0.0000e+000,20.00000,    -0.20787,0.83821
 326.49301, 43.73833,     0.19220,92.12420,50.00000,0.0000e+000,20.00000,    -0.20780,0.83648
 328.37000, 43.92833,     0.19485,92.08137,50.00000,0.0000e+000,20.00000,    -0.20910,0.83474
 330.24701, 44.11833,     0.19765,92.04283,50.00000,0.0000e+000,20.00000,    -0.21027,0.83300
 332.11801, 44.30833,     0.20029,92.00428,50.00000,0.0000e+000,20.00000,    -0.21156,0.83125
 333.98001, 44.49833,     0.20264,91.96360,50.00000,0.0000e+000,20.00000,    -0.21050,0.82951
 335.86600, 44.68833,     0.20524,91.92934,50.00000,0.0000e+000,20.00000,    -0.21116,0.82774
 337.73700, 44.87833,     0.20760,91.88223,50.00000,0.0000e+000,20.00000,    -0.21306,0.82598
 339.61499, 45.06833,     0.21009,91.84368,50.00000,0.0000e+000,20.00000,    -0.21560,0.82420
 341.48499, 45.25834,     0.21150,91.80300,50.00000,0.0000e+000,20.00000,    -0.21766,0.82243
 343.35699, 45.44833,     0.21333,91.76231,50.00000,0.0000e+000,20.00000,    -0.21610,0.82065
 345.23300, 45.63833,     0.21525,91.71949,50.00000,0.0000e+000,20.00000,    -0.21641,0.81886
 347.11401, 45.82833,     0.21730,91.67880,50.00000,0.0000e+000,20.00000,    -0.21610,0.81706
 348.98401, 46.01833,     0.21963,91.63597,50.00000,0.0000e+000,20.00000,    -0.21846,0.81527
 350.86499, 46.20833,     0.22140,91.59529,50.00000,0.0000e+000,20.00000,    -0.21716,0.81346
 352.74399, 46.39833,     0.22314,91.55675,50.00000,0.0000e+000,20.00000,    -0.21480,0.81165
 354.61200, 46.58833,     0.22451,91.51178,50.00000,0.0000e+000,20.00000,    -0.21396,0.80984
 356.49399, 46.77833,     0.22635,91.47323,50.00000,0.0000e+000,20.00000,    -0.21744,0.80802
 358.37701, 46.96833,     0.22816,91.43469,50.00000,0.0000e+000,20.00000,    -0.21966,0.80619
 360.25000, 47.15833,     0.22983,91.39400,50.00000,0.0000e+000,20.00000,    -0.21438,0.80437
 362.12500, 47.34833,     0.23146,91.34690,50.00000,0.0000e+000,20.00000,    -0.21329,0.80254
 364.00601, 47.53833,     0.23340,91.30407,50.00000,0.0000e+000,20.00000,    -0.21441,0.80070
 365.87799, 47.72833,     0.23532,91.26767,50.00000,0.0000e+000,20.00000,    -0.22124,0.79886
 367.75299, 47.91833,     0.23748,91.22698,50.00000,0.0000e+000,20.00000,    -0.21986,0.79702
 369.64200, 48.10833,     0.23995,91.19058,50.00000,0.0000e+000,20.00000,    -0.21725,0.79517
 371.52399, 48.29833,     0.24255,91.14347,50.00000,0.0000e+000,20.00000,    -0.21734,0.79331
 373.40100, 48.48833,     0.24458,91.10064,50.00000,0.0000e+000,20.00000,    -0.21723,0.79146
 375.27899, 48.67833,     0.24690,91.05996,50.00000,0.0000e+000,20.00000,    -0.22035,0.78960
 377.15799, 48.86833,     0.24924,91.01927,50.00000,0.0000e+000,20.00000,    -0.21441,0.78774
 379.03201, 49.05833,     0.25133,90.97859,50.00000,0.0000e+000,20.00000,    -0.21123,0.78588
 380.90601, 49.24833,     0.25347,90.93576,50.00000,0.0000e+000,20.00000,    -0.21023,0.78402
 382.78000, 49.43833,     0.25581,90.89722,50.00000,0.0000e+000,20.00000,    -0.21522,0.78216
 384.65701, 49.62833,     0.25765,90.85653,50.00000,0.0000e+000,20.00000,    -0.21370,0.78029
 386.53699, 49.81833,     0.25968,90.81799,50.00000,0.0000e+000,20.00000,    -0.21059,0.77841
 388.41199, 50.00834,     0.26287,90.77516,50.00000,0.0000e+000,20.00000,    -0.20605,0.77654
 390.29401, 50.19833,     0.26608,90.73448,50.00000,0.0000e+000,20.00000,    -0.20576,0.77466
 392.17200, 50.38833,     0.26954,90.69807,50.00000,0.0000e+000,20.00000,    -0.20639,0.77278
 394.07501, 50.57833,     0.27377,90.66381,50.00000,0.0000e+000,20.00000,    -0.20274,0.77087
 395.94800, 50.76833,     0.27690,90.62527,50.00000,0.0000e+000,20.00000,    -0.19712,0.76899
 397.83600, 50.95833,     0.27972,90.58244,50.00000,0.0000e+000,20.00000,    -0.19552,0.76710
 399.71799, 51.14833,     0.28259,90.54604,50.00000,0.0000e+000,20.00000,    -0.19620,0.76521
 401.61099, 51.33833,     0.28466,90.50750,50.00000,0.0000e+000,20.00000,    -0.19500,0.76330
 403.49701, 51.52833,     0.28685,90.47323,50.00000,0.0000e+000,20.00000,    -0.19132,0.76141
 405.39200, 51.71833,     0.28914,90.43683,50.00000,0.0000e+000,20.00000,    -0.19021,0.75950
 407.26300, 51.90833,     0.29096,90.40257,50.00000,0.0000e+000,20.00000,    -0.19130,0.75762
 409.13599, 52.09833,     0.29272,90.36831,50.00000,0.0000e+000,20.00000,    -0.19314,0.75573
 411.02301, 52.28833,     0.29374,90.32762,50.00000,0.0000e+000,20.00000,    -0.19157,0.75383
 412.91599, 52.47833,     0.29599,90.28694,50.00000,0.0000e+000,20.00000,    -0.19402,0.75192
 414.79901, 52.66833,     0.29948,90.25268,50.00000,0.0000e+000,20.00000,    -0.19389,0.75002
 416.69101, 52.85833,     0.30346,90.21627,50.00000,0.0000e+000,20.00000,    -0.19176,0.74811
 418.57800, 53.04833,     0.30653,90.17987,50.00000,0.0000e+000,20.00000,    -0.18838,0.74621
 420.45801, 53.23833,     0.30894,90.14561,50.00000,0.0000e+000,20.00000,    -0.18167,0.74431
 422.34100, 53.42833,     0.31052,90.10921,50.00000,0.0000e+000,20.00000,    -0.18215,0.74241
 424.23401, 53.61833,     0.31141,90.07709,50.00000,0.0000e+000,20.00000,    -0.18317,0.74050
 426.10699, 53.80833,     0.31307,90.04283,50.00000,0.0000e+000,20.00000,    -0.18537,0.73861
 427.98801, 53.99833,     0.31354,90.01071,50.00000,0.0000e+000,20.00000,    -0.18921,0.73671
 429.88599, 54.18833,     0.31436,89.97216,50.00000,0.0000e+000,20.00000,    -0.19679,0.73480
 431.76700, 54.37833,     0.31412,89.93362,50.00000,0.0000e+000,20.00000,    -0.20227,0.73290
 433.64999, 54.56833,     0.31275,89.89722,50.00000,0.0000e+000,20.00000,    -0.21915,0.73100
 435.53799, 54.75834,     0.30911,89.85225,50.00000,0.0000e+000,20.00000,    -0.23662,0.72910
 437.42099, 54.94833,     0.30180,89.80942,50.00000,0.0000e+000,20.00000,    -0.25498,0.72720
 439.29999, 55.13833,     0.29160,89.76231,50.00000,0.0000e+000,20.00000,    -0.28244,0.72531
 441.18301, 55.32833,     0.27886,89.70235,50.00000,0.0000e+000,20.00000,    -0.30598,0.72342
 443.06900, 55.51833,     0.26485,89.64454,50.00000,0.0000e+000,20.00000,    -0.32938,0.72152
 444.95099, 55.70833,     0.24963,89.57816,50.00000,0.0000e+000,20.00000,    -0.35807,0.71963
 446.82001, 55.89833,     0.23385,89.50321,50.00000,0.0000e+000,20.00000,    -0.38004,0.71776
 448.68100, 56.08833,     0.21730,89.43469,50.00000,0.0000e+000,20.00000,    -0.40450,0.71589
 450.56000, 56.27833,     0.20195,89.35546,50.00000,0.0000e+000,20.00000,    -0.42670,0.71401
 452.44601, 56.46833,     0.18594,89.27195,50.00000,0.0000e+000,20.00000,    -0.44811,0.71212
 454.31601, 56.65833,     0.16987,89.18415,50.00000,0.0000e+000,20.00000,    -0.47621,0.71025
 456.19501, 56.84833,     0.15353,89.09636,50.00000,0.0000e+000,20.00000,    -0.51913,0.70838
 458.07001, 57.03833,     0.13678,88.99143,50.00000,0.0000e+000,20.00000,    -0.53477,0.70651
 459.95300, 57.22833,     0.11964,88.89079,50.00000,0.0000e+000,20.00000,    -0.57398,0.70463
 461.83701, 57.41833,     0.10157,88.77088,50.00000,0.0000e+000,20.00000,    -0.59179,0.70275
 463.73199, 57.60833, 8.4031e-002,88.65525,50.00000,0.0000e+000,20.00000,    -0.62667,0.70087
 465.60501, 57.79833, 6.6258e-002,88.53747,50.00000,0.0000e+000,20.00000,    -0.65903,0.69901
 467.48599, 57.98833, 4.8415e-002,88.41328,50.00000,0.0000e+000,20.00000,    -0.68346,0.69715
 469.37299, 58.17833, 2.9559e-002,88.27623,50.00000,0.0000e+000,20.00000,    -0.69382,0.69528
 471.24500, 58.36833, 9.9893e-003,88.13919,50.00000,0.0000e+000,20.00000,    -0.73066,0.69343
 473.14301, 58.55833,-9.1659e-003,88.00428,50.00000,0.0000e+000,20.00000,    -0.74445,0.69156
 475.02499, 58.74833,-2.6103e-002,87.86081,50.00000,0.0000e+000,20.00000,    -0.77715,0.68971
 476.91699, 58.93833,-4.2823e-002,87.71092,50.00000,0.0000e+000,20.00000,    -0.79146,0.68785
 478.81000, 59.12833,-5.9228e-002,87.55246,50.00000,0.0000e+000,20.00000,    -0.81602,0.68599
 480.69699, 59.31833,-7.5125e-002,87.40043,50.00000,0.0000e+000,20.00000,    -0.83623,0.68415
 482.59000, 59.50834,-9.0341e-002,87.23769,50.00000,0.0000e+000,20.00000,    -0.84776,0.68230
 484.49200, 59.69833,    -0.10389,87.07281,50.00000,0.0000e+000,20.00000,    -0.85804,0.68044
 486.36600, 59.88833,    -0.11423,86.90792,50.00000,0.0000e+000,20.00000,    -0.86287,0.67862
 488.26599, 60.07833,    -0.11973,86.74090,50.00000,0.0000e+000,20.00000,    -0.84975,0.67677
 490.15399, 60.26833,    -0.11790,86.57602,50.00000,0.0000e+000,20.00000,    -0.80733,0.67495
 492.04199, 60.45833,    -0.10626,86.41114,50.00000,0.0000e+000,20.00000,    -0.74645,0.67312
 493.94501, 60.64833,-8.2819e-002,86.27195,50.00000,0.0000e+000,20.00000,    -0.66552,0.67129
 495.84799, 60.83833,-4.0656e-002,86.14561,50.00000,0.0000e+000,20.00000,    -0.56263,0.66946
 497.77399, 61.02833, 1.8280e-002,86.04711,50.00000,0.0000e+000,20.00000,    -0.46010,0.66761
 499.70901, 61.21833, 9.8942e-002,85.97216,50.00000,0.0000e+000,20.00000,    -0.37041,0.66576
 501.62799, 61.40833,     0.17473,85.93148,50.00000,0.0000e+000,20.00000,    -0.28582,0.66392
 503.55600, 61.59833,     0.23244,85.89508,50.00000,0.0000e+000,20.00000,    -0.22898,0.66209
 505.47501, 61.78833,     0.27423,85.85653,50.00000,0.0000e+000,20.00000,    -0.18747,0.66027
 507.38699, 61.97833,     0.30480,85.82227,50.00000,0.0000e+000,20.00000,    -0.17056,0.65846
 509.29001, 62.16833,     0.32793,85.79229,50.00000,0.0000e+000,20.00000,    -0.16327,0.65666
 511.20700, 62.35833,     0.34582,85.76231,50.00000,0.0000e+000,20.00000,    -0.15519,0.65486
 513.10199, 62.54833,     0.35952,85.73662,50.00000,0.0000e+000,20.00000,    -0.14562,0.65308
 515.01202, 62.73833,     0.37026,85.71092,50.00000,0.0000e+000,20.00000,    -0.13971,0.65129
 516.91901, 62.92833,     0.37845,85.67880,50.00000,0.0000e+000,20.00000,    -0.13424,0.64952
 518.82703, 63.11833,     0.38607,85.65525,50.00000,0.0000e+000,20.00000,    -0.12605,0.64774
 520.73700, 63.30833,     0.39266,85.63597,50.00000,0.0000e+000,20.00000,    -0.11998,0.64597
 522.64099, 63.49833,     0.39845,85.61028,50.00000,0.0000e+000,20.00000,    -0.11614,0.64421
 524.55603, 63.68833,     0.40280,85.59101,50.00000,0.0000e+000,20.00000,    -0.10920,0.64245
 526.43402, 63.87833,     0.40582,85.57173,50.00000,0.0000e+000,20.00000,    -0.10235,0.64073
 528.33099, 64.06834,     0.40937,85.55032,50.00000,0.0000e+000,20.00000,-9.7796e-002,0.63900
 530.20898, 64.25833,     0.41301,85.53319,50.00000,0.0000e+000,20.00000,-9.4862e-002,0.63729
 532.09900, 64.44833,     0.41669,85.51606,50.00000,0.0000e+000,20.00000,-9.4042e-002,0.63557
 533.99298, 64.63834,     0.41939,85.50107,50.00000,0.0000e+000,20.00000,-9.2499e-002,0.63386
 535.86798, 64.82833,     0.42204,85.48180,50.00000,0.0000e+000,20.00000,-8.8948e-002,0.63217
 537.75299, 65.01833,     0.42428,85.46253,50.00000,0.0000e+000,20.00000,-8.7533e-002,0.63048
 539.65302, 65.20834,     0.42722,85.44540,50.00000,0.0000e+000,20.00000,-8.8638e-002,0.62878
 541.55701, 65.39833,     0.43046,85.42827,50.00000,0.0000e+000,20.00000,-8.4911e-002,0.62709
 543.43201, 65.58833,     0.43317,85.41328,50.00000,0.0000e+000,20.00000,-8.1957e-002,0.62543
 545.33099, 65.77834,     0.43525,85.39829,50.00000,0.0000e+000,20.00000,-7.9002e-002,0.62375
 547.22400, 65.96833,     0.43818,85.38544,50.00000,0.0000e+000,20.00000,-7.5855e-002,0.62208
 549.12402, 66.15833,     0.44127,85.37045,50.00000,0.0000e+000,20.00000,-7.5493e-002,0.62042
 551.01398, 66.34834,     0.44427,85.35546,50.00000,0.0000e+000,20.00000,-7.5075e-002,0.61877
 552.90399, 66.53833,     0.44712,85.34261,50.00000,0.0000e+000,20.00000,-7.4354e-002,0.61713
 554.79498, 66.72833,     0.44947,85.32762,50.00000,0.0000e+000,20.00000,-7.4425e-002,0.61550
 556.69800, 66.91833,     0.45235,85.31263,50.00000,0.0000e+000,20.00000,-7.1681e-002,0.61386
 558.60999, 67.10833,     0.45527,85.29979,50.00000,0.0000e+000,20.00000,-7.4559e-002,0.61223
 560.51398, 67.29833,     0.45811,85.28694,50.00000,0.0000e+000,20.00000,-6.9231e-002,0.61060
 562.40997, 67.48833,     0.46082,85.27409,50.00000,0.0000e+000,20.00000,-6.6844e-002,0.60899
 564.30298, 67.67834,     0.46287,85.26124,50.00000,0.0000e+000,20.00000,-6.6558e-002,0.60740
 566.19397, 67.86833,     0.46481,85.24625,50.00000,0.0000e+000,20.00000,-6.8176e-002,0.60581
 568.07397, 68.05833,     0.46672,85.23340,50.00000,0.0000e+000,20.00000,-6.6847e-002,0.60424
 569.95697, 68.24834,     0.46829,85.22484,50.00000,0.0000e+000,20.00000,-6.6099e-002,0.60267
 571.85101, 68.43833,     0.47022,85.20985,50.00000,0.0000e+000,20.00000,-6.5400e-002,0.60110
 573.72803, 68.62833,     0.47323,85.19700,50.00000,0.0000e+000,20.00000,-6.6322e-002,0.59956
 575.62402, 68.81834,     0.47574,85.18415,50.00000,0.0000e+000,20.00000,-6.8452e-002,0.59800
 577.54999, 69.00833,     0.47863,85.17345,50.00000,0.0000e+000,20.00000,-6.7297e-002,0.59643
 579.47498, 69.19833,     0.48126,85.15846,50.00000,0.0000e+000,20.00000,-6.7732e-002,0.59487
 581.37598, 69.38834,     0.48429,85.14561,50.00000,0.0000e+000,20.00000,-6.3063e-002,0.59334
 583.26801, 69.57833,     0.48686,85.13490,50.00000,0.0000e+000,20.00000,-6.3053e-002,0.59182
 585.14600, 69.76833,     0.48862,85.12206,50.00000,0.0000e+000,20.00000,-6.1257e-002,0.59033
 587.01398, 69.95834,     0.49054,85.10921,50.00000,0.0000e+000,20.00000,-6.1191e-002,0.58885
 588.90100, 70.14833,     0.49304,85.10064,50.00000,0.0000e+000,20.00000,-5.7922e-002,0.58736
 590.77802, 70.33833,     0.49664,85.08994,50.00000,0.0000e+000,20.00000,-5.8575e-002,0.58589
 592.67200, 70.52834,     0.50176,85.07709,50.00000,0.0000e+000,20.00000,-5.6029e-002,0.58441
 594.56000, 70.71833,     0.50400,85.06424,50.00000,0.0000e+000,20.00000,-5.8226e-002,0.58295
 596.46503, 70.90833,     0.50541,85.05567,50.00000,0.0000e+000,20.00000,-6.2048e-002,0.58149
 598.36902, 71.09834,     0.50651,85.04497,50.00000,0.0000e+000,20.00000,-6.0046e-002,0.58003
 600.25299, 71.28833,     0.50909,85.03640,50.00000,0.0000e+000,20.00000,-6.1186e-002,0.57860
 602.16998, 71.47833,     0.51223,85.02141,50.00000,0.0000e+000,20.00000,-6.2319e-002,0.57715
 604.07501, 71.66833,     0.51532,85.01071,50.00000,0.0000e+000,20.00000,-6.2263e-002,0.57572
 605.98401, 71.85833,     0.51791,84.99786,50.00000,0.0000e+000,20.00000,-6.3984e-002,0.57430
 607.85901, 72.04833,     0.51939,84.98287,50.00000,0.0000e+000,20.00000,-6.5507e-002,0.57291
 609.73999, 72.23833,     0.52194,84.97216,50.00000,0.0000e+000,20.00000,-6.6230e-002,0.57152
 611.64099, 72.42834,     0.52450,84.95931,50.00000,0.0000e+000,20.00000,-6.7683e-002,0.57013
 613.57098, 72.61833,     0.52907,84.94647,50.00000,0.0000e+000,20.00000,-6.5898e-002,0.56873
 615.48602, 72.80833,     0.53372,84.93362,50.00000,0.0000e+000,20.00000,-6.7623e-002,0.56735
 617.39502, 72.99834,     0.53721,84.92077,50.00000,0.0000e+000,20.00000,-6.9642e-002,0.56598
 619.28802, 73.18833,     0.53927,84.90578,50.00000,0.0000e+000,20.00000,-7.3671e-002,0.56464
 621.18402, 73.37833,     0.54116,84.89293,50.00000,0.0000e+000,20.00000,-7.2896e-002,0.56330
 623.09497, 73.56834,     0.54320,84.87794,50.00000,0.0000e+000,20.00000,-7.1926e-002,0.56196
 625.06097, 73.75833,     0.54671,84.86510,50.00000,0.0000e+000,20.00000,-7.5107e-002,0.56059
 627.03601, 73.94833,     0.55132,84.85011,50.00000,0.0000e+000,20.00000,-7.5770e-002,0.55923
 628.97900, 74.13834,     0.55600,84.83940,50.00000,0.0000e+000,20.00000,-7.5392e-002,0.55790
 630.87598, 74.32833,     0.55755,84.82227,50.00000,0.0000e+000,20.00000,-7.5793e-002,0.55661
 632.76703, 74.51833,     0.55763,84.80728,50.00000,0.0000e+000,20.00000,-7.6895e-002,0.55533
 634.68903, 74.70834,     0.55848,84.79229,50.00000,0.0000e+000,20.00000,-7.8157e-002,0.55405
 636.58801, 74.89833,     0.55893,84.78158,50.00000,0.0000e+000,20.00000,-8.2360e-002,0.55278
 638.47699, 75.08833,     0.55977,84.76445,50.00000,0.0000e+000,20.00000,-8.5728e-002,0.55154
 640.35602, 75.27834,     0.55983,84.75161,50.00000,0.0000e+000,20.00000,-8.9668e-002,0.55031
 642.23102, 75.46833,     0.56000,84.73019,50.00000,0.0000e+000,20.00000,-9.3477e-002,0.54910
 644.09802, 75.65833,     0.56105,84.71306,50.00000,0.0000e+000,20.00000,-9.6206e-002,0.54790
 645.97803, 75.84834,     0.55849,84.69165,50.00000,0.0000e+000,20.00000,-9.9779e-002,0.54670
 647.84003, 76.03833,     0.55744,84.67238,50.00000,0.0000e+000,20.00000,    -0.10266,0.54552
 649.70697, 76.22833,     0.56080,84.65525,50.00000,0.0000e+000,20.00000,    -0.10515,0.54435
 651.61700, 76.41833,     0.56642,84.63383,50.00000,0.0000e+000,20.00000,    -0.10539,0.54316
 653.52600, 76.60833,     0.57178,84.61242,50.00000,0.0000e+000,20.00000,    -0.10723,0.54199
 655.41602, 76.79833,     0.57418,84.59315,50.00000,0.0000e+000,20.00000,    -0.11094,0.54083
 657.34198, 76.98833,     0.57536,84.56959,50.00000,0.0000e+000,20.00000,    -0.11337,0.53967
 659.24799, 77.17834,     0.57749,84.54818,50.00000,0.0000e+000,20.00000,    -0.11308,0.53852
 661.14697, 77.36833,     0.57898,84.52677,50.00000,0.0000e+000,20.00000,    -0.11730,0.53740
 663.06598, 77.55833,     0.58184,84.50321,50.00000,0.0000e+000,20.00000,    -0.11751,0.53627
 664.97803, 77.74834,     0.58458,84.48180,50.00000,0.0000e+000,20.00000,    -0.11933,0.53515
 666.88300, 77.93833,     0.58401,84.46253,50.00000,0.0000e+000,20.00000,    -0.11992,0.53405
 668.78998, 78.12833,     0.58536,84.43683,50.00000,0.0000e+000,20.00000,    -0.11965,0.53296
 670.70697, 78.31834,     0.58815,84.41328,50.00000,0.0000e+000,20.00000,    -0.11844,0.53188
 672.63501, 78.50833,     0.59402,84.38972,50.00000,0.0000e+000,20.00000,    -0.12437,0.53080
 674.53497, 78.69833,     0.59838,84.36831,50.00000,0.0000e+000,20.00000,    -0.12253,0.52974
 676.40198, 78.88834,     0.60096,84.34904,50.00000,0.0000e+000,20.00000,    -0.12249,0.52872
 678.28198, 79.07833,     0.60361,84.32120,50.00000,0.0000e+000,20.00000,    -0.12169,0.52769
 680.18103, 79.26833,     0.60882,84.29764,50.00000,0.0000e+000,20.00000,    -0.12388,0.52667
 682.08502, 79.45834,     0.61304,84.27409,50.00000,0.0000e+000,20.00000,    -0.12497,0.52566
 684.00000, 79.64833,     0.61733,84.25268,50.00000,0.0000e+000,20.00000,    -0.12428,0.52465
 685.95599, 79.83833,     0.62362,84.22698,50.00000,0.0000e+000,20.00000,    -0.12282,0.52363
 687.89801, 80.02834,     0.63028,84.20557,50.00000,0.0000e+000,20.00000,    -0.12557,0.52263
 689.84698, 80.21833,     0.63558,84.17773,50.00000,0.0000e+000,20.00000,    -0.12670,0.52164
 691.81500, 80.40833,     0.64159,84.16060,50.00000,0.0000e+000,20.00000,    -0.12622,0.52065
 693.74799, 80.59834,     0.64592,84.13276,50.00000,0.0000e+000,20.00000,    -0.12697,0.51969
 695.63599, 80.78833,     0.64862,84.10493,50.00000,0.0000e+000,20.00000,    -0.12911,0.51876
 697.53198, 80.97833,     0.65003,84.08351,50.00000,0.0000e+000,20.00000,    -0.13220,0.51784
 699.40503, 81.16833,     0.65176,84.05782,50.00000,0.0000e+000,20.00000,    -0.13101,0.51694
 701.28400, 81.35833,     0.65409,84.02998,50.00000,0.0000e+000,20.00000,    -0.12554,0.51605
 703.16498, 81.54833,     0.65733,84.00857,50.00000,0.0000e+000,20.00000,    -0.12278,0.51516
 705.04901, 81.73833,     0.65962,83.98287,50.00000,0.0000e+000,20.00000,    -0.11949,0.51429
 706.93298, 81.92834,     0.66496,83.96146,50.00000,0.0000e+000,20.00000,    -0.10948,0.51343
 708.81403, 82.11833,     0.67142,83.94218,50.00000,0.0000e+000,20.00000,    -0.10238,0.51258
 710.68500, 82.30833,     0.67794,83.92291,50.00000,0.0000e+000,20.00000,-9.5056e-002,0.51175
 712.56299, 82.49834,     0.68393,83.90578,50.00000,0.0000e+000,20.00000,-8.8892e-002,0.51092
 714.47302, 82.68833,     0.68924,83.89079,50.00000,0.0000e+000,20.00000,-8.4818e-002,0.51009
 716.36401, 82.87833,     0.69502,83.87580,50.00000,0.0000e+000,20.00000,-8.0086e-002,0.50928
 718.29700, 83.06834,     0.70109,83.86081,50.00000,0.0000e+000,20.00000,-7.6343e-002,0.50846
 720.20697, 83.25833,     0.70602,83.84797,50.00000,0.0000e+000,20.00000,-7.2213e-002,0.50766
 722.13098, 83.44833,     0.71070,83.83298,50.00000,0.0000e+000,20.00000,-7.2433e-002,0.50687
 724.08899, 83.63834,     0.71533,83.82013,50.00000,0.0000e+000,20.00000,-6.8478e-002,0.50608
 726.00897, 83.82833,     0.71929,83.80942,50.00000,0.0000e+000,20.00000,-6.4082e-002,0.50531
 727.90399, 84.01833,     0.72149,83.79229,50.00000,0.0000e+000,20.00000,-5.9444e-002,0.50456
 729.78302, 84.20834,     0.72403,83.78373,50.00000,0.0000e+000,20.00000,-5.4607e-002,0.50383
 731.67200, 84.39833,     0.72396,83.77302,50.00000,0.0000e+000,20.00000,-4.9709e-002,0.50311
 733.56299, 84.58833,     0.72343,83.76660,50.00000,0.0000e+000,20.00000,-4.8922e-002,0.50240
 735.41803, 84.77834,     0.72712,83.75803,50.00000,0.0000e+000,20.00000,-4.5686e-002,0.50171
 737.25500, 84.96833,     0.72875,83.74946,50.00000,0.0000e+000,20.00000,-4.4894e-002,0.50104
 739.10699, 85.15833,     0.73168,83.74090,50.00000,0.0000e+000,20.00000,-4.7119e-002,0.50038
 741.00702, 85.34834,     0.73544,83.73233,50.00000,0.0000e+000,20.00000,-4.7782e-002,0.49970
 742.93903, 85.53833,     0.73918,83.71949,50.00000,0.0000e+000,20.00000,-5.0354e-002,0.49903
 744.89398, 85.72833,     0.74450,83.71092,50.00000,0.0000e+000,20.00000,-5.1510e-002,0.49836
 746.88000, 85.91833,     0.74911,83.70236,50.00000,0.0000e+000,20.00000,-5.1044e-002,0.49769
 748.84399, 86.10833,     0.75259,83.68951,50.00000,0.0000e+000,20.00000,-5.0959e-002,0.49705
 750.76501, 86.29833,     0.75327,83.68094,50.00000,0.0000e+000,20.00000,-4.8326e-002,0.49642
 752.65100, 86.48833,     0.75092,83.67238,50.00000,0.0000e+000,20.00000,-4.8973e-002,0.49582
 754.55200, 86.67834,     0.74971,83.66381,50.00000,0.0000e+000,20.00000,-4.8620e-002,0.49523
 756.44501, 86.86833,     0.75082,83.65525,50.00000,0.0000e+000,20.00000,-4.8288e-002,0.49464
 758.32800, 87.05833,     0.75301,83.64668,50.00000,0.0000e+000,20.00000,-4.8930e-002,0.49408
 760.25598, 87.24834,     0.75375,83.63812,50.00000,0.0000e+000,20.00000,-4.6914e-002,0.49351
 762.16901, 87.43833,     0.75585,83.62527,50.00000,0.0000e+000,20.00000,-5.0911e-002,0.49295
 764.06598, 87.62833,     0.75691,83.61884,50.00000,0.0000e+000,20.00000,-5.0959e-002,0.49241
 765.95398, 87.81834,     0.75919,83.61028,50.00000,0.0000e+000,20.00000,-4.8904e-002,0.49188
 767.84998, 88.00833,     0.76108,83.60171,50.00000,0.0000e+000,20.00000,-5.0547e-002,0.49137
 769.77802, 88.19833,     0.76475,83.59315,50.00000,0.0000e+000,20.00000,-5.4066e-002,0.49085
 771.66901, 88.38834,     0.76805,83.58030,50.00000,0.0000e+000,20.00000,-5.4012e-002,0.49036
 773.56000, 88.57833,     0.77028,83.57388,50.00000,0.0000e+000,20.00000,-5.5682e-002,0.48987
 775.46198, 88.76833,     0.77330,83.55889,50.00000,0.0000e+000,20.00000,-5.4828e-002,0.48939
 777.35797, 88.95834,     0.77650,83.54604,50.00000,0.0000e+000,20.00000,-5.1102e-002,0.48893
 779.26398, 89.14833,     0.77880,83.53962,50.00000,0.0000e+000,20.00000,-5.2259e-002,0.48847
 781.13702, 89.33833,     0.77963,83.52677,50.00000,0.0000e+000,20.00000,-5.3425e-002,0.48804
 783.01398, 89.52834,     0.78189,83.52034,50.00000,0.0000e+000,20.00000,-5.1676e-002,0.48761
 784.95398, 89.71833,     0.78705,83.50964,50.00000,0.0000e+000,20.00000,-5.5882e-002,0.48717
 786.91901, 89.90833,     0.79271,83.49893,50.00000,0.0000e+000,20.00000,-5.6617e-002,0.48675
 788.82202, 90.09834,     0.79719,83.48822,50.00000,0.0000e+000,20.00000,-6.2823e-002,0.48635
 790.73199, 90.28833,     0.79965,83.47538,50.00000,0.0000e+000,20.00000,-6.4837e-002,0.48595
 792.60699, 90.47833,     0.80215,83.46467,50.00000,0.0000e+000,20.00000,-6.6315e-002,0.48558
 794.50897, 90.66833,     0.80381,83.44968,50.00000,0.0000e+000,20.00000,-6.5993e-002,0.48521
 796.40002, 90.85833,     0.80677,83.43897,50.00000,0.0000e+000,20.00000,-6.4271e-002,0.48485
 798.30298, 91.04833,     0.81089,83.42612,50.00000,0.0000e+000,20.00000,-6.8474e-002,0.48450
 800.19098, 91.23833,     0.81372,83.41113,50.00000,0.0000e+000,20.00000,-6.4852e-002,0.48416
 802.06500, 91.42834,     0.81619,83.40257,50.00000,0.0000e+000,20.00000,-6.6246e-002,0.48383
 803.93903, 91.61833,     0.81885,83.38972,50.00000,0.0000e+000,20.00000,-6.4675e-002,0.48352
 805.83002, 91.80833,     0.82133,83.37687,50.00000,0.0000e+000,20.00000,-6.4153e-002,0.48321
 807.73401, 91.99834,     0.82434,83.36188,50.00000,0.0000e+000,20.00000,-7.2380e-002,0.48291
 809.67401, 92.18833,     0.82891,83.35118,50.00000,0.0000e+000,20.00000,-7.3165e-002,0.48262
 811.58899, 92.37833,     0.83274,83.34261,50.00000,0.0000e+000,20.00000,-7.4862e-002,0.48234
 813.51501, 92.56834,     0.83606,83.32548,50.00000,0.0000e+000,20.00000,-7.7774e-002,0.48206
 815.41498, 92.75833,     0.83742,83.30835,50.00000,0.0000e+000,20.00000,-8.1320e-002,0.48181
 817.32501, 92.94833,     0.83983,83.28908,50.00000,0.0000e+000,20.00000,-8.7209e-002,0.48156
 819.23798, 93.13834,     0.84354,83.27623,50.00000,0.0000e+000,20.00000,-9.0754e-002,0.48132
 821.14398, 93.32833,     0.84608,83.25482,50.00000,0.0000e+000,20.00000,-8.9256e-002,0.48109
 823.06299, 93.51833,     0.84986,83.23983,50.00000,0.0000e+000,20.00000,-9.2015e-002,0.48087
 824.97302, 93.70834,     0.85292,83.22056,50.00000,0.0000e+000,20.00000,-9.4806e-002,0.48066
 826.86401, 93.89833,     0.85449,83.20557,50.00000,0.0000e+000,20.00000,-9.0642e-002,0.48046
 828.78699, 94.08833,     0.85885,83.18630,50.00000,0.0000e+000,20.00000,-9.0432e-002,0.48027
 830.69397, 94.27834,     0.86305,83.16702,50.00000,0.0000e+000,20.00000,-9.1713e-002,0.48009
 832.58899, 94.46833,     0.86601,83.15418,50.00000,0.0000e+000,20.00000,-9.1129e-002,0.47992
 834.49402, 94.65833,     0.86916,83.13705,50.00000,0.0000e+000,20.00000,-9.1175e-002,0.47976
 836.43903, 94.84834,     0.87431,83.11991,50.00000,0.0000e+000,20.00000,-8.8083e-002,0.47961
 838.36700, 95.03833,     0.87852,83.10064,50.00000,0.0000e+000,20.00000,-8.8610e-002,0.47946
 840.28198, 95.22833,     0.88156,83.08565,50.00000,0.0000e+000,20.00000,-8.7601e-002,0.47933
 842.19202, 95.41833,     0.88488,83.06424,50.00000,0.0000e+000,20.00000,-8.7617e-002,0.47921
 844.08099, 95.60833,     0.88853,83.05139,50.00000,0.0000e+000,20.00000,-8.5623e-002,0.47910
 845.98700, 95.79833,     0.89142,83.03640,50.00000,0.0000e+000,20.00000,-7.9356e-002,0.47899
 847.88098, 95.98833,     0.89347,83.01927,50.00000,0.0000e+000,20.00000,-7.8934e-002,0.47890
 849.76703, 96.17834,     0.89564,83.00214,50.00000,0.0000e+000,20.00000,-7.8479e-002,0.47882
 851.65302, 96.36833,     0.89725,82.99358,50.00000,0.0000e+000,20.00000,-7.7474e-002,0.47874
 853.55902, 96.55833,     0.89887,82.97645,50.00000,0.0000e+000,20.00000,-7.2231e-002,0.47868
 855.47699, 96.74834,     0.90229,82.96360,50.00000,0.0000e+000,20.00000,-7.1877e-002,0.47862
 857.38300, 96.93833,     0.90576,82.94861,50.00000,0.0000e+000,20.00000,-7.3849e-002,0.47857
 859.34100, 97.12833,     0.90891,82.93790,50.00000,0.0000e+000,20.00000,-6.4837e-002,0.47853
 861.29797, 97.31834,     0.91307,82.92505,50.00000,0.0000e+000,20.00000,-6.2705e-002,0.47850
 863.22101, 97.50833,     0.91509,82.91006,50.00000,0.0000e+000,20.00000,-6.0962e-002,0.47848
 865.11298, 97.69833,     0.91641,82.90150,50.00000,0.0000e+000,20.00000,-5.8128e-002,0.47847
 866.98700, 97.88834,     0.91713,82.89293,50.00000,0.0000e+000,20.00000,-5.6838e-002,0.47846
 868.85699, 98.07833,     0.91708,82.88009,50.00000,0.0000e+000,20.00000,-5.4493e-002,0.47847
 870.73700, 98.26833,     0.91839,82.87152,50.00000,0.0000e+000,20.00000,-5.2909e-002,0.47848
 872.58099, 98.45834,     0.91954,82.86081,50.00000,0.0000e+000,20.00000,-5.5177e-002,0.47850
 874.38702, 98.64833,     0.91802,82.84797,50.00000,0.0000e+000,20.00000,-5.2992e-002,0.47853
 876.33600, 98.83833,     0.91992,82.83726,50.00000,0.0000e+000,20.00000,-5.1416e-002,0.47857
 878.33002, 99.02834,     0.92703,82.82869,50.00000,0.0000e+000,20.00000,-5.2758e-002,0.47862
 880.27899, 99.21833,     0.92825,82.82227,50.00000,0.0000e+000,20.00000,-5.1187e-002,0.47868
 882.20203, 99.40833,     0.93037,82.81585,50.00000,0.0000e+000,20.00000,-4.6938e-002,0.47875
 884.10602, 99.59834,     0.93375,82.80300,50.00000,0.0000e+000,20.00000,-4.6921e-002,0.47882
 885.99799, 99.78833,     0.93591,82.79229,50.00000,0.0000e+000,20.00000,-4.8948e-002,0.47890
 887.86700, 99.97833,     0.93663,82.78373,50.00000,0.0000e+000,20.00000,-5.2180e-002,0.47899
 889.71198,100.16833,     0.93746,82.77516,50.00000,0.0000e+000,20.00000,-4.7774e-002,0.47908
 891.54602,100.35833,     0.93740,82.76660,50.00000,0.0000e+000,20.00000,-4.4887e-002,0.47918
 893.42401,100.54833,     0.93852,82.75589,50.00000,0.0000e+000,20.00000,-4.4638e-002,0.47929
 895.33899,100.73833,     0.94169,82.74732,50.00000,0.0000e+000,20.00000,-4.4020e-002,0.47941
 897.35498,100.92834,     0.94619,82.74304,50.00000,0.0000e+000,20.00000,-4.0674e-002,0.47955
 899.48401,101.11833,     0.95593,82.73448,50.00000,0.0000e+000,20.00000,-3.6436e-002,0.47970
 901.48297,101.30833,     0.96220,82.72591,50.00000,0.0000e+000,20.00000,-3.7309e-002,0.47986
 903.40302,101.49834,     0.96346,82.72163,50.00000,0.0000e+000,20.00000,-3.8732e-002,0.48001
 905.27502,101.68833,     0.96242,82.71306,50.00000,0.0000e+000,20.00000,-3.7438e-002,0.48017
 907.13702,101.87833,     0.96097,82.70878,50.00000,0.0000e+000,20.00000,-3.2161e-002,0.48033
 909.00201,102.06834,     0.96090,82.69807,50.00000,0.0000e+000,20.00000,-3.2094e-002,0.48050
 910.88000,102.25833,     0.96330,82.68951,50.00000,0.0000e+000,20.00000,-3.6871e-002,0.48068
 912.71301,102.44833,     0.96045,82.68737,50.00000,0.0000e+000,20.00000,-3.5717e-002,0.48087
 914.56702,102.63834,     0.95885,82.68523,50.00000,0.0000e+000,20.00000,-3.5758e-002,0.48106
 916.43298,102.82833,     0.96194,82.67238,50.00000,0.0000e+000,20.00000,-2.4695e-002,0.48126
 918.31598,103.01833,     0.96251,82.66595,50.00000,0.0000e+000,20.00000,-2.6659e-002,0.48147
 920.23499,103.20834,     0.96530,82.66167,50.00000,0.0000e+000,20.00000,-3.3896e-002,0.48168
 922.15399,103.39833,     0.96515,82.65739,50.00000,0.0000e+000,20.00000,-2.5631e-002,0.48191
 924.04303,103.58833,     0.97313,82.65525,50.00000,0.0000e+000,20.00000,-2.5578e-002,0.48214
 925.93298,103.77834,     0.97319,82.64668,50.00000,0.0000e+000,20.00000,-2.4747e-002,0.48238
 927.85101,103.96833,     0.97747,82.64240,50.00000,0.0000e+000,20.00000,-2.2153e-002,0.48262
 929.75500,104.15833,     0.98186,82.64026,50.00000,0.0000e+000,20.00000,-2.2182e-002,0.48287
 931.64899,104.34834,     0.98614,82.63169,50.00000,0.0000e+000,20.00000,-2.0475e-002,0.48313
 933.55603,104.53833,     0.98973,82.63169,50.00000,0.0000e+000,20.00000,-1.8289e-002,0.48340
 935.47302,104.72833,     0.99275,82.62955,50.00000,0.0000e+000,20.00000,-1.1944e-002,0.48367
 937.36200,104.91833,     0.99428,82.62527,50.00000,0.0000e+000,20.00000,-8.5390e-003,0.48395
 939.25598,105.10833,     0.99731,82.62099,50.00000,0.0000e+000,20.00000,-9.0632e-003,0.48423
 941.16302,105.29833,     1.00261,82.62313,50.00000,0.0000e+000,20.00000,-1.2476e-002,0.48452
 943.08899,105.48833,     1.00654,82.62313,50.00000,0.0000e+000,20.00000,-1.3106e-002,0.48482
 945.02002,105.67834,     1.01028,82.61884,50.00000,0.0000e+000,20.00000,-6.8263e-003,0.48512
 946.96198,105.86833,     1.01565,82.61456,50.00000,0.0000e+000,20.00000,-9.1723e-003,0.48544
 948.89301,106.05833,     1.02215,82.61456,50.00000,0.0000e+000,20.00000,-1.3650e-002,0.48576
 950.82202,106.24834,     1.02432,82.61456,50.00000,0.0000e+000,20.00000,-1.6827e-002,0.48608
 952.74103,106.43833,     1.02971,82.61028,50.00000,0.0000e+000,20.00000,-1.6715e-002,0.48641
 954.63898,106.62833,     1.03481,82.60600,50.00000,0.0000e+000,20.00000,-1.5242e-002,0.48674
 956.53699,106.81834,     1.03910,82.60385,50.00000,0.0000e+000,20.00000,-1.5355e-002,0.48708
 958.42603,107.00833,     1.04175,82.59957,50.00000,0.0000e+000,20.00000,-1.1951e-002,0.48742
 960.32300,107.19833,     1.04647,82.59529,50.00000,0.0000e+000,20.00000,-1.3614e-002,0.48777
 962.22302,107.38834,     1.05057,82.59529,50.00000,0.0000e+000,20.00000,-1.2477e-002,0.48812
 964.12097,107.57833,     1.05411,82.59529,50.00000,0.0000e+000,20.00000,-1.3951e-002,0.48848
 966.01801,107.76833,     1.05881,82.59315,50.00000,0.0000e+000,20.00000,-1.0273e-002,0.48884
 967.90997,107.95834,     1.06412,82.58886,50.00000,0.0000e+000,20.00000,-1.1944e-002,0.48921
 969.78198,108.14833,     1.06609,82.58672,50.00000,0.0000e+000,20.00000,-1.3650e-002,0.48958
 971.67200,108.33833,     1.06561,82.58672,50.00000,0.0000e+000,20.00000,-1.1943e-002,0.48996
 973.57703,108.52834,     1.06447,82.58244,50.00000,0.0000e+000,20.00000,-1.3642e-002,0.49034
 975.47601,108.71833,     1.06729,82.57816,50.00000,0.0000e+000,20.00000,-1.0237e-002,0.49073
 977.39301,108.90833,     1.07314,82.57816,50.00000,0.0000e+000,20.00000,-1.1303e-002,0.49113
 979.27802,109.09834,     1.07584,82.57388,50.00000,0.0000e+000,20.00000,-6.8250e-003,0.49152
 981.22400,109.28833,     1.07776,82.57388,50.00000,0.0000e+000,20.00000,-7.3763e-003,0.49193
 983.20300,109.47833,     1.08124,82.56959,50.00000,0.0000e+000,20.00000,-8.5311e-003,0.49236
 985.10901,109.66833,     1.08265,82.57388,50.00000,0.0000e+000,20.00000,-1.0237e-002,0.49277
 987.02899,109.85833,     1.08322,82.56959,50.00000,0.0000e+000,20.00000,-5.1187e-003,0.49319
 988.92902,110.04833,     1.08266,82.56745,50.00000,0.0000e+000,20.00000,-4.5673e-003,0.49362
 990.80499,110.23833,     1.08283,82.56745,50.00000,0.0000e+000,20.00000,-3.4118e-003,0.49404
 992.66901,110.42834,     1.08263,82.56959,50.00000,0.0000e+000,20.00000,-6.8095e-003,0.49446
 994.54401,110.61833,     1.08256,82.56745,50.00000,0.0000e+000,20.00000,-3.6881e-003,0.49489
 996.42999,110.80833,     1.08213,82.56531,50.00000,0.0000e+000,20.00000,-5.0046e-003,0.49532
 998.32703,110.99834,     1.08183,82.56531,50.00000,0.0000e+000,20.00000,-3.4126e-003,0.49576
1000.22400,111.18833,     1.08261,82.56531,50.00000,0.0000e+000,20.00000,-3.4126e-003,0.49620
1002.13599,111.37833,     1.08234,82.55889,50.00000,0.0000e+000,20.00000,-2.7787e-003,0.49666
1004.05402,111.56834,     1.08017,82.56103,50.00000,0.0000e+000,20.00000,-5.1267e-003,0.49711
1005.97998,111.75833,     1.07555,82.56317,50.00000,0.0000e+000,20.00000,-8.5315e-003,0.49758
1007.91302,111.94833,     1.07618,82.56317,50.00000,0.0000e+000,20.00000,-5.2326e-003,0.49805
1009.81897,112.13834,     1.07629,82.55674,50.00000,0.0000e+000,20.00000,-6.8248e-003,0.49851
1011.71899,112.32833,     1.07492,82.55460,50.00000,0.0000e+000,20.00000,-5.2326e-003,0.49898
1013.59601,112.51833,     1.07098,82.55460,50.00000,0.0000e+000,20.00000,-8.5316e-003,0.49944
1015.49902,112.70834,     1.06797,82.55246,50.00000,0.0000e+000,20.00000,-5.1046e-003,0.49992
1017.40198,112.89833,     1.06718,82.55460,50.00000,0.0000e+000,20.00000,-6.8240e-003,0.50039
1019.35199,113.08833,     1.06884,82.55246,50.00000,0.0000e+000,20.00000,-1.7145e-003,0.50089
1021.28601,113.27834,     1.06844,82.55246,50.00000,0.0000e+000,20.00000,-4.4774e-003,0.50138
1023.19299,113.46833,     1.06379,82.55032,50.00000,0.0000e+000,20.00000,-1.9345e-003,0.50187
1025.09900,113.65833,     1.06129,82.55032,50.00000,0.0000e+000,20.00000,-3.6954e-003,0.50236
1027.00903,113.84834,     1.05855,82.54818,50.00000,0.0000e+000,20.00000,-3.4486e-003,0.50285
1028.89697,114.03833,     1.05681,82.55032,50.00000,0.0000e+000,20.00000,-5.2327e-003,0.50334
1030.77405,114.22833,     1.05163,82.54818,50.00000,0.0000e+000,20.00000,-3.4124e-003,0.50383
1032.65198,114.41833,     1.05011,82.54604,50.00000,0.0000e+000,20.00000, 1.7060e-003,0.50432
1034.54504,114.60833,     1.04765,82.54604,50.00000,0.0000e+000,20.00000,-3.6238e-005,0.50482
1036.44604,114.79833,     1.04483,82.54604,50.00000,0.0000e+000,20.00000,-3.4124e-003,0.50533
1038.34094,114.98833,     1.04259,82.55032,50.00000,0.0000e+000,20.00000,-6.7115e-003,0.50583
1040.27405,115.17834,     1.04036,82.54818,50.00000,0.0000e+000,20.00000,-5.1185e-003,0.50635
1042.18799,115.36833,     1.03818,82.54604,50.00000,0.0000e+000,20.00000,-3.9449e-003,0.50687
1044.09998,115.55833,     1.03390,82.53961,50.00000,0.0000e+000,20.00000,-9.6345e-003,0.50738
1046.00305,115.74834,     1.03079,82.53961,50.00000,0.0000e+000,20.00000,-5.6095e-004,0.50790
1047.90698,115.93833,     1.02605,82.53961,50.00000,0.0000e+000,20.00000,-6.5440e-014,0.50841
1048.51001,115.99834,     1.02501,82.53961,50.00000,0.0000e+000,20.00000,-1.0606e-012,0.50858